Workbook
Name billion: About!$A$38
Name IQ_CH: 110000
Name IQ_CQ: 5000
Name IQ_CY: 10000
Name IQ_DAILY: 500000
Name IQ_FH: 100000
Name IQ_FQ: 500
Name IQ_FY: 1000
Name IQ_LTM: 2000
Name IQ_MONTH: 15000
Name IQ_NTM: 6000
Name IQ_WEEK: 50000
Name IQ_YTD: 3000
Name thousand: About!$A$37

Sheet About
A1: BAADTbVT BAU Average Annual Dist Traveled by Vehicle Type | B1: New Jersey | C1: 46245 | E1: State | F1: State
B2: =LOOKUP(B1,E2:F51,F2:F51) -> NJ | E2: Alabama | F2: AL
A3: Source: | B3: All vehicle types except motorbikes and passenger ships | D3: NREL calibration factors for ships | E3: Alaska | F3: AK
B4: EIA | D4: National Renewable Energy Laboratory | E4: Arizona | F4: AZ
B5: 2024 | D5: 2017 | E5: Arkansas | F5: AR
B6: SEDS | D6: Electrification Futures Study | E6: California | F6: CA
B7: https://www.eia.gov/state/seds/ | D7: Final Demand | E7: Colorado | F7: CO
D8: https://data.nrel.gov/submissions/92 | E8: Connecticut | F8: CT
E9: Delaware | F9: DE
B10: Motorbikes | D10: Passenger Rail Scaling | E10: Florida | F10: FL
B11: National Highway Traffic Safety Administration | D11: National Transit Database Tables | E11: Georgia | F11: GA
B12: 2016 | D12: American Public Transportation Association | E12: Hawaii | F12: HI
B13: Quick Facts 2014 | D13: 2020 | E13: Idaho | F13: ID
B14: http://www-nrd.nhtsa.dot.gov/Pubs/812234.pdf | D14: https://www.apta.com/research-technical-resources/transit-statistics/ntd-data-tables/ | E14: Illinois | F14: IL
B15: Page 1, "Exposure Data" | E15: Indiana | F15: IN
E16: Iowa | F16: IA
B17: passenger ships | E17: Kansas | F17: KS
B18: U.S. Coast Guard | E18: Kentucky | F18: KY
B19: 2013 | E19: Louisiana | F19: LA
B20: National Recreational Boating Survey 2012 | E20: Maine | F20: ME
B21: http://www.uscgboating.org/library/recreational-boating-servey/2012survey%20report.pdf | E21: Maryland | F21: MD
B22: Page 63, Table 40 | E22: Massachusetts | F22: MA
E23: Michigan | F23: MI
A24: Notes: | E24: Minnesota | F24: MN
A25: In the U.S. model, passenger ships are recreational boats, and they are represented | E25: Mississippi | F25: MS
A26: in hours per year rather than distance per year. | E26: Missouri | F26: MO
E27: Montana | F27: MT
A28: This is a time-series variable to support countries or regions where average distance | E28: Nebraska | F28: NE
A29: traveled per year changes over the model run. The values are constant in the U.S. | E29: Nevada | F29: NV
A30: version of the model. | E30: New Hampshire | F30: NH
E31: New Jersey | F31: NJ
A32: Start Year | B32: 2018 | E32: New Mexico | F32: NM
A33: The start year is the year prior the first simulated year in the model. | E33: New York | F33: NY
A34: For the U.S. in EPS 3.0, the start year is 2018, as the first simulated year is 2019. | E34: North Carolina | F34: NC
A35: We use AEO 2019 to calculate start year vehicles, as AEO 2020 does not include 2018 data. | E35: North Dakota | F35: ND
E36: Ohio | F36: OH
A37: 1000 | E37: Oklahoma | F37: OK
A38: =10^9 -> 1000000000 | E38: Oregon | F38: OR
E39: Pennsylvania | F39: PA
E40: Rhode Island | F40: RI
...

Sheet all_csv_SYVbT-passenger
A1: SourceFolder | B1: Number of Vehicles | C1: battery electric vehicle | D1: natural gas vehicle | E1: gasoline vehicle | F1: diesel vehicle | G1: plugin hybrid vehicle | H1: LPG vehicle | I1: hydrogen vehicle
A2: AK | B2: LDVs | C2: 4769953 | D2: 14506 | E2: 257649823 | F2: 1553093 | G2: 1417825 | H2: 13525 | I2: 17094
A3: AK | B3: HDVs | C3: 300 | D3: 128402 | E3: 101051 | F3: 802832 | G3: 0 | H3: 47038 | I3: 174
A4: AK | B4: aircraft | C4: 0 | D4: 0 | E4: 0 | F4: 6767 | G4: 0 | H4: 0 | I4: 0
A5: AK | B5: rail | C5: 2564 | D5: 0 | E5: 0 | F5: 173 | G5: 0 | H5: 0 | I5: 0
A6: AK | B6: ships | C6: 0 | D6: 0 | E6: 10214830 | F6: 2490170 | G6: 0 | H6: 0 | I6: 0
A7: AK | B7: motorbikes | C7: 0 | D7: 0 | E7: 9261249 | F7: 0 | G7: 0 | H7: 0 | I7: 0
A8: AL | B8: LDVs | C8: 17500 | D8: 100 | E8: 5181820 | F8: 28594 | G8: 6800 | H8: 100 | I8: 0
A9: AL | B9: HDVs | C9: 1 | D9: 401 | E9: 315 | F9: 2505 | G9: 0 | H9: 147 | I9: 1
A10: AL | B10: aircraft | C10: 0 | D10: 0 | E10: 0 | F10: 24 | G10: 0 | H10: 0 | I10: 0
A11: AL | B11: rail | C11: 0 | D11: 0 | E11: 0 | F11: 0 | G11: 0 | H11: 0 | I11: 0
A12: AL | B12: ships | C12: 0 | D12: 0 | E12: 219517 | F12: 53514 | G12: 0 | H12: 0 | I12: 0
A13: AL | B13: motorbikes | C13: 0 | D13: 0 | E13: 129014 | F13: 0 | G13: 0 | H13: 0 | I13: 0
... A313: WY | B313: motorbikes | C313: 0 | D313: 0 | E313: 28613 | F313: 0 | G313: 0 | H313: 0 | I313: 0

Sheet all_csv_SYVbT-freight
A1: SourceFolder | B1: Number of Vehicles | C1: battery electric vehicle | D1: natural gas vehicle | E1: gasoline vehicle | F1: diesel vehicle | G1: plugin hybrid vehicle | H1: LPG vehicle | I1: hydrogen vehicle | J1: Unnamed: 8 | K1: Unnamed: 9
A2: AK | B2: LDVs | C2: 138292 | D2: 25267 | E2: 12833715 | F2: 10968619 | G2: 493 | H2: 2238 | I2: 0
A3: AK | B3: HDVs | C3: 2114 | D3: 57392 | E3: 38136 | F3: 5453223 | G3: 0 | H3: 3057 | I3: 0
A4: AK | B4: aircraft | C4: 0 | D4: 0 | E4: 0 | F4: 925 | G4: 0 | H4: 0 | I4: 0
A5: AK | B5: rail | C5: 0 | D5: 0 | E5: 0 | F5: 24526 | G5: 0 | H5: 0 | I5: 0
A6: AK | B6: ships | C6: 0 | D6: 0 | E6: 0 | F6: 164 | G6: 0 | H6: 0 | I6: 0
A7: AK | B7: motorbikes | C7: 0 | D7: 0 | E7: 0 | F7: 0 | G7: 0 | H7: 0 | I7: 0
A8: AL | B8: LDVs | C8: 897 | D8: 164 | E8: 83198 | F8: 71107 | G8: 3 | H8: 15 | I8: 0
A9: AL | B9: HDVs | C9: 50 | D9: 1371 | E9: 911 | F9: 130263 | G9: 0 | H9: 73 | I9: 0
A10: AL | B10: aircraft | C10: 0 | D10: 0 | E10: 0 | F10: 4 | G10: 0 | H10: 0 | I10: 0
A11: AL | B11: rail | C11: 0 | D11: 0 | E11: 0 | F11: 371 | G11: 0 | H11: 0 | I11: 0
A12: AL | B12: ships | C12: 0 | D12: 0 | E12: 0 | F12: 4 | G12: 0 | H12: 0 | I12: 0
A13: AL | B13: motorbikes | C13: 0 | D13: 0 | E13: 0 | F13: 0 | G13: 0 | H13: 0 | I13: 0
... A67: HI | B67: motorbikes | C67: 0 | D67: 0 | E67: 0 | F67: 0 | G67: 0 | H67: 0 | I67: 0
A68: HI
A69: HI
A70: HI
A71: HI
A72: HI
A73: HI
A74: HI
A75: HI
A76: HI
A77: HI
A78: HI
A79: HI
... A83: HI
A84: IA | B84: LDVs | C84: 662 | D84: 121 | E84: 61426 | F84: 52499 | G84: 2 | H84: 11 | I84: 0
A85: IA | B85: HDVs | C85: 37 | D85: 1012 | E85: 673 | F85: 96175 | G85: 0 | H85: 54 | I85: 0
A86: IA | B86: aircraft | C86: 0 | D86: 0 | E86: 0 | F86: 4 | G86: 0 | H86: 0 | I86: 0
A87: IA | B87: rail | C87: 0 | D87: 0 | E87: 0 | F87: 339 | G87: 0 | H87: 0 | I87: 0
A88: IA | B88: ships | C88: 0 | D88: 0 | E88: 0 | F88: 0 | G88: 0 | H88: 0 | I88: 0
A89: IA | B89: motorbikes | C89: 0 | D89: 0 | E89: 0 | F89: 0 | G89: 0 | H89: 0 | I89: 0
A90: ID | B90: LDVs | C90: 360 | D90: 66 | E90: 33426 | F90: 28568 | G90: 1 | H90: 6 | I90: 0
A91: ID | B91: HDVs | C91: 20 | D91: 551 | E91: 366 | F91: 52334 | G91: 0 | H91: 29 | I91: 0
A92: ID | B92: aircraft | C92: 0 | D92: 0 | E92: 0 | F92: 2 | G92: 0 | H92: 0 | I92: 0
A93: ID | B93: rail | C93: 0 | D93: 0 | E93: 0 | F93: 86 | G93: 0 | H93: 0 | I93: 0
A94: ID | B94: ships | C94: 0 | D94: 0 | E94: 0 | F94: 0 | G94: 0 | H94: 0 | I94: 0
A95: ID | B95: motorbikes | C95: 0 | D95: 0 | E95: 0 | F95: 0 | G95: 0 | H95: 0 | I95: 0
... A329: WY | B329: motorbikes | C329: 0 | D329: 0 | E329: 0 | F329: 0 | G329: 0 | H329: 0 | I329: 0

Sheet all_csv_AVLo-passengers
B1: Vehicle Loading (passengers) | C1: 2015 | D1: State
A2: 0 | B2: LDVs | C2: 1.67 | D2: AK | E2: AVLo-passengers
A3: 1 | B3: HDVs | C3: 21.196137 | D3: AK | E3: AVLo-passengers
A4: 2 | B4: aircraft | C4: 111.39416 | D4: AK | E4: AVLo-passengers
A5: 3 | B5: rail | C5: 15.34784 | D5: AK | E5: AVLo-passengers
A6: 4 | B6: ships | C6: 1 | D6: AK | E6: AVLo-passengers
A7: 5 | B7: motorbikes | C7: 1.2700757 | D7: AK | E7: AVLo-passengers

Sheet all_csv_AVLo-freight
B1: Vehicle Loading (tons) | C1: 2021 | D1: State | E1: Metric Name
A2: 0 | B2: LDVs | C2: 1 | D2: AK | E2: AVLo-freight
A3: 1 | B3: HDVs | C3: 16 | D3: AK | E3: AVLo-freight
A4: 2 | B4: aircraft | C4: 41.989116 | D4: AK | E4: AVLo-freight
A5: 3 | B5: rail | C5: 3512.3592 | D5: AK | E5: AVLo-freight
A6: 4 | B6: ships | C6: 1974.4736 | D6: AK | E6: AVLo-freight
A7: 5 | B7: motorbikes | C7: 0 | D7: AK | E7: AVLo-freight

Sheet all_csv_SYFAFE-psgr
B1: Fuel Economy (passenger*miles/BTU) | C1: battery electric vehicle | D1: natural gas vehicle | E1: gasoline vehicle | F1: diesel vehicle | G1: plugin hybrid vehicle | H1: LPG vehicle | I1: hydrogen vehicle | J1: State
A2: 0 | B2: LDVs | C2: 0.001464487 | D2: 0.000285996 | E2: 0.000308115 | F2: 0.000349551 | G2: 0.000544402 | H2: 0.000245972 | I2: 0.000954776 | J2: AK | K2: SYFAFE-psgr
A3: 1 | B3: HDVs | C3: 0.003319966 | D3: 0.002348966 | E3: 0.000851798 | F3: 0.001033139 | G3: 0.002290894 | H3: 0.001829444 | I3: 0.003099417 | J3: AK | K3: SYFAFE-psgr
A4: 2 | B4: aircraft | C4: 0.000978983 | D4: 0.000304649 | E4: 0.000304649 | F4: 0.000304649 | G4: 0 | H4: 0 | I4: 0.000913948 | J4: AK | K4: SYFAFE-psgr
A5: 3 | B5: rail | C5: 0.000674285 | D5: 5.05863e-05 | E5: 5.05863e-05 | F5: 5.05863e-05 | G5: 0 | H5: 0 | I5: 0.000151759 | J5: AK | K5: SYFAFE-psgr
A6: 4 | B6: ships | C6: 3.81517e-05 | D6: 0 | E6: 1.18724e-05 | F6: 1.18724e-05 | G6: 0 | H6: 0 | I6: 3.56172e-05 | J6: AK | K6: SYFAFE-psgr
A7: 5 | B7: motorbikes | C7: 0.005802878 | D7: 0.001822391 | E7: 0.001822391 | F7: 0.001822391 | G7: 0.004011659 | H7: 0.001412353 | I7: 0.005467174 | J7: AK | K7: SYFAFE-psgr

Sheet all_csv_SYFAFE-frgt
B1: Fuel Economy (freight ton*miles/BTU) | C1: battery electric vehicle | D1: natural gas vehicle | E1: gasoline vehicle | F1: diesel vehicle | G1: plugin hybrid vehicle | H1: LPG vehicle | I1: hydrogen vehicle | J1: State | K1: Metric Name
A2: 0 | B2: LDVs | C2: 0.0003015665 | D2: 7.0213474e-05 | E2: 9.3322264e-05 | F2: 8.9590244e-05 | G2: 0.0001534286 | H2: 0.00011549321 | I2: 8.3798902e-05 | J2: AK | K2: SYFAFE-frgt
A3: 1 | B3: HDVs | C3: 0.0016283397 | D3: 0.00077263482 | E3: 0.0006720672 | F3: 0.00075059325 | G3: 0 | H3: 0.00068755018 | I3: 0 | J3: AK | K3: SYFAFE-frgt
A4: 2 | B4: aircraft | C4: 0.00029962433 | D4: 9.3239985e-05 | E4: 9.3239985e-05 | F4: 9.3239985e-05 | G4: 0 | H4: 0 | I4: 0.00027971996 | J4: AK | K4: SYFAFE-frgt
A5: 3 | B5: rail | C5: 0.010840496 | D5: 0.00337345 | E5: 0.00337345 | F5: 0.00337345 | G5: 0 | H5: 0 | I5: 0.01012035 | J5: AK | K5: SYFAFE-frgt
A6: 4 | B6: ships | C6: 0.01561035 | D6: 0.004857779 | E6: 0.004857779 | F6: 0.004857779 | G6: 0 | H6: 0 | I6: 0.014573337 | J6: AK | K6: SYFAFE-frgt
A7: 5 | B7: motorbikes | C7: 0 | D7: 0 | E7: 0 | F7: 0 | G7: 0 | H7: 0 | I7: 0 | J7: AK | K7: SYFAFE-frgt

Sheet Codes_and_Descriptions
B2: State Energy Data System
B3: Data Series Names (MSN) and Descriptions
B6: The MSNs are five-character codes, most of which are structured as follows:
B7: First and second characters - describes an energy source (for example, NG for natural gas, MG for motor gasoline)
B8: Third and fourth characters - describes an energy sector or an energy activity (for example, RC for residential consumption, PR for production)
B9: Fifth character - describes a type of data (for example, P for data in physical unit, B for data in billion Btu)
B11: MSN | C11: Description | D11: Unit
B12: ABICB | C12: Aviation gasoline blending components consumed by the industrial sector | D12: Billion Btu
B13: ABICP | C13: Aviation gasoline blending components consumed by the industrial sector | D13: Thousand barrels
B14: ARICB | C14: Asphalt and road oil consumed by the industrial sector | D14: Billion Btu
B15: ARICD | C15: Asphalt and road oil price in the industrial sector | D15: Dollars per million Btu
B16: ARICP | C16: Asphalt and road oil consumed by the industrial sector | D16: Thousand barrels
B17: ARICV | C17: Asphalt and road oil expenditures in the industrial sector | D17: Million dollars
B18: ARTCB | C18: Asphalt and road oil total consumption | D18: Billion Btu
B19: ARTCD | C19: Asphalt and road oil average price, all sectors | D19: Dollars per million Btu
B20: ARTCP | C20: Asphalt and road oil total consumption | D20: Thousand barrels
B21: ARTCV | C21: Asphalt and road oil total expenditures | D21: Million dollars
B22: ARTXB | C22: Asphalt and road oil total end-use consumption | D22: Billion Btu
... B395: NGICP | C395: Natural gas consumed by the industrial sector | D395: Million cubic feet
B396: NGICV | C396: Natural gas expenditures in the industrial sector | D396: Million dollars | E396: =SUM(A397:A398,A407) -> 0
B397: NGISB | C397: Natural gas consumed by the industrial sector excluding refinery fuel | D397: Billion Btu
B398: NGLPB | C398: Natural gas consumed as lease and plant fuel | D398: Billion Btu | E398: energy pipelines or oil and gas
B399: NGMPB | C399: Natural gas marketed production | D399: Billion Btu
B400: NGMPK | C400: Conversion factor for natural gas marketed production | D400: Thousand Btu per cubic feet
B401: NGMPP | C401: Natural gas marketed production | D401: Million cubic feet
B402: NGPZB | C402: Natural gas for pipeline and distribution use | D402: Billion Btu
B403: NGRCB | C403: Natural gas consumed by (delivered to) the residential sector | D403: Billion Btu
B404: NGRCD | C404: Natural gas price in the residential sector | D404: Dollars per million Btu
B405: NGRCP | C405: Natural gas consumed by (delivered to) the residential sector | D405: Million cubic feet
B406: NGRCV | C406: Natural gas expenditures in the residential sector | D406: Million dollars
B407: NGRFB | C407: Natural gas consumed as refinery fuel | D407: Billion Btu | E407: refinery
B408: NGSCB | C408: Natural gas total consumption adjusted for process fuel | D408: Billion Btu
B409: NGTCB | C409: Natural gas total consumption | D409: Billion Btu
B410: NGTCD | C410: Natural gas average price, all sectors | D410: Dollars per million Btu
B411: NGTCK | C411: Factor for converting natural gas total consumption from physical units to Btu | D411: Thousand Btu per cubic foot
B412: NGTCP | C412: Natural gas total consumption | D412: Million cubic feet
B413: NGTCV | C413: Natural gas total expenditures | D413: Million dollars
B414: NGTPB | C414: Natural gas total consumption per capita | D414: Million Btu
B415: NGTPP | C415: Natural gas total consumption per capita | D415: Thousand cubic feet
B416: NGTXB | C416: Natural gas total end-use consumption | D416: Billion Btu
...

Sheet SEDS_use_all_btu
A1: Data_Status | B1: State | C1: MSN | D1: 2021 | E1: 2022 | F1: 2023 | G1: 2024
A2: 2024P | B2: AK | C2: ABICB | D2: -8 | E2: -6 | F2: -6 | G2: -10
A3: 2024P | B3: AK | C3: ARICB | D3: 13425 | E3: 12981 | F3: 13173 | G3: 13322
A4: 2024P | B4: AK | C4: ARTCB | D4: 13425 | E4: 12981 | F4: 13173 | G4: 13322
A5: 2024P | B5: AK | C5: ARTXB | D5: 13425 | E5: 12981 | F5: 13173 | G5: 13322
A6: 2024P | B6: AK | C6: AVACB | D6: 1037 | E6: 1073 | F6: 1019 | G6: 1096
A7: 2024P | B7: AK | C7: AVTCB | D7: 1037 | E7: 1073 | F7: 1019 | G7: 1096
A8: 2024P | B8: AK | C8: AVTXB | D8: 1037 | E8: 1073 | F8: 1019 | G8: 1096
A9: 2024P | B9: AK | C9: B1ABB | D9: 0 | E9: 0 | F9: 0 | G9: 0
A10: 2024P | B10: AK | C10: B1ACB | D10: 0 | E10: 0 | F10: 0 | G10: 0
A11: 2024P | B11: AK | C11: B1AUB | D11: 0 | E11: 0 | F11: 0 | G11: 0
A12: 2024P | B12: AK | C12: B1RIB | D12: 0 | E12: 0 | F12: 0 | G12: 0
... A26: 2024P | B26: AK | C26: BDRUB | D26: 0 | E26: 0 | F26: 0 | G26: 0
A27: 2024P | B27: AK | C27: BDSAB
A28: 2024P | B28: AK | C28: BDSUB | D28: 0 | E28: 0 | F28: 0 | G28: 0
A29: 2024P | B29: AK | C29: BDTCB | D29: 0 | E29: 0 | F29: 0 | G29: 0
A30: 2024P | B30: AK | C30: BDTXB | D30: 0 | E30: 0 | F30: 0 | G30: 0
A31: 2024P | B31: AK | C31: BDXUB | D31: 0 | E31: 0 | F31: 0 | G31: 0
A32: 2024P | B32: AK | C32: BFLCB | D32: 0 | E32: 0 | F32: 0 | G32: 0
A33: 2024P | B33: AK | C33: BFTCB | D33: 0 | E33: 0 | F33: 0 | G33: 0
A34: 2024P | B34: AK | C34: BMCAS | D34: 62.1 | E34: 66.6 | F34: 63.5 | G34: 69.8
A35: 2024P | B35: AK | C35: BMTCB | D35: 3153 | E35: 3873 | F35: 3431 | G35: 3308
A36: 2024P | B36: AK | C36: BQICB | D36: 0 | E36: 0 | F36: 0 | G36: 0
A37: 2024P | B37: AK | C37: BQTCB | D37: 0 | E37: 0 | F37: 0 | G37: 0
A38: 2024P | B38: AK | C38: BTCAS | D38: 0.1 | E38: 0.1 | F38: 0.4 | G38: 0.4
A39: 2024P | B39: AK | C39: BTGBP | D39: 45 | E39: 92 | F39: 92 | G39: 132
... A347: 2024P | B347: AL | C347: BDRUB | D347: 0 | E347: 0 | F347: 0 | G347: 0
A348: 2024P | B348: AL | C348: BDSAB
A349: 2024P | B349: AL | C349: BDSUB | D349: 1905 | E349: 1745 | F349: 2498 | G349: 2683
A350: 2024P | B350: AL | C350: BDTCB | D350: 3316 | E350: 2976 | F350: 3970 | G350: 4133
A351: 2024P | B351: AL | C351: BDTXB | D351: 3316 | E351: 2976 | F351: 3970 | G351: 4133
A352: 2024P | B352: AL | C352: BDXUB | D352: 1905 | E352: 1745 | F352: 2498 | G352: 2683
A353: 2024P | B353: AL | C353: BFLCB | D353: 22 | E353: 22 | F353: 29 | G353: 26
A354: 2024P | B354: AL | C354: BFTCB | D354: 28786 | E354: 30648 | F354: 30582 | G354: 33095
A355: 2024P | B355: AL | C355: BMCAS | D355: 72.8 | E355: 68.3 | F355: 67.7 | G355: 72.2
A356: 2024P | B356: AL | C356: BMTCB | D356: 198543 | E356: 201913 | F356: 196969 | G356: 202371
A357: 2024P | B357: AL | C357: BQICB | D357: 0 | E357: 0 | F357: 0 | G357: 0
A358: 2024P | B358: AL | C358: BQTCB | D358: 0 | E358: 0 | F358: 0 | G358: 0
A359: 2024P | B359: AL | C359: BTCAS | D359: 1.9 | E359: 3.2 | F359: 5.8 | G359: 0
A360: 2024P | B360: AL | C360: BTGBP | D360: 1 | E360: 1 | F360: 1 | G360: 1
...

Sheet BAADTBVT-USA
A1: BAADTbVT-passengers
A2: Annual Distance (miles/vehicle) | B2: 2024 | C2: 2025 | D2: 2026 | E2: 2027 | F2: 2028 | G2: 2029 | H2: 2030 | I2: 2031 | J2: 2032 | K2: 2033 | L2: 2034 | M2: 2035 | N2: 2036 | O2: 2037 | P2: 2038 | Q2: 2039 | R2: 2040 | S2: 2041 | T2: 2042 | U2: 2043 | V2: 2044 | W2: 2045 | X2: 2046 | Y2: 2047 | Z2: 2048 | AA2: 2049 | AB2: 2050 | AC2: 2048 | AD2: 2049 | AE2: 2050
A3: LDVs | B3: 11354 | C3: 10518 | D3: 10488 | E3: 10461 | F3: 10399 | G3: 10327 | H3: 10237 | I3: 10141 | J3: 10051 | K3: 9948 | L3: 9859 | M3: 9767 | N3: 9694 | O3: 9628 | P3: 9565 | Q3: 9500 | R3: 9440 | S3: 9380 | T3: 9325 | U3: 9274 | V3: 9232 | W3: 9195 | X3: 9164 | Y3: 9133 | Z3: 9112 | AA3: 9095 | AB3: 9092 | AC3: 11804 | AD3: 11849 | AE3: 11900
A4: HDVs | B4: 16361 | C4: 16361 | D4: 16361 | E4: 16361 | F4: 16361 | G4: 16361 | H4: 16361 | I4: 16361 | J4: 16361 | K4: 16361 | L4: 16361 | M4: 16361 | N4: 16361 | O4: 16361 | P4: 16361 | Q4: 16361 | R4: 16361 | S4: 16361 | T4: 16361 | U4: 16361 | V4: 16361 | W4: 16361 | X4: 16361 | Y4: 16361 | Z4: 16361 | AA4: 16361 | AB4: 16361 | AC4: 16680 | AD4: 16680 | AE4: 16680
A5: aircraft | B5: 685003 | C5: 685003 | D5: 685003 | E5: 685003 | F5: 685003 | G5: 685003 | H5: 685003 | I5: 685003 | J5: 685003 | K5: 685003 | L5: 685003 | M5: 685003 | N5: 685003 | O5: 685003 | P5: 685003 | Q5: 685003 | R5: 685003 | S5: 685003 | T5: 685003 | U5: 685003 | V5: 685003 | W5: 685003 | X5: 685003 | Y5: 685003 | Z5: 685003 | AA5: 685003 | AB5: 685003 | AC5: 1366021 | AD5: 1370295 | AE5: 1374610
A6: rail | B6: 395569 | C6: 395569 | D6: 395569 | E6: 395569 | F6: 395569 | G6: 395569 | H6: 395569 | I6: 395569 | J6: 395569 | K6: 395569 | L6: 395569 | M6: 395569 | N6: 395569 | O6: 395569 | P6: 395569 | Q6: 395569 | R6: 395569 | S6: 395569 | T6: 395569 | U6: 395569 | V6: 395569 | W6: 395569 | X6: 395569 | Y6: 395569 | Z6: 395569 | AA6: 395569 | AB6: 395569 | AC6: 395569 | AD6: 395569 | AE6: 395569
A7: ships | B7: 194 | C7: 194 | D7: 194 | E7: 194 | F7: 194 | G7: 194 | H7: 194 | I7: 194 | J7: 194 | K7: 194 | L7: 194 | M7: 194 | N7: 194 | O7: 194 | P7: 194 | Q7: 194 | R7: 194 | S7: 194 | T7: 194 | U7: 194 | V7: 194 | W7: 194 | X7: 194 | Y7: 194 | Z7: 194 | AA7: 194 | AB7: 194 | AC7: 194 | AD7: 194 | AE7: 194
A8: motorbikes | B8: 8797 | C8: 8797 | D8: 8797 | E8: 8797 | F8: 8797 | G8: 8797 | H8: 8797 | I8: 8797 | J8: 8797 | K8: 8797 | L8: 8797 | M8: 8797 | N8: 8797 | O8: 8797 | P8: 8797 | Q8: 8797 | R8: 8797 | S8: 8797 | T8: 8797 | U8: 8797 | V8: 8797 | W8: 8797 | X8: 8797 | Y8: 8797 | Z8: 8797 | AA8: 8797 | AB8: 8797 | AC8: 2093 | AD8: 2093 | AE8: 2093
A10: BAADTbVT-freight
A11: Annual Distance (miles/vehicle) | B11: 2024 | C11: 2025 | D11: 2026 | E11: 2027 | F11: 2028 | G11: 2029 | H11: 2030 | I11: 2031 | J11: 2032 | K11: 2033 | L11: 2034 | M11: 2035 | N11: 2036 | O11: 2037 | P11: 2038 | Q11: 2039 | R11: 2040 | S11: 2041 | T11: 2042 | U11: 2043 | V11: 2044 | W11: 2045 | X11: 2046 | Y11: 2047 | Z11: 2048 | AA11: 2049 | AB11: 2050 | AC11: 2048 | AD11: 2049 | AE11: 2050
A12: LDVs | B12: 9797 | C12: 9797 | D12: 9782 | E12: 9778 | F12: 9750 | G12: 9718 | H12: 9714 | I12: 9691 | J12: 9669 | K12: 9644 | L12: 9645 | M12: 9658 | N12: 9681 | O12: 9721 | P12: 9777 | Q12: 9839 | R12: 9911 | S12: 9969 | T12: 10020 | U12: 10030 | V12: 10027 | W12: 10040 | X12: 10066 | Y12: 10101 | Z12: 10132 | AA12: 10185 | AB12: 10246 | AC12: 10690 | AD12: 10741 | AE12: 10830
A13: HDVs | B13: 35195 | C13: 35195 | D13: 35195 | E13: 35195 | F13: 35195 | G13: 35195 | H13: 35195 | I13: 35195 | J13: 35195 | K13: 35195 | L13: 35195 | M13: 35195 | N13: 35195 | O13: 35195 | P13: 35195 | Q13: 35195 | R13: 35195 | S13: 35195 | T13: 35195 | U13: 35195 | V13: 35195 | W13: 35195 | X13: 35195 | Y13: 35195 | Z13: 35195 | AA13: 35195 | AB13: 35195 | AC13: 31564 | AD13: 31573 | AE13: 31720
A14: aircraft | B14: 889421 | C14: 889421 | D14: 889421 | E14: 889421 | F14: 889421 | G14: 889421 | H14: 889421 | I14: 889421 | J14: 889421 | K14: 889421 | L14: 889421 | M14: 889421 | N14: 889421 | O14: 889421 | P14: 889421 | Q14: 889421 | R14: 889421 | S14: 889421 | T14: 889421 | U14: 889421 | V14: 889421 | W14: 889421 | X14: 889421 | Y14: 889421 | Z14: 889421 | AA14: 889421 | AB14: 889421 | AC14: 988086 | AD14: 988086 | AE14: 988086
A15: rail | B15: 17005 | C15: 17005 | D15: 17005 | E15: 17005 | F15: 17005 | G15: 17005 | H15: 17005 | I15: 17005 | J15: 17005 | K15: 17005 | L15: 17005 | M15: 17005 | N15: 17005 | O15: 17005 | P15: 17005 | Q15: 17005 | R15: 17005 | S15: 17005 | T15: 17005 | U15: 17005 | V15: 17005 | W15: 17005 | X15: 17005 | Y15: 17005 | Z15: 17005 | AA15: 17005 | AB15: 17005 | AC15: 18501 | AD15: 18501 | AE15: 18501
A16: ships | B16: 7513092 | C16: 7513092 | D16: 7513092 | E16: 7513092 | F16: 7513092 | G16: 7513092 | H16: 7513092 | I16: 7513092 | J16: 7513092 | K16: 7513092 | L16: 7513092 | M16: 7513092 | N16: 7513092 | O16: 7513092 | P16: 7513092 | Q16: 7513092 | R16: 7513092 | S16: 7513092 | T16: 7513092 | U16: 7513092 | V16: 7513092 | W16: 7513092 | X16: 7513092 | Y16: 7513092 | Z16: 7513092 | AA16: 7513092 | AB16: 7513092 | AC16: 218680 | AD16: 218680 | AE16: 218680
A17: motorbikes | B17: 0 | C17: 0 | D17: 0 | E17: 0 | F17: 0 | G17: 0 | H17: 0 | I17: 0 | J17: 0 | K17: 0 | L17: 0 | M17: 0 | N17: 0 | O17: 0 | P17: 0 | Q17: 0 | R17: 0 | S17: 0 | T17: 0 | U17: 0 | V17: 0 | W17: 0 | X17: 0 | Y17: 0 | Z17: 0 | AA17: 0 | AB17: 0 | AC17: 0 | AD17: 0 | AE17: 0

Sheet BPoEFUbVT-ships-frgt-dslveh
A1: Percentage Fuel Use (dimensionless) | B1: 2021
A2: electricity | B2: 0
A3: natural gas | B3: 0
A4: petroleum gasoline | B4: 0
A5: petroleum diesel | B5: 0.25
A6: biofuel gasoline | B6: 0
A7: biofuel diesel | B7: 0
A8: jet fuel | B8: 0
A9: heavy or residual fuel oil | B9: 0.75
A10: LPG propane or butane | B10: 0
A11: hydrogen | B11: 0

Sheet Scale to SEDS
B2: 1. Conversion Factors | C2: BTU per Gallon Liquid Fuels
C3: gasoline | D3: 120476
C4: diesel | D4: 137452
C5: billion | D5: =10^9 -> 1000000000
B7: 2. EIA Fuel Consumption | C7: EIA: Diesel and Gas Energy Consumption
C8: SEDS FUEL
C9: billion btu | E9: btu
E10: 2024
A11: JFACB | B11: AVACB | C11: Transportation | D11: JET FUEL | E11: =SUM(SUMIFS(SEDS_use_all_btu!G:G,SEDS_use_all_btu!B:B,About!$B$2,SEDS_use_all_btu!C:C,$A11),SUMIFS(SEDS_use_all_btu!G:G,SEDS_use_all_btu!B:B,About!$B$2,SEDS_use_all_btu!C:C,$B11))*$D$5 -> 107999000000000
A12: BDACB | B12: DFACB | C12: Transportation | D12: DIESEL | E12: =SUM(SUMIFS(SEDS_use_all_btu!G:G,SEDS_use_all_btu!B:B,About!$B$2,SEDS_use_all_btu!C:C,$A12),SUMIFS(SEDS_use_all_btu!G:G,SEDS_use_all_btu!B:B,About!$B$2,SEDS_use_all_btu!C:C,$B12))*$D$5 -> 110235000000000
B13: MGACB | C13: Transportation | D13: GASOLINE | E13: =SUMIFS(SEDS_use_all_btu!G:G,SEDS_use_all_btu!B:B,About!$B$2,SEDS_use_all_btu!C:C,$B13)*$D$5 -> 412731000000000
B14: RFACB | C14: Transportation | D14: RESIDUAL FUEL | E14: =SUMIFS(SEDS_use_all_btu!G:G,SEDS_use_all_btu!B:B,About!$B$2,SEDS_use_all_btu!C:C,$B14)*$D$5 -> 23811000000000
B17: 3. Estimated fuel consumption using US BAAD
C18: we estimate fuel consumption using US miles traveled and then scale to the specific state
E19: Gasoline Fuel | F19: Diesel Fuel | G19: jet fuel
C20: Transportation | E20: petroleum gasoline | F20: petroleum diesel | G20: jet fuel
D21: LDV-psgr | E21: =IFERROR(E101*E117*E132/E86,0) -> 3.4067846e+14 | F21: =IFERROR(F101*F117*F132/F86,0) -> 9.3121341e+11
D22: HDV-psgr | E22: =IFERROR(E102*E118*E133/E87,0) -> 9.6081982e+11 | F22: =IFERROR(F102*F118*F133/F87,0) -> 6.2934085e+12
D23: aircraft-psgr | G23: =IFERROR(G103*G119*G134/G88,0) -> 4.5335011e+13
D24: rail-psgr | E24: =IFERROR(E104*E120*E135/E89,0) -> 0 | F24: =IFERROR(F104*F120*F135/F89,0) -> 2.400306e+12
D25: ships-psgr | E25: =IFERROR(E105*E121*E136/E90,0) -> 2.283688e+12 | F25: =IFERROR(F105*F121*F136/F90,0) -> 5.567181e+11
D26: motorbikes | E26: =IFERROR(E106*E122*E137/E91,0) -> 8.9512649e+11 | F26: =IFERROR(F106*F122*F137/F91,0) -> 0
D27: LDV-frgt | E27: =IFERROR(E107*E123*E138/E92,0) -> 9.2802592e+12 | F27: =IFERROR(F107*F123*F138/F92,0) -> 8.2619793e+12
D28: HDV-frgt | E28: =IFERROR(E108*E124*E139/E93,0) -> 8.1107984e+11 | F28: =IFERROR(F108*F124*F139/F93,0) -> 1.0383828e+14
D29: aircraft-frgt | G29: =IFERROR(G109*G125*G140/G94,0) -> 7.209654e+12
D30: rail-frgt | E30: =IFERROR(E110*E126*E141/E95,0) -> 0 | F30: =IFERROR(F110*F126*F141/F95,0) -> 1.1472981e+13
D31: ships-frgt | E31: =IFERROR(E111*E127*E142/E96,0) -> 0 | F31: =IFERROR(F111*F127*F142/F96,0)*'BPoEFUbVT-ships-frgt-dslveh'!B5 -> 1.2315984e+11
D32: TOTAL | E32: =SUM(E21:E31) -> 3.5490944e+14 | F32: =SUM(F21:F31) -> 1.3387805e+14 | G32: =SUM(G21:G31) -> 5.2544665e+13
C34: percent of fuel consumption
E35: Gasoline Fuel | F35: Diesel Fuel | G35: jet fuel
C36: Transportation | E36: petroleum gasoline | F36: petroleum diesel | G36: jet fuel
D37: LDV-psgr | E37: =E21/E$32 -> 0.95990252 | F37: =F21/F$32 -> 0.0069556841 | G37: =G21/G$32 -> 0
D38: HDV-psgr | E38: =E22/E$32 -> 0.0027072254 | F38: =F22/F$32 -> 0.047008517 | G38: =G22/G$32 -> 0
D39: aircraft-psgr | E39: =E23/E$32 -> 0 | F39: =F23/F$32 -> 0 | G39: =G23/G$32 -> 0.86278999
D40: rail-psgr | E40: =E24/E$32 -> 0 | F40: =F24/F$32 -> 0.017929048 | G40: =G24/G$32 -> 0
D41: ships-psgr | E41: =E25/E$32 -> 0.0064345656 | F41: =F25/F$32 -> 0.0041583973 | G41: =G25/G$32 -> 0
D42: motorbikes | E42: =E26/E$32 -> 0.0025221265 | F42: =F26/F$32 -> 0 | G42: =G26/G$32 -> 0
D43: LDV-frgt | E43: =E27/E$32 -> 0.026148246 | F43: =F27/F$32 -> 0.061712727 | G43: =G27/G$32 -> 0
D44: HDV-frgt | E44: =E28/E$32 -> 0.002285315 | F44: =F28/F$32 -> 0.77561843 | G44: =G28/G$32 -> 0
D45: aircraft-frgt | E45: =E29/E$32 -> 0 | F45: =F29/F$32 -> 0 | G45: =G29/G$32 -> 0.13721001
...

Sheet Annual Service Data_rail only
A1: Agency | B1: City | C1: State | D1: Legacy NTD ID | E1: NTD ID | F1: Organization Type | G1: NTD Reporter Type | H1: Primary UZA Population | I1: Agency VOMS | J1: Mode | K1: Type of Service | L1: Mode VOMS | M1: Mode VOMS Questionable | N1: Max Trains in Operation | O1: Max Trains in Operation Questionable | P1: Average Speed (mi/hr) | Q1: Average Speed (mi/hr) Questionable | R1: Average Passenger Trip Length (mi) | S1: Average Passenger Trip Length (mi) Questionable | T1: Passengers per Hour | U1: Passengers per Hour Questionable | V1: Scheduled Vehicle Revenue Miles | W1: Scheduled Vehicle Revenue Miles Questionable | X1: Vehicle Miles | Y1: Vehicle Miles Questionable | Z1: Vehicle Revenue Miles | AA1: Vehicle Revenue Miles Questionable | AB1: Deadhead Miles | AC1: Deadhead Miles Questionable | AD1: Vehicle Hours | AE1: Vehicle Hours Questionable | AF1: Vehicle Revenue Hours | AG1: Vehicle Revenue Hours Questionable | AH1: Deadhead Hours | AI1: Deadhead Hours Questionable | AJ1: Train Miles | AK1: Train Miles Questionable | AL1: Train Revenue Miles | AM1: Train Revenue Miles Questionable | AN1: Train Hours | AO1: Train Hours Questionable | AP1: Train Revenue Hours | AQ1: Train Revenue Hours Questionable | AR1: Unlinked Passenger Trips | AS1: Unlinked Passenger Trips Questionable | AT1: Passenger Miles | AU1: Passenger Miles Questionable | AV1: Directional Route Miles | AW1: Directional Route Miles Questionable | AX1: Any data questionable
A2: MTA New York City Transit | B2: Brooklyn | C2: NY | D2: 2008 | E2: 20008 | F2: Subsidiary Unit of a Transit Agency, Reporting Separately | G2: Full Reporter | H2: 18351295 | I2: 10427 | J2: HR | K2: DO | L2: 5413 | N2: 527 | P2: 18.2156 | R2: 4.2032 | T2: 62.4037 | V2: 376401985 | X2: 334949157 | Z2: 324782077 | AB2: 10167080 | AD2: 18782357 | AF2: 17829918 | AH2: 952439 | AJ2: 36770774 | AL2: 35625281 | AN2: 2060234 | AP2: 1955760 | AR2: 1112653405 | AT2: 4676670633 | AV2: 493.68 | AX2: No
A3: New Jersey Transit Corporation | B3: Newark | C3: NJ | D3: 2080 | E3: 20080 | F3: Other Publicly-Owned or Privately Chartered Corporation | G3: Full Reporter | H3: 18351295 | I3: 3646 | J3: LR | K3: PT | L3: 42 | N3: 20 | P3: 16.5765 | R3: 3.7544 | T3: 104.7091 | V3: 1809860 | X3: 1929113 | Z3: 1893039 | AB3: 36074 | AD3: 115699 | AF3: 114200 | AH3: 1499 | AJ3: 1096779 | AL3: 1076347 | AN3: 64689 | AP3: 63804 | AR3: 11957780 | AT3: 44894834 | AV3: 34.08 | AX3: No
A4: New Jersey Transit Corporation | B4: Newark | C4: NJ | D4: 2080 | E4: 20080 | F4: Other Publicly-Owned or Privately Chartered Corporation | G4: Full Reporter | H4: 18351295 | I4: 3646 | J4: LR | K4: DO | L4: 15 | N4: 15 | P4: 9.3913 | R4: 2.2517 | T4: 88.6621 | V4: 458806 | X4: 481308 | Z4: 470004 | AB4: 11304 | AD4: 55608 | AF4: 50047 | AH4: 5561 | AJ4: 481308 | AL4: 470004 | AN4: 55608 | AP4: 50047 | AR4: 4437270 | AT4: 9991369 | AV4: 12.42 | AX4: No
A5: New Jersey Transit Corporation | B5: Newark | C5: NJ | D5: 2080 | E5: 20080 | F5: Other Publicly-Owned or Privately Chartered Corporation | G5: Full Reporter | H5: 18351295 | I5: 3646 | J5: CR | K5: DO | L5: 904 | N5: 105 | P5: 32.758 | R5: 22.0101 | T5: 40.0147 | V5: 54847772 | X5: 57155030 | Z5: 54301350 | AB5: 2853680 | AD5: 1953118 | AF5: 1657653 | AH5: 295465 | AJ5: 8422625 | AL5: 7942892 | AN5: 287491 | AP5: 248272 | AR5: 66330426 | AT5: 1459936301 | AV5: 920.4 | AX5: No
A6: Los Angeles County Metropolitan Transportation Authority, dba: Metro | B6: Los Angeles | C6: CA | D6: 9154 | E6: 90154 | F6: Independent Public Agency or Authority of Transit Service | G6: Full Reporter | H6: 12150996 | I6: 3482 | J6: LR | K6: DO | L6: 203 | N6: 74 | P6: 20.558 | R6: 7.5713 | T6: 55.704 | V6: 15592469 | X6: 16090545 | Z6: 15536688 | AB6: 553857 | AD6: 792734 | AF6: 755749 | AH6: 36985 | AJ6: 6384468 | AL6: 6156417 | AN6: 309440 | AP6: 294220 | AR6: 42098255 | AT6: 318737668 | AV6: 171.92 | AX6: No
A7: Los Angeles County Metropolitan Transportation Authority, dba: Metro | B7: Los Angeles | C7: CA | D7: 9154 | E7: 90154 | F7: Independent Public Agency or Authority of Transit Service | G7: Full Reporter | H7: 12150996 | I7: 3482 | J7: HR | K7: DO | L7: 68 | N7: 13 | P7: 21.8993 | R7: 4.8392 | T7: 108.4073 | V7: 6821561 | X7: 6973555 | Z7: 6801301 | AB7: 172254 | AD7: 327668 | AF7: 310572 | AH7: 17096 | AJ7: 1383514 | AL7: 1350454 | AN7: 66480 | AP7: 63158 | AR7: 33668265 | AT7: 162927528 | AV7: 31.9 | AX7: No
A8: Washington Metropolitan Area Transit Authority | B8: Washington | C8: DC | D8: 3030 | E8: 30030 | F8: Independent Public Agency or Authority of Transit Service | G8: Full Reporter | H8: 4586770 | I8: 3304 | J8: HR | K8: DO | L8: 998 | N8: 129 | P8: 23.3386 | R8: 5.6487 | T8: 51.0164 | V8: 81860566 | X8: 82234530 | Z8: 79847615 | AB8: 2386915 | AD8: 3524685 | AF8: 3421264 | AH8: 103421 | AJ8: 11770449 | AL8: 11432619 | AN8: 505929 | AP8: 489793 | AR8: 174540714 | AT8: 985922295 | AV8: 234.2 | AX8: No
A9: Chicago Transit Authority | B9: Chicago | C9: IL | D9: 5066 | E9: 50066 | F9: Independent Public Agency or Authority of Transit Service | G9: Full Reporter | H9: 8608208 | I9: 2703 | J9: HR | K9: DO | L9: 1148 | N9: 158 | P9: 18.0276 | R9: 6.3144 | S9: W | T9: 19.7235 | V9: 82996946 | X9: 70519745 | Z9: 69510641 | AB9: 1009104 | AD9: 4177041 | AF9: 3855798 | AH9: 321243 | AJ9: 10533049 | AL9: 10388783 | AN9: 631507 | AP9: 582079 | AR9: 76049871 | AT9: 480210760 | AU9: W | AV9: 207.84 | AX9: Yes
A10: Massachusetts Bay Transportation Authority | B10: Boston | C10: MA | D10: 1003 | E10: 10003 | F10: Independent Public Agency or Authority of Transit Service | G10: Full Reporter | H10: 4181019 | I10: 2428 | J10: LR | K10: DO | L10: 154 | N10: 86 | P10: 7.3029 | R10: 2.3538 | T10: 57.7745 | V10: 5714964 | X10: 5260506 | Z10: 5241369 | AB10: 19137 | AD10: 726323 | AF10: 717709 | AH10: 8614 | AI10: Q | AJ10: 2876932 | AL10: 2870560 | AN10: 321018 | AP10: 315916 | AR10: 41465243 | AT10: 97602251 | AV10: 51 | AX10: Yes
A11: Massachusetts Bay Transportation Authority | B11: Boston | C11: MA | D11: 1003 | E11: 10003 | F11: Independent Public Agency or Authority of Transit Service | G11: Full Reporter | H11: 4181019 | I11: 2428 | J11: HR | K11: DO | L11: 338 | N11: 56 | P11: 16.7071 | R11: 3.5198 | T11: 87.0464 | V11: 23317516 | X11: 22746421 | Z11: 22203578 | AB11: 542843 | AD11: 1393950 | AF11: 1328990 | AH11: 64960 | AJ11: 3791070 | AL11: 3700596 | AN11: 253575 | AP11: 242748 | AR11: 115683733 | AT11: 407181618 | AV11: 76.3 | AX11: No
A12: Massachusetts Bay Transportation Authority | B12: Boston | C12: MA | D12: 1003 | E12: 10003 | F12: Independent Public Agency or Authority of Transit Service | G12: Full Reporter | H12: 4181019 | I12: 2428 | J12: CR | K12: PT | L12: 436 | N12: 67 | P12: 29.7292 | R12: 20.751 | T12: 33.01 | V12: 22195183 | X12: 22810502 | Z12: 22300695 | AB12: 509807 | AD12: 768699 | AF12: 750128 | AH12: 18571 | AJ12: 4189947 | AL12: 4093393 | AN12: 141215 | AP12: 137738 | AR12: 24761705 | AT12: 513830968 | AV12: 776.08 | AX12: No
A13: Southeastern Pennsylvania Transportation Authority | B13: Philadelphia | C13: PA | D13: 3019 | E13: 30019 | F13: Independent Public Agency or Authority of Transit Service | G13: Full Reporter | H13: 5441567 | I13: 2406 | J13: HR | K13: DO | L13: 286 | N13: 61 | P13: 17.0971 | R13: 4.4254 | S13: W | T13: 75.5141 | U13: W | V13: 16431036 | X13: 16168711 | Z13: 16089713 | AB13: 78998 | AD13: 945947 | AF13: 941080 | AH13: 4867 | AJ13: 3121305 | AL13: 3101700 | AN13: 182557 | AP13: 181391 | AR13: 71064786 | AS13: W | AT13: 314489396 | AU13: W | AV13: 74.9 | AX13: Yes
A14: Southeastern Pennsylvania Transportation Authority | B14: Philadelphia | C14: PA | D14: 3019 | E14: 30019 | F14: Independent Public Agency or Authority of Transit Service | G14: Full Reporter | H14: 5441567 | I14: 2406 | J14: CR | K14: DO | L14: 357 | N14: 84 | P14: 19.6909 | R14: 13.4494 | S14: W | T14: 29.7939 | U14: W | V14: 16896038 | X14: 17498310 | Z14: 16621821 | AB14: 876489 | AD14: 882766 | AF14: 844136 | AH14: 38630 | AJ14: 4453116 | AL14: 4225898 | AN14: 224140 | AP14: 214329 | AR14: 25150117 | AS14: W | AT14: 338253606 | AU14: W | AV14: 446.94 | AX14: Yes
A15: Metropolitan Transit Authority of Harris County, Texas, dba: Metro | B15: Houston | C15: TX | D15: 6008 | E15: 60008 | F15: Independent Public Agency or Authority of Transit Service | G15: Full Reporter | H15: 4944332 | I15: 2157 | J15: LR | K15: DO | L15: 56 | N15: 29 | P15: 12.1474 | R15: 2.9095 | T15: 48.3795 | V15: 3257209 | X15: 3247125 | Z15: 3236011 | AB15: 11114 | AD15: 268268 | AF15: 266396 | AH15: 1872 | AJ15: 1940638 | AL15: 1929524 | AN15: 176143 | AP15: 174271 | AR15: 12888105 | AT15: 37497523 | AV15: 43.59 | AX15: No
A16: Maryland Transit Administration | B16: Baltimore | C16: MD | D16: 3034 | E16: 30034 | F16: State Government Unit or Department of Transportation | G16: Full Reporter | H16: 2203663 | I16: 1888 | J16: LR | K16: DO | L16: 38 | N16: 18 | P16: 19.6769 | R16: 5.7128 | S16: W | T16: 35.3738 | V16: 2774375 | X16: 2676810 | Z16: 2588105 | AB16: 88705 | AD16: 138492 | AF16: 131530 | AH16: 6962 | AJ16: 1046361 | AL16: 1044905 | AN16: 58730 | AP16: 58193 | AR16: 4652718 | AT16: 26579844 | AU16: W | AV16: 57.6 | AX16: Yes
A17: Maryland Transit Administration | B17: Baltimore | C17: MD | D17: 3034 | E17: 30034 | F17: State Government Unit or Department of Transportation | G17: Full Reporter | H17: 2203663 | I17: 1888 | J17: HR | K17: DO | L17: 54 | N17: 9 | P17: 26.0926 | R17: 4.7674 | S17: W | T17: 36.698 | V17: 4289979 | X17: 4659371 | Z17: 4169492 | AB17: 489879 | AD17: 180401 | AF17: 159796 | AH17: 20605 | AJ17: 845652 | AL17: 734915 | AN17: 32887 | AP17: 28462 | AR17: 5864191 | AT17: 27957087 | AU17: W | AV17: 29.4 | AX17: Yes
A18: Maryland Transit Administration | B18: Baltimore | C18: MD | D18: 3034 | E18: 30034 | F18: State Government Unit or Department of Transportation | G18: Full Reporter | H18: 2203663 | I18: 1888 | J18: CR | K18: PT | L18: 149 | N18: 28 | P18: 38.3283 | R18: 29.5846 | S18: W | T18: 45.7479 | V18: 6001808 | X18: 5996542 | Z18: 5596811 | AB18: 399731 | AD18: 155174 | AF18: 146023 | AH18: 9151 | AJ18: 1094365 | AL18: 1036558 | AN18: 30902 | AP18: 28513 | AR18: 6680248 | AT18: 197632189 | AU18: W | AV18: 400.4 | AX18: Yes
A19: County of Miami-Dade, dba: Transportation & Public Work | B19: Miami | C19: FL | D19: 4034 | E19: 40034 | F19: City, County or Local Government Unit or Department of Transportation | G19: Full Reporter | H19: 5502379 | I19: 1452 | J19: HR | K19: DO | L19: 76 | N19: 18 | P19: 21.7622 | R19: 7.3831 | S19: W | T19: 35.9601 | V19: 7212362 | X19: 7598157 | Z19: 7178627 | AB19: 419530 | AD19: 362201 | AF19: 329867 | AH19: 32334 | AJ19: 1899556 | AL19: 1794673 | AN19: 90549 | AP19: 82465 | AR19: 11862059 | AT19: 87578321 | AU19: W | AV19: 49.84 | AX19: Yes
A20: Denver Regional Transportation District | B20: Denver | C20: CO | D20: 8006 | E20: 80006 | F20: Independent Public Agency or Authority of Transit Service | G20: Full Reporter | H20: 2374203 | I20: 1431 | J20: LR | K20: DO | L20: 156 | N20: 41 | P20: 17.2002 | R20: 6.9673 | T20: 19.8586 | V20: 9004264 | X20: 9327859 | Z20: 9063803 | AB20: 264056 | AD20: 590892 | AF20: 526960 | AH20: 63932 | AJ20: 3900081 | AL20: 3745938 | AN20: 267096 | AP20: 226007 | AR20: 10464678 | AT20: 72910951 | AV20: 119.78 | AX20: No
A21: Denver Regional Transportation District | B21: Denver | C21: CO | D21: 8006 | E21: 80006 | F21: Independent Public Agency or Authority of Transit Service | G21: Full Reporter | H21: 2374203 | I21: 1431 | J21: CR | K21: PT | L21: 44 | N21: 12 | P21: 27.5631 | R21: 11.5166 | T21: 21.7837 | V21: 6222945 | X21: 6197643 | Z21: 6048702 | AB21: 148941 | AD21: 228257 | AF21: 219449 | AH21: 8808 | AJ21: 2010537 | AL21: 1917204 | AN21: 74540 | AP21: 70293 | AR21: 4780402 | AT21: 55053882 | AV21: 72.76 | AX21: No
A22: Denver Regional Transportation District | B22: Denver | C22: CO | D22: 8006 | E22: 80006 | F22: Independent Public Agency or Authority of Transit Service | G22: Full Reporter | H22: 2374203 | I22: 1431 | J22: CR | K22: DO | L22: 8 | N22: 3 | P22: 20.4842 | R22: 8.6131 | T22: 18.0161 | V22: 203262 | X22: 223786 | Z22: 197570 | AB22: 26216 | AD22: 12511 | AF22: 9645 | AH22: 2866 | AJ22: 115030 | AL22: 98743 | AN22: 6243 | AP22: 4937 | AR22: 173765 | AT22: 1496661 | AV22: 26.32 | AX22: No
A23: Metro-North Commuter Railroad Company, dba: MTA Metro-North Railroad | B23: New York | C23: NY | D23: 2078 | E23: 20078 | F23: Subsidiary Unit of a Transit Agency, Reporting Separately | G23: Full Reporter | H23: 18351295 | I23: 1133 | J23: CR | K23: DO | L23: 1122 | N23: 135 | P23: 31.2997 | R23: 22.8524 | S23: W | T23: 18.8824 | V23: 47488237 | X23: 53139671 | Z23: 48719168 | AB23: 4420503 | AD23: 1709469 | AF23: 1556539 | AH23: 152930 | AJ23: 7201726 | AL23: 6564652 | AN23: 225218 | AP23: 203440 | AR23: 29391259 | AT23: 671661254 | AU23: W | AV23: 545.74 | AX23: Yes
A24: Dallas Area Rapid Transit | B24: Dallas | C24: TX | D24: 6056 | E24: 60056 | F24: Independent Public Agency or Authority of Transit Service | G24: Full Reporter | H24: 5121892 | I24: 1082 | J24: LR | K24: DO | L24: 117 | N24: 44 | P24: 20.5101 | R24: 8.1822 | T24: 41.7424 | V24: 9953657 | X24: 9937246 | Z24: 9866803 | AB24: 70443 | AD24: 486886 | AF24: 481071 | AH24: 5815 | AJ24: 5348975 | AL24: 5310292 | AN24: 261692 | AP24: 258495 | AR24: 20081036 | AT24: 164306746 | AV24: 182.44 | AX24: No
A25: Dallas Area Rapid Transit | B25: Dallas | C25: TX | D25: 6056 | E25: 60056 | F25: Independent Public Agency or Authority of Transit Service | G25: Full Reporter | H25: 5121892 | I25: 1082 | J25: CR | K25: PT | L25: 23 | N25: 3 | P25: 22.474 | R25: 17.3008 | T25: 20.2524 | V25: 1390207 | X25: 1437340 | Z25: 1404961 | AB25: 32379 | AD25: 63773 | AF25: 62515 | AH25: 1258 | AJ25: 506768 | AL25: 495677 | AN25: 22535 | AP25: 22090 | AR25: 1266076 | AT25: 21904126 | AV25: 72.3 | AX25: No
A26: Utah Transit Authority | B26: Salt Lake City | C26: UT | D26: 8001 | E26: 80001 | F26: Independent Public Agency or Authority of Transit Service | G26: Full Reporter | H26: 1021243 | I26: 1081 | J26: LR | K26: DO | L26: 89 | N26: 22 | P26: 17.1928 | R26: 4.7437 | T26: 23.1914 | V26: 6112222 | X26: 6204641 | Z26: 6114108 | AB26: 90533 | AD26: 367255 | AF26: 355621 | AH26: 11634 | AJ26: 2255583 | AL26: 2223959 | AN26: 136213 | AP26: 131989 | AR26: 8247364 | AT26: 39122864 | AV26: 93.91 | AX26: No
A27: Utah Transit Authority | B27: Salt Lake City | C27: UT | D27: 8001 | E27: 80001 | F27: Independent Public Agency or Authority of Transit Service | G27: Full Reporter | H27: 1021243 | I27: 1081 | J27: CR | K27: DO | L27: 50 | N27: 9 | P27: 32.4736 | R27: 25.6439 | T27: 16.2748 | V27: 4053946 | X27: 4051779 | Z27: 4039581 | AB27: 12198 | AD27: 128674 | AF27: 124396 | AH27: 4278 | AJ27: 1067699 | AL27: 1064546 | AN27: 33846 | AP27: 32741 | AR27: 2024524 | AT27: 51916777 | AV27: 174.46 | AX27: No
A28: Northeast Illinois Regional Commuter Railroad Corporation, dba: Metra | B28: Chicago | C28: IL | D28: 5118 | E28: 50118 | F28: Independent Public Agency or Authority of Transit Service | G28: Full Reporter | H28: 8608208 | I28: 1066 | J28: CR | K28: PT | L28: 527 | N28: 40 | P28: 30.9325 | R28: 21.7125 | T28: 18.9791 | V28: 16284231 | X28: 16302662 | Z28: 15388572 | AB28: 914090 | AD28: 520340 | AF28: 497488 | AH28: 22852 | AJ28: 2394714 | AL28: 2258067 | AN28: 76862 | AP28: 73504 | AR28: 9441882 | AT28: 205006670 | AV28: 399.6 | AX28: No
A29: Northeast Illinois Regional Commuter Railroad Corporation, dba: Metra | B29: Chicago | C29: IL | D29: 5118 | E29: 50118 | F29: Independent Public Agency or Authority of Transit Service | G29: Full Reporter | H29: 8608208 | I29: 1066 | J29: CR | K29: DO | L29: 539 | N29: 53 | P29: 29.0824 | R29: 21.1725 | T29: 13.8796 | V29: 16028080 | X29: 15585872 | Z29: 15273179 | AB29: 312693 | AD29: 535954 | AF29: 525169 | AH29: 10785 | AJ29: 2545102 | AL29: 2494601 | AN29: 89035 | AP29: 87312 | AR29: 7289149 | AT29: 154329520 | AV29: 575.4 | AX29: No
A30: MTA Long Island Rail Road | B30: Jamaica | C30: NY | D30: 2100 | E30: 20100 | F30: Subsidiary Unit of a Transit Agency, Reporting Separately | G30: Full Reporter | H30: 18351295 | I30: 1022 | J30: CR | K30: DO | L30: 1022 | N30: 107 | P30: 29.2123 | R30: 28.2692 | S30: W | T30: 20.566 | U30: W | V30: 61301708 | X30: 68469245 | Z30: 61766650 | AB30: 6702595 | AD30: 2305899 | AF30: 2114409 | AH30: 191490 | AJ30: 7765181 | AL30: 6968685 | AN30: 266731 | AP30: 199752 | AR30: 43484907 | AS30: W | AT30: 1229284540 | AU30: W | AV30: 638.2 | AX30: Yes
A31: City and County of San Francisco, dba: San Francisco Municipal Transportation Agency (MUNI) | B31: San Francisco | C31: CA | D31: 9015 | E31: 90015 | F31: City, County or Local Government Unit or Department of Transportation | G31: Full Reporter | H31: 3281212 | I31: 996 | J31: LR | K31: DO | L31: 149 | N31: 141 | P31: 9.497 | R31: 2.7421 | T31: 76.5848 | V31: 4944335 | X31: 4660934 | Z31: 4640244 | AB31: 20690 | AD31: 491748 | AF31: 488601 | AH31: 3147 | AJ31: 3097363 | AL31: 3084167 | AN31: 326422 | AP31: 324323 | AR31: 37419416 | AT31: 102607757 | AV31: 64.4 | AX31: No
A32: Tri-County Metropolitan Transportation District of Oregon, dba: TriMet | B32: Portland | C32: OR | D32: 8 | E32: 8 | F32: Independent Public Agency or Authority of Transit Service | G32: Full Reporter | H32: 1849898 | I32: 982 | J32: LR | K32: DO | L32: 116 | N32: 55 | P32: 14.1369 | R32: 5.2552 | T32: 48.3924 | V32: 8977599 | X32: 8981104 | Z32: 8864217 | AB32: 116887 | AD32: 636882 | AF32: 627025 | AH32: 9857 | AJ32: 4501055 | AL32: 4442373 | AN32: 319090 | AP32: 314140 | AR32: 30343267 | AT32: 159458488 | AV32: 118.91 | AX32: No
A33: Metropolitan Atlanta Rapid Transit Authority | B33: Atlanta | C33: GA | D33: 4022 | E33: 40022 | F33: Independent Public Agency or Authority of Transit Service | G33: Full Reporter | H33: 4515419 | I33: 943 | J33: HR | K33: DO | L33: 212 | N33: 39 | P33: 26.494 | R33: 7.2762 | T33: 58.7473 | V33: 20499724 | X33: 21145309 | Z33: 20430752 | AB33: 714557 | AD33: 794602 | AF33: 771146 | AH33: 23456 | AJ33: 3715370 | AL33: 3628801 | AN33: 143614 | AP33: 139086 | AR33: 45302714 | AT33: 329631085 | AV33: 96.06 | AX33: No
A34: Port Authority of Allegheny County | B34: Pittsburgh | C34: PA | D34: 3022 | E34: 30022 | F34: Independent Public Agency or Authority of Transit Service | G34: Full Reporter | H34: 1733853 | I34: 930 | J34: LR | K34: DO | L34: 58 | N34: 29 | P34: 12.9097 | R34: 4.0318 | T34: 37.5305 | V34: 2027777 | X34: 1999310 | Z34: 1916792 | AB34: 82518 | AD34: 155486 | AF34: 148477 | AH34: 7009 | AJ34: 1497766 | AL34: 1442245 | AN34: 116738 | AP34: 112071 | AR34: 5572417 | AT34: 22466673 | AV34: 49.64 | AX34: No
A35: San Diego Metropolitan Transit System | B35: San Diego | C35: CA | D35: 9026 | E35: 90026 | F35: Independent Public Agency or Authority of Transit Service | G35: Full Reporter | H35: 2956746 | I35: 906 | J35: LR | K35: DO | L35: 103 | N35: 35 | P35: 18.1208 | R35: 6.0708 | T35: 62.966 | V35: 9662505 | X35: 9410942 | Z35: 9210076 | AB35: 200866 | AD35: 527144 | AF35: 508259 | AH35: 18885 | AJ35: 3279625 | AL35: 3207856 | AN35: 183992 | AP35: 177429 | AR35: 32003027 | AT35: 194284885 | AV35: 108.4 | AX35: No
A36: Metro Transit, dba: Metro Transit | B36: Minneapolis | C36: MN | D36: 5027 | E36: 50027 | F36: Subsidiary Unit of a Transit Agency, Reporting Separately | G36: Full Reporter | H36: 2650890 | I36: 823 | J36: LR | K36: DO | L36: 76 | N36: 23 | P36: 11.9859 | R36: 3.9724 | S36: W | T36: 30.4653 | V36: 4237895 | X36: 4129925 | Z36: 4034814 | AB36: 95111 | AD36: 354913 | AF36: 336629 | AH36: 18284 | AJ36: 1500026 | AL36: 1436691 | AN36: 125192 | AP36: 118274 | AR36: 10255520 | AT36: 40738989 | AU36: W | AV36: 44.26 | AX36: Yes
A37: Metro Transit, dba: Metro Transit | B37: Minneapolis | C37: MN | D37: 5027 | E37: 50027 | F37: Subsidiary Unit of a Transit Agency, Reporting Separately | G37: Full Reporter | H37: 2650890 | I37: 823 | J37: CR | K37: PT | L37: 20 | N37: 4 | P37: 43.769 | R37: 24.7025 | S37: W | T37: 26.3444 | V37: 253487 | X37: 256360 | Z37: 253291 | AB37: 3069 | AD37: 6199 | AF37: 5787 | AH37: 412 | AJ37: 64139 | AL37: 63372 | AN37: 1552 | AP37: 1448 | AR37: 152455 | AT37: 3766017 | AU37: W | AV37: 77.9 | AX37: Yes
A38: Santa Clara Valley Transportation Authority | B38: San Jose | C38: CA | D38: 9013 | E38: 90013 | F38: Independent Public Agency or Authority of Transit Service | G38: Full Reporter | H38: 1664496 | I38: 635 | J38: LR | K38: DO | L38: 61 | N38: 29 | P38: 14.6876 | R38: 5.3386 | T38: 31.9576 | V38: 3049391 | X38: 3045104 | Z38: 2886997 | AB38: 158107 | AD38: 208938 | AF38: 196560 | AH38: 12378 | AJ38: 1824324 | AL38: 1733696 | AN38: 131172 | AP38: 123509 | AR38: 6281578 | AT38: 33535077 | AV38: 80.96 | AX38: No
A39: San Francisco Bay Area Rapid Transit District | B39: Oakland | C39: CA | D39: 9003 | E39: 90003 | F39: Independent Public Agency or Authority of Transit Service | G39: Full Reporter | H39: 3281212 | I39: 616 | J39: HR | K39: DO | L39: 599 | N39: 56 | P39: 34.8299 | Q39: W | R39: 13.963 | T39: 44.2609 | U39: W | V39: 69597595 | X39: 72050709 | Z39: 69799195 | AB39: 2251514 | AD39: 2377255 | AF39: 2004002 | AG39: W | AH39: 373253 | AJ39: 8255518 | AL39: 7973519 | AN39: 277276 | AP39: 229211 | AR39: 88698878 | AT39: 1238506222 | AV39: 239.42 | AX39: Yes
A40: Bi-State Development Agency of the Missouri-Illinois Metropolitan District, dba: St. Louis Metro | B40: Saint Louis | C40: MO | D40: 7006 | E40: 70006 | F40: Independent Public Agency or Authority of Transit Service | G40: Full Reporter | H40: 2150706 | I40: 493 | J40: LR | K40: DO | L40: 50 | N40: 25 | P40: 23.1905 | R40: 6.749 | T40: 41.7394 | V40: 5954691 | X40: 5905439 | Z40: 5839491 | AB40: 65948 | AD40: 256119 | AF40: 251805 | AH40: 4314 | AJ40: 2952712 | AL40: 2919745 | AN40: 128060 | AP40: 125902 | AR40: 10510179 | AT40: 70933375 | AV40: 91.06 | AX40: No
...

Sheet Fuel and Energy_rail only
A1: Agency | B1: City | C1: State | D1: Legacy NTD ID | E1: NTD ID | F1: Organization Type | G1: Primary UZA Population | H1: Agency VOMS | I1: Mode | J1: TOS | K1: Mode VOMS | L1: Fuel/Energy Used: | M1: Diesel (gal) | N1: Diesel (gal) Questionable | O1: Gasoline (gal) | P1: Gasoline (gal) Questionable | Q1: Liquefied Petroleum Gas (gal equivalent) | R1: Liquefied Petroleum Gas (gal equivalent) Questionable | S1: Compressed Natural Gas (gal equivalent) | T1: Compressed Natural Gas (gal equivalent) Questionable | U1: Bio-Diesel (gal) | V1: Bio-Diesel (gal) Questionable | W1: Other Fuel (gal/gal equivalent) | X1: Other Fuel (gal/gal equivalent) Questionable | Y1: Electric Propulsion (kwh) | Z1: Electric Propulsion (kwh) Questionable | AA1: Electric Battery (kwh) | AB1: Electric Battery (kwh) Questionable | AC1: Miles Traveled by Vehicles Fueled by: | AD1: Diesel | AE1: Diesel Questionable | AF1: Gasoline | AG1: Gasoline Questionable | AH1: Liquefied Petroleum Gas | AI1: Liquefied Petroleum Gas Questionable | AJ1: Compressed Natural Gas | AK1: Compressed Natural Gas Questionable | AL1: Other Fuel | AM1: Other Fuel Questionable | AN1: Electric Propulsion | AO1: Electric Propulsion Questionable | AP1: Electric Battery | AQ1: Electric Battery Questionable | AR1: Miles per Gallon/KwH: | AS1: Diesel (mpg) | AT1: Diesel (mpg) Questionable | AU1: Gasoline (mpg) | AV1: Gasoline (mpg) Questionable | AW1: Liquefied Petroleum Gas (mpg) | AX1: Liquefied Petroleum Gas (mpg) Questionable | AY1: Compressed Natural Gas (mpg) | AZ1: Compressed Natural Gas (mpg) Questionable | BA1: Other Fuel (mpg) | BB1: Other Fuel (mpg) Questionable | BC1: Electric Propulsion (mi/kwh) | BD1: Electric Propulsion (mi/kwh) Questionable | BE1: Electric Battery (mi/kwh) | BF1: Electric Battery (mi/kwh) Questionable | BG1: Any data questionable?
A2: MTA New York City Transit | B2: Brooklyn | C2: NY | D2: 2008 | E2: 20008 | F2: Subsidiary Unit of a Transit Agency, Reporting Separately | G2: 18351295 | H2: 10427 | I2: HR | J2: DO | K2: 5413 | M2: 0 | O2: 0 | Q2: 0 | S2: 0 | U2: 0 | W2: 0 | Y2: 1596235000 | AA2: 0 | AD2: 0 | AF2: 0 | AH2: 0 | AJ2: 0 | AL2: 0 | AN2: 335497633 | AP2: 0 | BC2: 0.2102 | BG2: No
A3: New Jersey Transit Corporation | B3: Newark | C3: NJ | D3: 2080 | E3: 20080 | F3: Other Publicly-Owned or Privately Chartered Corporation | G3: 18351295 | H3: 3646 | I3: CR | J3: DO | K3: 904 | M3: 13166567 | O3: 0 | Q3: 0 | S3: 0 | U3: 0 | W3: 0 | Y3: 359673989 | AA3: 0 | AD3: 2485889 | AF3: 0 | AH3: 0 | AJ3: 0 | AL3: 1663636 | AN3: 8381067 | AP3: 0 | AS3: 0.1888 | BC3: 0.0233 | BG3: No
A4: New Jersey Transit Corporation | B4: Newark | C4: NJ | D4: 2080 | E4: 20080 | F4: Other Publicly-Owned or Privately Chartered Corporation | G4: 18351295 | H4: 3646 | I4: LR | J4: PT | K4: 42 | M4: 0 | O4: 0 | Q4: 0 | S4: 0 | U4: 0 | W4: 0 | Y4: 27163871 | AA4: 0 | AD4: 0 | AF4: 0 | AH4: 0 | AJ4: 0 | AL4: 0 | AN4: 2073346 | AP4: 0 | BC4: 0.0763 | BG4: No
A5: New Jersey Transit Corporation | B5: Newark | C5: NJ | D5: 2080 | E5: 20080 | F5: Other Publicly-Owned or Privately Chartered Corporation | G5: 18351295 | H5: 3646 | I5: LR | J5: DO | K5: 15 | M5: 0 | O5: 0 | Q5: 0 | S5: 0 | U5: 0 | W5: 0 | Y5: 6694675 | AA5: 0 | AD5: 0 | AF5: 0 | AH5: 0 | AJ5: 0 | AL5: 0 | AN5: 492775 | AP5: 0 | BC5: 0.0736 | BG5: No
A6: Los Angeles County Metropolitan Transportation Authority, dba: Metro | B6: Los Angeles | C6: CA | D6: 9154 | E6: 90154 | F6: Independent Public Agency or Authority of Transit Service | G6: 12150996 | H6: 3482 | I6: HR | J6: DO | K6: 68 | M6: 0 | O6: 0 | Q6: 0 | S6: 0 | U6: 0 | W6: 0 | Y6: 82163176 | AA6: 0 | AD6: 0 | AF6: 0 | AH6: 0 | AJ6: 0 | AL6: 0 | AN6: 6909214 | AP6: 0 | BC6: 0.0841 | BG6: No
A7: Los Angeles County Metropolitan Transportation Authority, dba: Metro | B7: Los Angeles | C7: CA | D7: 9154 | E7: 90154 | F7: Independent Public Agency or Authority of Transit Service | G7: 12150996 | H7: 3482 | I7: LR | J7: DO | K7: 203 | M7: 0 | O7: 0 | Q7: 0 | S7: 0 | U7: 0 | W7: 0 | Y7: 144995154 | AA7: 0 | AD7: 0 | AF7: 0 | AH7: 0 | AJ7: 0 | AL7: 0 | AN7: 16469107 | AP7: 0 | BC7: 0.1136 | BG7: No
A8: Washington Metropolitan Area Transit Authority | B8: Washington | C8: DC | D8: 3030 | E8: 30030 | F8: Independent Public Agency or Authority of Transit Service | G8: 4586770 | H8: 3304 | I8: HR | J8: DO | K8: 998 | M8: 0 | O8: 0 | Q8: 0 | S8: 0 | U8: 0 | W8: 0 | Y8: 576455528 | AA8: 0 | AD8: 0 | AF8: 0 | AH8: 0 | AJ8: 0 | AL8: 0 | AN8: 64920984 | AP8: 0 | BC8: 0.1126 | BG8: No
A9: Chicago Transit Authority | B9: Chicago | C9: IL | D9: 5066 | E9: 50066 | F9: Independent Public Agency or Authority of Transit Service | G9: 8608208 | H9: 2703 | I9: HR | J9: DO | K9: 1148 | M9: 0 | O9: 0 | Q9: 0 | S9: 0 | U9: 0 | W9: 0 | Y9: 366545522 | AA9: 0 | AD9: 0 | AF9: 0 | AH9: 0 | AJ9: 0 | AL9: 0 | AN9: 63157258 | AP9: 0 | BC9: 0.1723 | BG9: No
A10: Massachusetts Bay Transportation Authority | B10: Boston | C10: MA | D10: 1003 | E10: 10003 | F10: Independent Public Agency or Authority of Transit Service | G10: 4181019 | H10: 2428 | I10: CR | J10: PT | K10: 436 | M10: 13360985 | O10: 0 | Q10: 0 | S10: 0 | U10: 0 | W10: 0 | Y10: 0 | AA10: 0 | AD10: 4339139 | AF10: 0 | AH10: 0 | AJ10: 0 | AL10: 0 | AN10: 0 | AP10: 0 | AS10: 0.3248 | BG10: No
A11: Massachusetts Bay Transportation Authority | B11: Boston | C11: MA | D11: 1003 | E11: 10003 | F11: Independent Public Agency or Authority of Transit Service | G11: 4181019 | H11: 2428 | I11: HR | J11: DO | K11: 338 | M11: 0 | O11: 0 | Q11: 0 | S11: 0 | U11: 0 | W11: 0 | Y11: 178406868 | AA11: 0 | AD11: 0 | AF11: 0 | AH11: 0 | AJ11: 0 | AL11: 0 | AN11: 22078161 | AP11: 0 | BC11: 0.1238 | BG11: No
A12: Massachusetts Bay Transportation Authority | B12: Boston | C12: MA | D12: 1003 | E12: 10003 | F12: Independent Public Agency or Authority of Transit Service | G12: 4181019 | H12: 2428 | I12: LR | J12: DO | K12: 154 | M12: 0 | O12: 0 | Q12: 0 | S12: 0 | U12: 0 | W12: 0 | Y12: 46803331 | AA12: 0 | AD12: 0 | AF12: 0 | AH12: 0 | AJ12: 0 | AL12: 0 | AN12: 5523588 | AP12: 0 | BC12: 0.118 | BG12: No
A13: Southeastern Pennsylvania Transportation Authority | B13: Philadelphia | C13: PA | D13: 3019 | E13: 30019 | F13: Independent Public Agency or Authority of Transit Service | G13: 5441567 | H13: 2406 | I13: CR | J13: DO | K13: 357 | M13: 0 | O13: 0 | Q13: 0 | S13: 0 | U13: 0 | W13: 0 | Y13: 190958248 | AA13: 0 | AD13: 0 | AF13: 0 | AH13: 0 | AJ13: 0 | AL13: 0 | AN13: 15598066 | AP13: 0 | BC13: 0.0817 | BG13: No
A14: Southeastern Pennsylvania Transportation Authority | B14: Philadelphia | C14: PA | D14: 3019 | E14: 30019 | F14: Independent Public Agency or Authority of Transit Service | G14: 5441567 | H14: 2406 | I14: HR | J14: DO | K14: 286 | M14: 0 | O14: 0 | Q14: 0 | S14: 0 | U14: 0 | W14: 0 | Y14: 125067726 | AA14: 0 | AD14: 0 | AF14: 0 | AH14: 0 | AJ14: 0 | AL14: 0 | AN14: 14000061 | AP14: 0 | BC14: 0.1119 | BG14: No
A15: Metropolitan Transit Authority of Harris County, Texas, dba: Metro | B15: Houston | C15: TX | D15: 6008 | E15: 60008 | F15: Independent Public Agency or Authority of Transit Service | G15: 4944332 | H15: 2157 | I15: LR | J15: DO | K15: 56 | M15: 0 | O15: 0 | Q15: 0 | S15: 0 | U15: 0 | W15: 0 | Y15: 20764234 | AA15: 0 | AD15: 0 | AF15: 0 | AH15: 0 | AJ15: 0 | AL15: 0 | AN15: 3420524 | AP15: 0 | BC15: 0.1647 | BG15: No
A16: Maryland Transit Administration | B16: Baltimore | C16: MD | D16: 3034 | E16: 30034 | F16: State Government Unit or Department of Transportation | G16: 2203663 | H16: 1888 | I16: HR | J16: DO | K16: 54 | M16: 0 | O16: 0 | Q16: 0 | S16: 0 | U16: 0 | W16: 0 | Y16: 44465246 | AA16: 0 | AD16: 0 | AF16: 0 | AH16: 0 | AJ16: 0 | AL16: 0 | AN16: 0 | AP16: 0 | BC16: 0 | BG16: No
A17: Maryland Transit Administration | B17: Baltimore | C17: MD | D17: 3034 | E17: 30034 | F17: State Government Unit or Department of Transportation | G17: 2203663 | H17: 1888 | I17: LR | J17: DO | K17: 38 | M17: 0 | O17: 0 | Q17: 0 | S17: 0 | U17: 0 | W17: 0 | Y17: 25044315 | AA17: 0 | AD17: 0 | AF17: 0 | AH17: 0 | AJ17: 0 | AL17: 0 | AN17: 2679810 | AP17: 0 | BC17: 0.107 | BG17: No
A18: Maryland Transit Administration | B18: Baltimore | C18: MD | D18: 3034 | E18: 30034 | F18: State Government Unit or Department of Transportation | G18: 2203663 | H18: 1888 | I18: CR | J18: PT | K18: 149 | M18: 3709703 | O18: 0 | Q18: 0 | S18: 0 | U18: 0 | W18: 0 | Y18: 21715405 | AA18: 0 | AD18: 764117 | AF18: 0 | AH18: 0 | AJ18: 0 | AL18: 0 | AN18: 163832 | AP18: 0 | AS18: 0.206 | BC18: 0.0075 | BG18: No
A19: County of Miami-Dade, dba: Transportation & Public Work | B19: Miami | C19: FL | D19: 4034 | E19: 40034 | F19: City, County or Local Government Unit or Department of Transportation | G19: 5502379 | H19: 1452 | I19: HR | J19: DO | K19: 76 | M19: 0 | O19: 0 | Q19: 0 | S19: 0 | U19: 0 | W19: 0 | Y19: 66954261 | AA19: 0 | AD19: 0 | AF19: 0 | AH19: 0 | AJ19: 0 | AL19: 0 | AN19: 559892 | AP19: 0 | BC19: 0.0084 | BG19: No
A20: Denver Regional Transportation District | B20: Denver | C20: CO | D20: 8006 | E20: 80006 | F20: Independent Public Agency or Authority of Transit Service | G20: 2374203 | H20: 1431 | I20: CR | J20: DO | K20: 8 | M20: 0 | O20: 0 | Q20: 0 | S20: 0 | U20: 0 | W20: 0 | Y20: 688983 | AA20: 0 | AD20: 0 | AF20: 0 | AH20: 0 | AJ20: 0 | AL20: 0 | AN20: 0 | AP20: 0 | BC20: 0 | BG20: No
A21: Denver Regional Transportation District | B21: Denver | C21: CO | D21: 8006 | E21: 80006 | F21: Independent Public Agency or Authority of Transit Service | G21: 2374203 | H21: 1431 | I21: CR | J21: PT | K21: 44 | M21: 0 | O21: 0 | Q21: 0 | S21: 0 | U21: 0 | W21: 0 | Y21: 40149051 | AA21: 0 | AD21: 0 | AF21: 0 | AH21: 0 | AJ21: 0 | AL21: 0 | AN21: 6311542 | AP21: 0 | BC21: 0.1572 | BG21: No
A22: Denver Regional Transportation District | B22: Denver | C22: CO | D22: 8006 | E22: 80006 | F22: Independent Public Agency or Authority of Transit Service | G22: 2374203 | H22: 1431 | I22: LR | J22: DO | K22: 156 | M22: 0 | O22: 0 | Q22: 0 | S22: 0 | U22: 0 | W22: 0 | Y22: 60630772 | AA22: 0 | AD22: 0 | AF22: 0 | AH22: 0 | AJ22: 0 | AL22: 0 | AN22: 9327859 | AP22: 0 | BC22: 0.1538 | BG22: No
A23: Metro-North Commuter Railroad Company, dba: MTA Metro-North Railroad | B23: New York | C23: NY | D23: 2078 | E23: 20078 | F23: Subsidiary Unit of a Transit Agency, Reporting Separately | G23: 18351295 | H23: 1133 | I23: CR | J23: DO | K23: 1122 | M23: 5697351 | O23: 0 | Q23: 0 | S23: 0 | U23: 0 | W23: 0 | Y23: 367362724 | AA23: 0 | AD23: 0 | AF23: 0 | AH23: 0 | AJ23: 0 | AL23: 2002432 | AN23: 40070882 | AP23: 0 | AS23: 0 | BC23: 0.1091 | BG23: No
A24: Dallas Area Rapid Transit | B24: Dallas | C24: TX | D24: 6056 | E24: 60056 | F24: Independent Public Agency or Authority of Transit Service | G24: 5121892 | H24: 1082 | I24: CR | J24: PT | K24: 23 | M24: 1375987 | O24: 0 | Q24: 0 | S24: 0 | U24: 0 | W24: 0 | Y24: 0 | AA24: 0 | AD24: 460806 | AF24: 0 | AH24: 0 | AJ24: 0 | AL24: 0 | AN24: 0 | AP24: 0 | AS24: 0.3349 | BG24: No
