Workbook

Sheet About
A1: Web App Data | B1: New Jersey | C1: 45747 | G1: abrv | H1: state
B2: =_xlfn.XLOOKUP(B1,H:H,G:G,0,0,1) -> NJ | C2: =_xlfn.XLOOKUP(B2,G:G, H:H, 0,0,1) -> New Jersey | G2: AK | H2: Alaska
A3: This spreadsheet contains data that is used to populate the web application interface | G3: AL | H3: Alabama
A4: for the Energy Policy Simulator. The data in other tabs in this spreadsheet are used | G4: AR | H4: Arkansas
A5: to establish the policy levers, lever bounds, descriptive text for pop-over | G5: AZ | H5: Arizona
A6: panels, output graphs, and reference scenarios available in the web app. | G6: CA | H6: California
G7: CO | H7: Colorado
A8: A live version of the web application interface powered by a copy of this model | G8: CT | H8: Connecticut
A9: can be found at: | G9: DC | H9: DC
A10: https://www.energypolicy.solutions | G10: DE | H10: Delaware
G11: FL | H11: Florida
A12: You are unlikely to need to use or change the contents of this spreadsheet, unless | G12: GA | H12: Georgia
A13: you are adapting the Energy Policy Simulator to a new country and desire | G13: HI | H13: Hawaii
A14: a web application interface customized for your country-specific model version. | G14: IA | H14: Iowa
G15: ID | H15: Idaho
A16: Checks for Policy ID Number Validity | G16: IL | H16: Illinois
A17: Max policy ID number in use | B17: =MAX(PolicyLevers!H:H) -> 2769 | G17: IN | H17: Indiana
A18: Lowest duplicate ID number | B18: {=IF(MIN(IF(COUNTIF(PolicyLevers!$H$2:$H$2025,PolicyLevers!$H$2:$H$2025)>1,PolicyLevers!$H$2:$H$2025, ""))=0,"No duplicate ID numbers",MIN(IF(COUNTIF(PolicyLevers!$H$2:$H$2025,PolicyLevers!$H$2:$H$2025)>1,PolicyLevers!$H$2:$H$2025, "")))} -> No duplicate ID numbers | G18: KS | H18: Kansas
A19: Row of first policy missing a valid ID number | B19: {=IF(MIN(IF((NOT(ISNUMBER(PolicyLevers!$H$2:$H$2025)))*(ISTEXT(PolicyLevers!$I$2:$I$2025)),ROW(PolicyLevers!$H$2:$H$2025)))=0,"No missing ID numbers",MIN(IF((NOT(ISNUMBER(PolicyLevers!$H$2:$H$2025)))*(ISTEXT(PolicyLevers!$I$2:$I$2025)),ROW(PolicyLevers!$H$2:$H$2025))))} -> No missing ID numbers | G19: KY | H19: Kentucky
G20: LA | H20: Louisiana
A21: Customizing Policy Levers | G21: MA | H21: Massachusetts
A22: Define most policy properties on the "Policy Characteristics" tab. | G22: MD | H22: Maryland
A23: Specify the subscripted elements of each policy and which are enabled/disabled on the "PolicyLevers" tab. | G23: ME | H23: Maine
A24: On the PolicyLevers tab, only manually edit the cells under the green column headers. Simply extend the | G24: MI | H24: Michigan
A25: existing formulas up or down to fill cells under the red headers on that tab. | G25: MN | H25: Minnesota
G26: MO | H26: Missouri
A27: Notes on Meaning of Blank Cells on the Policy Characteristics Tab | G27: MS | H27: Mississippi
A28: Leave the "Policy Schedule Subscript" cell blank to deny the ability to edit the implementation | G28: MT | H28: Montana
A29: schedule for a lever. This should generally only be done for levers that do not use an | G29: NC | H29: North Carolina
A30: implementation schedule: the toggle to Non-BAU Mandated Capacity Construction | G30: ND | H30: North Dakota
A31: (which has its own schedule built into its input data) and the Nuclear Lifetime Extension | G31: NE | H31: Nebraska
A32: (which simply delays retirements that would occur in the BAU Retirements input data). | G32: NH | H32: New Hampshire
G33: NJ | H33: New Jersey
A34: Leave the "Policy Group" cell blank to exclude a lever from wedge diagrams and abatement cost curves. | G34: NM | H34: New Mexico
A35: This should always be done for "Control Settings" (which affect both the BAU and policy cases), | G35: NV | H35: Nevada
A36: and should generally never be done for actual policy levers. | G36: NY | H36: New York
G37: OH | H37: Ohio
A38: Leave the "URL for "How the model handles this policy" links" cell blank to exclude this link from | G38: OK | H38: Oklahoma
A39: the policy's pop-over pane. You should generally do this whenever there is no on-topic place | G39: OR | H39: Oregon
A40: in the documentation to which to send a user. | G40: PA | H40: Pennsylvania
...

Sheet Policy Characteristics
A1: This tab contains information about each policy that does not vary by subscripted element of that policy.
A2: It matches policies to the listing in the "PolicyLevers" tab using the "Vensim Variable Name" column.
A3: Sector | B3: Short Name | C3: Vensim Variable Name | D3: Policy Group | E3: Policy Schedule Subscript | F3: Min Slider Value | G3: Max Slider Value | H3: Slider Step Size | I3: Units | J3: Text for Pop-Over Panel Description | K3: URL for "How the model handles this policy" links | L3: URL for "How to design this policy well" links | M3: Source for Guidance Text (if any) | N3: Source for Max Slider Value (if any)
A4: Transportation | B4: Conventional Pollutant Standards | C4: Percentage Reduction of Separately Regulated Pollutants | D4: Conventional Pollutant Standard | E4: trans reduce regulated pollutants | F4: 0 | G4: 1 | H4: 0.02 | I4: % reduction in emissions | J4: **Description:** This policy represents strengthening standards for the selected pollutant(s) emitted by the selected vehicle type(s). Conventional pollutants' most important, harmful impacts are on human health rather than on climate change. The following descriptions detail the different vehicle types: // **Passenger cars and SUVs:** most light-duty road vehicles // **Light and Medium Commercial Trucks:** commercial trucks carrying freight, not passengers // **Buses:** including school, transit, and intercity buses // **Heavy Duty Trucks:** all other heavy road vehicles (mostly freight trucks) // **Commercial passenger flights:** this is not general aviation // **Commercial freight flights:** this includes all other commercial flights, and is not general aviation // **Passenger rail:** intercity, transit, and commuter rail // **Freight rail:** all other rail // **Recreational boats:** not commercial passenger ferries // **Cargo ships:** commercial ships carrying freight // **Passenger motorbikes:** registered motorcycles // **Guidance for setting values:** In the United States, since 1997, the 24-hour national ambient air quality standard (NAAQS) for PM2.5, the most harmful type of particulate for human health, declined from 65 µg/m^3 to 35 µg/m^3, a reduction of 46%. | K4: transportation-sector-main.html#conv-pol-stds | L4: conventional-pollutant-standards.html
A5: Transportation | B5: Electric Vehicle Charger Deployment | C5: Percentage Increase in EV Chargers | D5: EV Charger Deployment | E5: trans EV charger deployment | F5: -2 | G5: 3 | H5: 0.1 | I5: % change | J5: **Description:** This policy increases the deployment of EV charging stations, including DC Fast and Level 2 charging stations. A negative value decreases chargers relative to the Current Policies scenario. // **Guidance for setting values:** This policy increases vehicle deployment by lowering the perceived charging availability penalty for EVs, insofar as it increases the ratio of EV chargers to gasoline pumps. In the United States, we find the charging availability penalty already reaches zero by roughly 2030. Beyond that point, this policy lever will have no additional effect on EV deployment. | L5: ev-charger-deployment.html | M5: Number of EV chargers: https://evadoption.com/ev-charging-stations-statistics/ Number of gas stations: U.S. Census, Statistics of U.S. Businesses, https://www.census.gov/data/tables/2016/econ/susb/2016-susb-annual.html Pumps per station: https://247wallst.com/economy/2014/05/22/why-are-there-115000-or-150000-gas-stations-in-america/
A6: Transportation | B6: Electric Vehicle Range | C6: Reduce EV Range Anxiety | D6: EV Range & Charging Time | E6: trans reduce EV range anxiety | F6: 0 | G6: 1 | H6: 0.02 | I6: % reduction in concern | J6: **Description:** This policy specifies a percentage reduction in vehicle buyers' aversion to electric vehicles due to concerns over the vehicles' range (how far the EV can travel on a charge). A 100% setting implies consumers are no more concerned about EV range and charging time than they are about range and fueling time of gasoline vehicles. It does not imply that range is infinite. This policy only affects passenger cars and SUVs (most light-duty road vehicles). // **Guidance for setting values:** U.S. model year 2017 all-electric (not hybrid) vehicles had ranges from 58 to 335 miles (median 114 miles). | L6: reduce-range-anxiety-charging-time.html | M6: Ranges: https://www.energy.gov/eere/vehicles/articles/fotw-1010-january-1-2018-all-electric-light-vehicle-ranges-can-exceed-those Charging Times: https://www.chargepoint.com/files/Quick_Guide_to_Fast_Charging.pdf
A7: Transportation | B7: Passenger Vehicle Subsidy | C7: Additional Passenger Vehicle Subsidy | D7: Vehicle Subsidy | E7: trans psgr subsidy | F7: -45000 | G7: 50000 | H7: 100 | I7: $ / vehicle | J7: =_xlfn.XLOOKUP($C7,'State Policy Descriptions'!$C:$C,'State Policy Descriptions'!$L:$L,0,1,1) -> **Description:** This policy specifies the dollar amount offered as a subsidy to the purchaser of a new passenger vehicle. This is in addition to subsidies that exist in the BAU case. A negative value implies a tax or removal of subsidies. // **Guidance for setting values:** The U.S. currently offers a federal tax credit for up to $7,500 for qualifying clean passenger light-duty vehicles as part of the Inflation Reduction Act. This tax credit is included in the BAU scenario as an estimated average credit for new vehicles, accounting for the fact many vehicles will not be eligible starting in 2025 due to requirements for critical minerals sourcing. The BAU also includes the state-level credit on top of the federal tax credits. As of late 2020, there is an additional state subsidy of $5000. | K7: transportation-sector-main.html#ev-subsidy | L7: ev-subsidy.html | M7: https://www.fueleconomy.gov/feg/taxevb.shtml plus Chevrolet and Tesla websites
A8: Transportation | B8: Freight Vehicle Subsidy | C8: Additional Freight Vehicle Subsidy | D8: Vehicle Subsidy | E8: trans frgt subsidy | F8: -45000 | G8: 50000 | H8: 100 | I8: $ / vehicle | J8: =_xlfn.XLOOKUP($C8,'State Policy Descriptions'!$C:$C,'State Policy Descriptions'!$L:$L,0,1,1) -> **Description:** This policy specifies the dollar amount offered as a subsidy to the purchaser of a new freight vehicle. This is in addition to subsidies that exist in the BAU case. A negative value implies a tax or removal of subsidies. // **Guidance for setting values:** The U.S. currently offers a federal tax credit for up to $40,500 for qualifying clean commercial vehicles, which is incorporated in the BAU. This state has no additional state subsidies. | K8: transportation-sector-main.html#ev-subsidy | L8: ev-subsidy.html
A9: Transportation | B9: Feebate | C9: LDVs Feebate Rate | D9: Feebate | E9: trans LDVs feebate | F9: 0 | G9: 1 | H9: 0.02 | I9: % of global best practice rate | J9: **Description:** This policy implements a fee on sales of inefficient cars and SUVs (light-duty road vehicles; LDVs) that is rebated to buyers of efficient LDVs. The feebate policy is revenue-neutral, as the pivot point (the efficiency level that incurs neither a rebate nor a fee) is set such that the total of all fees equals the total of all rebates. // **Guidance for setting values:** The feebate is set as a fraction of the global best practice feebate rate. The global best practice feebate rate is $2000 per (hundredth gal/mile), which equates to a $2000 fee on an LDV that gets 20 mpg if the pivot point is 25 mpg. (To see this: 20 mpg is 0.04 gpm. 25 mpg is 0.05 gpm. The difference is -.01 gpm. So in order to levy a $2000 fee on the 20 mpg car when the pivot point is 25 mpg, we need a rate of $2000/.01 gpm.) | K9: transportation-sector-main.html#feebate | L9: feebate.html | M9: Greene et al., 2005, "Feebates, rebates and gas-guzzler taxes: a study of incentives for increased fuel economy", Energy Policy, 33(6), 757-775, http://cta.ornl.gov/cta/Publications/Reports/FeebateEnergyPolicy_FINAL.pdf. | N9: John German and Dan Meszler, 2010, "Best Practices for Feebate Program Design and Implementation", ICCT, http://www.theicct.org/sites/default/files/publications/ICCT_feebates_may2010.pdf, Table 2
A10: Transportation | B10: Fuel Economy Standard | C10: Percentage Additional Improvement of Fuel Economy Std | D10: Vehicle Fuel Economy Standards | E10: trans fuel economy standards | F10: -0.25 | G10: =ROUND(MaxBoundCalculations!B88,1) -> 1 | H10: 0.01 | I10: % change in miles/gal | J10: **Description:** This policy specifies a percentage improvement in fuel economy (distance traveled on the same quantity of fuel with the same cargo or passenger loading) due to fuel economy standards for newly sold vehicles of the selected type(s) with fossil fuel-burning engines. A negative value implies a rollback of fuel economy standards relative to those in the BAU scenario. The following descriptions detail the different vehicle types: // **Passenger cars and SUVs:** most light-duty road vehicles // **Light and Medium Commercial Trucks:** commercial trucks carrying freight, not passengers // **Buses:** including school, transit, and intercity buses // **Heavy Duty Trucks:** all other heavy road vehicles (mostly freight trucks) // **Commercial passenger flights:** this is not general aviation // **Commercial freight flights:** this includes all other commercial flights, and is not general aviation // **Passenger rail:** intercity, transit, and commuter rail // **Freight rail:** all other rail // **Recreational boats:** not commercial passenger ferries // **Cargo ships:** commercial ships carrying freight // **Passenger motorbikes:** registered motorcycles // **Guidance for setting values:** // **Passenger cars and SUVs:** U.S. combined fuel economy standards for cars and light trucks were 34.6 mpg in 2020 and are scheduled to rise to 38.3 mpg through 2026, then remain constant. This improvement is reflected in the BAU case. The National Research Council's estimated future average fuel economy is roughly 74 mpg for a midrange scenario and 94 mpg for an optimistic scenario. // **Light and Medium Commercial Trucks:** U.S. fuel economy standards for heavy-duty vehicles vary by vehicle characteristics, but proposed standards for vocational vehicles (the category that includes buses) would reduce GHG emissions by 24% for 2027 model year vehicles relative to the 2018 model year, then remain constant. Extrapolating this trend to 2050 would be an 85% improvement relative to 2018, compared to a 40% improvement relative to 2018 in the BAU case. This could be represented by a policy lever setting of 45%. // **Heavy Duty Trucks:** U.S. fuel economy standards for heavy-duty vehicles vary by vehicle characteristics, but proposed standards for combination tractor-trailers (which are responsible for roughly 60% of HDV emissions) would reduce GHG emissions by 25% for 2027 model year trucks relative to the 2018 model year, then remain constant. Extrapolating this trend to 2050 would be an 96% improvement relative to 2018, compared to a 40% improvement relative to 2018 in the BAU case. This could be represented by a policy lever setting of 56%. // **Commercial passenger flights:** The U.S. currently does not have fuel economy standards for aircraft. In the absence of standards, new passenger aircraft fuel economy is projected to improve roughly 17% from 2018-2050 in the BAU case. // **Commercial freight flights:** The U.S. currently does not have fuel economy standards for aircraft. In the absence of standards, new freight aircraft fuel economy is projected to improve roughly 50% from 2018-2050 in the BAU case. // **Passenger rail:** The U.S. currently does not have fuel economy standards for trains. In the absence of standards, new passenger train fuel economy is not projected to change significantly from 2018-2050 in the BAU case. // **Freight rail:** The U.S. currently does not have fuel economy standards for trains. In the absence of standards, new freight train fuel economy is projected to improve roughly 23% from 2018-2050 in the BAU case. // **Recreational boats:** The U.S. currently does not have fuel economy standards for recreational boats. In the absence of standards, new passenger boat fuel economy is not projected to change significantly from 2018-2050 in the BAU case. // **Cargo ships:** The U.S. currently does not have fuel economy standards for ships. In the absence of standards, new freight ship fuel economy is projected to improve roughly 21% from 2018-2050 in the BAU case. however, the ICCT suggests in-use CO2 intensity of freight ships could fall by roughly 50% by 2040, corresponding to a 100% improvement in fuel economy. // **Passenger motorbikes:** The U.S. currently does not have fuel economy standards for motorbikes. In the absence of standards, new motorbike fuel economy is not projected to change significantly from 2018-2050 in the BAU case. | K10: transportation-sector-main.html#fuel-econ-std | L10: fuel-economy-standard.html | M10: U. S. EPA, 2012, "Fact Sheet: EPA and NHTSA Set Standards to Reduce Greenhouse Gases and Improve Fuel Economy for Model Years 2017-2025 Cars and Light Trucks", https://nepis.epa.gov/Exe/ZyNET.exe/P100EZ7C.txt?ZyActionD=ZyDocument&Client=EPA&Index=2011%20Thru%202015&Docs=&Query=&Time=&EndTime=&SearchMethod=1&TocRestrict=n&Toc=&TocEntry=&QField=&QFieldYear=&QFieldMonth=&QFieldDay=&UseQField=&IntQFieldOp=0&ExtQFieldOp=0&XmlQuery=&File=D%3A%5CZYFILES%5CINDEX%20DATA%5C11THRU15%5CTXT%5C00000005%5CP100EZ7C.txt&User=ANONYMOUS&Password=anonymous&SortMethod=h%7C-&MaximumDocuments=1&FuzzyDegree=0&ImageQuality=r75g8/r75g8/x150y150g16/i425&Display=hpfr&DefSeekPage=x&SearchBack=ZyActionL&Back=ZyActionS&BackDesc=Results%20page&MaximumPages=1&ZyEntry=4, Table 1, Row 4. U.S. EPA, 2015, "EPA and NHTSA Propose Standards to Reduce Greenhouse Gas Emissions and Improve Fuel Efficiency of Medium- and Heavy-Duty Vehicles for Model Year 2018 and Beyond", https://nepis.epa.gov/Exe/ZyNET.exe/P100P7NL.txt?ZyActionD=ZyDocument&Client=EPA&Index=2016%20Thru%202020&Docs=&Query=&Time=&EndTime=&SearchMethod=1&TocRestrict=n&Toc=&TocEntry=&QField=&QFieldYear=&QFieldMonth=&QFieldDay=&UseQField=&IntQFieldOp=0&ExtQFieldOp=0&XmlQuery=&File=D%3A%5CZYFILES%5CINDEX%20DATA%5C16THRU20%5CTXT%5C00000002%5CP100P7NL.txt&User=ANONYMOUS&Password=anonymous&SortMethod=h%7C-&MaximumDocuments=1&FuzzyDegree=0&ImageQuality=r75g8/r75g8/x150y150g16/i425&Display=hpfr&DefSeekPage=x&SearchBack=ZyActionL&Back=ZyActionS&BackDesc=Results%20page&MaximumPages=1&ZyEntry=3, Page 3. https://theicct.org/sites/default/files/publications/ICCT_ShipEfficiency_20130723.pdf Others calculated from model input data. | N10: National Research Council, 2013, "Transitions to Alternative Vehicles and Fuels", https://www.nap.edu/catalog/18264/transitions-to-alternative-vehicles-and-fuels, Table 2.9, Fuel economy test mpg. U.S. DoE, 2013, "Potential for Energy Efficiency Improvement Beyond the Light-Duty-Vehicle Sector," http://www.nrel.gov/docs/fy13osti/55637.pdf, Table 2.2 and Section 3.4.5, Paragraph 1 David McCollum, Gregory Gould, and Davide Greene, 2009, "Greenhouse Gas Emissions from Aviation and Marine Transportation: Mitigation Potential and Policies", Pew Center on Global Climate Change, http://www.c2es.org/docUploads/aviation-and-marine-report-2009.pdf, Table 4 https://theicct.org/sites/default/files/publications/ICCT_ShipEfficiency_20130723.pdf
A11: Transportation | B11: Low Carbon Fuel Standard | C11: Additional LCFS Percentage | D11: Low Carbon Fuel Standard | E11: trans LCFS | F11: 0 | G11: 1 | H11: 0.01 | I11: % reduction in carbon emissions | J11: **Description:** This policy specifies the percentage reduction in carbon emissions from the transportation sector that must be achieved via fuel switching. By default, this policy applies to all non-aviation vehicle types. If the lever Non-BAU LCFS-Qualifying Vehicles is enabled, this policy only applies to aviation and represents the use of sustainable aviation fuels. The value set in this lever is in addition to BAU requirements. // **Guidance for setting values:** The U.S. National Renewable Fuel Standard equates to a BAU LCFS of 2.2% - 4.6% (varying by year). California adopted an LCFS that required a 10% reduction in carbon intensity of the transportation fuel pool by 2020. | K11: transportation-sector-main.html#lcfs | L11: low-carbon-fuel-standard.html | M11: https://www.arb.ca.gov/fuels/lcfs/background/basics.htm
A12: Transportation | B12: Non-BAU LCFS-Qualifying Vehicles | C12: Boolean Use Non BAU LCFS Vehicle Types | D12: Low Carbon Fuel Standard | E12: trans LCFS vehicles | F12: 0 | G12: 1 | H12: 1 | I12: on/off | J12: **Description:** This lever changes which vehicles qualify under the low carbon fuel standard. With the lever off, LCFS-qualifying vehicles include all vehicle types except aircraft. With the lever on, only aircraft qualify. | K12: transportation-sector-main.html#lcfs | L12: low-carbon-fuel-standard.html | M12: https://www.arb.ca.gov/fuels/lcfs/background/basics.htm
A13: Transportation | B13: Mode Shifting | C13: Percent of Travel Demand Shifted to Other Modes or Eliminated | D13: Mode Shifting | E13: trans mode shifting | F13: 0 | G13: =-ROUND(MaxBoundCalculations!$B$206,2) -> 0.33 | H13: 0.01 | I13: % of trips shifted | J13: **Description:** This policy represents a set of measures to reduce demand for passenger or freight transportation in the selected vehicle type(s). **Passenger car and SUV** trips may be shifted to other travel modes, such as buses, rail, walking, biking, or eliminated through technology such as videoconferencing. Example measures include improved public transit systems, more walking and bike paths, zoning for higher density along transit corridors, zoning for mixed-use developments, roadway and congestion pricing, and increased parking fees. **Commercial passenger and freight flight** trips may be shifted to inter-city rail or eliminated using technology such as videoconferencing. **Heavy Heavy Duty Truck** trips can be reduced through improved logistics that avoids backhauls and transporting empty shipping containers. The following descriptions detail the different vehicle types: // **Passenger cars and SUVs:** most light-duty road vehicles // **Heavy Duty Trucks:** all other heavy road vehicles (mostly freight trucks) // **Commercial passenger flights:** this is not general aviation // **Guidance for setting values:** // **Passenger cars and SUVs:** The International Energy Agency's BLUE Shifts scenario (from the 2009 report "Transport, Energy, and CO2: Moving Toward Sustainability") includes a 26% reduction in usage of cars and SUVs in OECD countries by 2050 relative to a BAU case. // **Commercial passenger flights:** The International Energy Agency's BLUE Shifts scenario (from the 2009 report "Transport, Energy, and CO2: Moving Toward Sustainability") includes a 30% reduction in usage of aircraft in OECD countries by 2050 relative to a BAU case. // **Heavy Duty Trucks:** The U.S. Federal Highway Administration reports that approximately 25% of mileage for trucks larger than pickups/minivans/other light vans are for empty backhauls and empty shipping containers. | K13: transportation-sector-main.html#tdm | L13: transportation-demand-management.html | M13: International Energy Agency, 2009, "Transport, Energy and CO2: Moving toward Sustainability", http://www.iea.org/publications/freepublications/publication/transport2009.pdf "Freight Facts and Figures", 2013, https://ops.fhwa.dot.gov/freight/freight_analysis/nat_freight_stats/docs/13factsfigures/pdfs/fff2013_highres.pdf
A14: Transportation | B14: Zero-Emission Vehicle Sales Standard | C14: Additional Minimum Required ZEV Sales Percentage for Model Region | D14: ZEV Sales Standard | E14: trans ZEV minimum | F14: -1 | G14: 1 | H14: 0.01 | I14: % of new vehicles sold | J14: =_xlfn.XLOOKUP($C14,'State Policy Descriptions'!$C:$C,'State Policy Descriptions'!$L:$L,0,1,1) -> **Description:** This policy requires the specified percentage of newly sold vehicles of the selected type(s) to consist of zero-emission vehicles. If that percentage would already be achieved through BAU sales plus the effects of other policies, such as an EV subsidy, this policy has no effect. Manufactures may meet a sales standard through techniques such as more heavily marketing electric vehicles, lowering the price of electric vehicles, or raising the price of non-electric vehicles. A negative setting for this lever implies a decrease in ZEV sales requirements relative to the BAU scenario. The following descriptions detail the different vehicle types: // **Passenger cars and SUVs:** most light-duty road vehicles //**Light and Medium Commercial Trucks:** commercial trucks carrying freight, not passengers // **Buses:** including school, transit, and intercity buses // **Heavy Duty Trucks:** all other heavy road vehicles (mostly freight trucks) // **Passenger motorbikes:** registered motorcycles // **Guidance for setting values:**//**Passenger cars and SUVs: ** Under the Clean Air Act, California was awarded a waiver enabling the state to set vehicle emissions standards that are more stringent than federal standards. The waiver has resulted in the Advanced Clean Cars (ACC) and Advanced Clean Cars II (ACC II) regulations. Other states can also choose to adopt the regulations. ACC requires requires automakers to sell ~7-10% EV sales by 2025. ACC II stipulates a 35 percent sales requirement in 2026, ramping up to a 100 percent sales target in 2035. The state has adopted ACC and partially adopted ACC II. // **Light and Medium Commercial and Heavy Duty Trucks:** Today, the share of electric freight trucks is very low, but electrification is particularly promising for certain types of trucks, such as those used to make deliveries within cities, those involved in port operations, garbage trucks, and others with frequent starts and stops. // **Buses:** Electric bus manufacturer Proterra believes all new transit bus sales could be electric as early as 2030, but transit buses make up roughly 15% of the bus fleet. // **Passenger motorbikes:** Though electric motorcycles and scooters are popular in Europe and Asia, where motorbikes are commonly used for urban transportation and commuting, electric motorbikes are not yet a significant presence in the U.S., where motorbikes are mostly used for recreation. | K14: transportation-sector-main.html#ev-mandate | L14: ev-mandate.html | M14: https://autoalliance.org/energy-environment/state-electric-vehicle-mandate/ https://www.cnbc.com/2019/08/26/colorado-joins-california-in-requiring-automakers-to-sell-more-evs.html https://www.consumerreports.org/hybrids-evs/california-says-new-cars-sold-in-the-state-must-be-zero-emissions-by-2035/ https://www.greentechmedia.com/articles/read/electric-buses-are-going-to-dominate statistics from FoVObE variable https://www.prnewswire.com/news-releases/electric-boats-and-ships-2017-2027-300561222.html
A15: Transportation | B15: Non-BAU ZEV-Qualifying Vehicles | C15: Boolean Use Non BAU ZEV Qualifying Vehicle Definitions | D15: ZEV Sales Standard | E15: trans non BAU ZEV vehicle definitions | F15: 0 | G15: 1 | H15: 1 | I15: on/off | J15: **Description:** This lever changes which vehicles qualify under the ZEV standard. With the lever off, ZEV-qualifying vehicles include battery electric vehicles, plugin hybrid vehicles, and hydrogen-fueled vehicles. With the lever on, only battery electric vehicles and hydrogen-fueled vehicles qualify.
A16: Transportation | B16: Subsidy for Vehicle Battery Production | C16: Additional Subsidy for Vehicle Battery Production | D16: Vehicle Battery Production Subsidy | E16: trans battery subsidy | F16: -50 | G16: 50 | H16: 1 | I16: $/kWh | J16: **Description:** This policy specifies the dollar per kilowatt-hour subsidy for production of vehicle batteries. This is in addition to subsidies that exist in the BAU scenario. The subsidy will only be applied to the fraction of vehicle batteries produced domestically. A negative value implies a tax or removal of subsidies. // **Guidance for setting values:** The Inflation Reduction Act includes a $35/kWh tax credit for battery cells and a $10/kWh tax credit for assembly for onroad vehicles, which are included in the BAU.
A17: Transportation | B17: Non-BAU Zero-Emission Vehicle Sales Standard by Subregion | C17: Boolean Use Non BAU Minimum Required ZEV Sales Percentage by Subregion | D17: ZEV Sales Standard | E17: trans non BAU ZEV minimum | F17: 0 | G17: 1 | H17: 1 | I17: on/off | J17: **Description:** Turning this policy lever on will edit the BAU assumptions for state-level minimum ZEV requirements. This is done by using different input data files for the model. In the United States model and in the various U.S. state models, turning this policy lever on reverses state-level Advanced Clean Cars and Advanced Clean Trucks requirements starting in 2025. This only has an effect if the state has adopted ACC or ACT.
A18: Buildings and Appliances | B18: Building Component Electrification | C18: Fraction of New Bldg Components Shifted to Other Fuels | D18: Building Component Electrification | E18: bldgs new component fuel shifting | F18: 0 | G18: 1 | H18: 0.01 | I18: % of newly sold non-electric building components | J18: =_xlfn.XLOOKUP($C18,'State Policy Descriptions'!$C:$C,'State Policy Descriptions'!$L:$L,0,1,1) -> **Description:** This policy replaces the specified fraction of newly sold non-electric building components of the selected type(s) in buildings of the selected type(s) with electricity-using components. // **Guidance for setting values:** //**Urban Residential Heating:** In the BAU case, in New Jersey, the share of electricity among fuels used for heating in urban, residential buildings will rise from 7% to 11% through 2050.//**Urban Residential Appliances:** In the BAU case, in New Jersey, the share of electricity among fuels used for appliances in urban, residential buildings will fall from 31% to 30% through 2050.//**Urban Residential Other Components:** In the United States, the share of electricity among fuels used by other components in urban, residential buildings is 100%.//**Rural Residential Heating:** In the BAU case, in New Jersey, the share of electricity among fuels used for heating in rural, residential buildings will rise from 7% to 11% through 2050.//**Rural Residential Appliances:** In the BAU case, in New Jersey, the share of electricity among fuels used for appliances in rural, residential buildings will fall from 30% to 30% through 2050.//**Rural Residential Other Components:** In the United States, the share of electricity among fuels used by other components in rural, residential buildings is 100%.//**Commercial Heating:** In the BAU case, in New Jersey, the share of electricity among fuels used for heating in commercial buildings will fall from 3% to 3% through 2050.//**Comercial Appliances:** In the BAU case, in New Jersey, the share of electricity among fuels used for appliances in commercial buildings will fall from 30% to 28% through 2050.//**Comercial Other Components:** In the BAU case, in New Jersey, the share of electricity among fuels used for other components in commercial buildings will rise from 66% to 76% through 2050. | K18: buildings-sector-main.html#component-elec | L18: building-component-electrification.html | M18: EIA AEO
A19: Buildings and Appliances | B19: Building Energy Efficiency Standards | C19: Reduction in E Use Allowed by Component Eff Std | D19: Building Energy Efficiency Standards | E19: bldgs efficiency standards | F19: 0 | G19: 0.75 | H19: 0.01 | I19: % reduction in energy use | J19: =_xlfn.XLOOKUP($C19,'State Policy Descriptions'!$C:$C,'State Policy Descriptions'!$L:$L,0,1,1) -> **Description:** This policy tightens energy efficiency standards for the selected component(s) in the selected building type(s). The policy only applies to newly sold components each year (whether for new buildings or replacement of old components of existing buildings). // **Guidance for setting values:** In "Assessment of Electricity Savings in the U.S. Achievable through New Appliance/Equipment Efficiency Standards and Building Efficiency Codes, 2010-2025" (2011), the Edison Foundation considered a 30% reduction in whole-building energy use (moderate case) and 40-45% (aggressive case) relative to BAU from 2010 to 2025. | K19: buildings-sector-main.html#eff-stds | L19: building-energy-efficiency-standards.html | M19: Edison Foundation, 2011, "Assessment of Electricity Savings in the U.S. Achievable through New Appliance/Equipment Efficiency Standards and Building Efficiency Codes (2010 - 2025)", http://www.edisonfoundation.net/iei/Documents/IEE_CodesandStandardsAssessment_2010-2025_UPDATE.pdf, Page B-2, Table B-1. | N19: Itron, 2007, "ASSESSMENT OF LONG-TERM ELECTRIC ENERGY EFFICIENCY POTENTIAL IN CALIFORNIA’S RESIDENTIAL SECTOR," http://www.energy.ca.gov/2007publications/CEC-500-2007-002/CEC-500-2007-002.PDF, p.33, Table 5-1
A20: Buildings and Appliances | B20: Contractor Training | C20: Boolean Improved Contractor Edu and Training | D20: Contractor Training | E20: bldgs contractor training | F20: 0 | G20: 1 | H20: 1 | I20: on/off | J20: **Description:** This policy represents a program to train contractors in energy-efficient products and installation practices. This covers activities such as air sealing, building framing, and choice and application of insulation. This policy affects newly sold building envelope components, which reduce the energy use of heating, cooling, and ventilation systems in buildings by 3.7% (based on a 2006 study from the Energy Center of Wisconsin). | K20: buildings-sector-main.html#contractor-ed | L20: contractor-training.html
A21: Buildings and Appliances | B21: Distributed Solar Carve-Out | C21: Min Fraction of Total Elec Demand to be Met by Distributed Solar PV | D21: Distributed Solar Promotion | E21: bldgs min fraction distributed solar | F21: 0 | G21: =ROUND(MaxBoundCalculations!B172,2) -> 0.24 | H21: 0.005 | I21: minimum % elec from solar | J21: **Description:** This policy requires at least the specified percentage of total retail electricity demand to be generated by residential and commercial buildings' distributed solar systems (typically rooftop PV). // **Guidance for setting values:** It is typical for state policy to include 0 to 5% carve-outs. For example, Colorado has established a 3% carve-out for 2020 (though it includes non-solar on-site sources). | K21: buildings-sector-main.html#solar-carve-out | L21: solar-carve-out.html | M21: MASSACHUSETTS: http://www.mass.gov/eea/energy-utilities-clean-tech/renewable-energy/solar/rps-solar-carve-out/current-status-of-the-rps-solar-carve-out-program.html COLORADO: http://www.seia.org/research-resources/rps-solar-carve-out-colorado | N21: RMI, 2011, "Reinventing Fire Electricity Sector Methodology," http://www.rmi.org/cms/Download.aspx?id=10765&file=Reinventing+Fire+Electricity+Sector+Methodology.pdf&title=Reinventing+Fire+Electricity+Sector+Methodology, Page 11, 2050 Generation by Case
A22: Buildings and Appliances | B22: Distributed Solar Subsidy | C22: Additional Perc Subsidy for Distributed Solar PV Capacity | D22: Distributed Solar Promotion | E22: bldgs distributed solar subsidy | F22: 0 | G22: 0.5 | H22: 0.01 | I22: % of PV system cost | J22: **Description:** This policy causes the government to reimburse building owners for an additional percentage of the cost of new distributed solar PV capacity that is installed on or around buildings. This is in addition to the subsidy that is included in BAU. // **Guidance for setting values:** The Inflation Reduction Act includes a 30% tax credit for residential solar through 2032, phased down to 0% by 2035. This is incorporated in the BAU scenario. | K22: buildings-sector-main.html#distributed-solar-subsidy | L22: distributed-solar-subsidy.html | M22: Department of Energy. Business Energy Investment Tax Credit (ITC). http://energy.gov/savings/business-energy-investment-tax-credit-itc
A23: Buildings and Appliances | B23: Distributed Solar Capacity Requirement | C23: Min Required Rooftop Solar Capacity | D23: Distributed Solar Promotion | E23: bldgs min req rooftop solar | F23: 0 | G23: 600000 | H23: 5000 | I23: MW | J23: **Description:** This policy requires at least the specified capacity of distributed solar be built by the model. // **Guidance for setting values:** We estimate the maximum rooftop solar potential in the U.S. at 385 GW for commercial buildings, 595 GW for urban residential buildings, and 135 GW for rural residential buildings. We recommend users not set the value above this potential.
A24: Buildings and Appliances | B24: Non BAU Distributed Solar Capacity | C24: Boolean Use Non BAU Distributed Solar Capacity | D24: Distributed Solar Promotion | E24: non BAU dist solar | F24: 0 | G24: 1 | H24: 1 | I24: on/off | J24: **Description:** Turning this policy lever on will edit the BAU assumptions for deployment of distributed solar. This is done by using different input data files for the model. In the United States model and in the various U.S. state models, turning this policy lever on will remove the incremental distributed solar deployments expected from the Inflation Reduction Act. //
A25: Buildings and Appliances | B25: Improved Labeling | C25: Boolean Improved Device Labeling | D25: Improved Labeling | E25: bldgs device labeling | F25: 0 | G25: 1 | H25: 1 | I25: on/off | J25: **Description:** This policy represents a program requiring newly sold heating systems, cooling and ventilation systems, and appliances to feature prominent, well-designed labels highlighting their energy efficiencies. The policy reduces energy consumption of newly sold building components of these types by 10%. | K25: buildings-sector-main.html#device-labeling | L25: improved-labeling.html | M25: none
A26: Buildings and Appliances | B26: Retrofit Existing Buildings | C26: Share of Preexisting Buildings Subject to Retrofitting | D26: Increased Retrofitting | E26: bldgs retrofitting | F26: 0 | G26: 1 | H26: 0.01 | I26: % of existing buildings | J26: **Description:** Each year, the specified percentage of the selected building type(s) that existed at the start of the model run will be retrofit with more efficient heating, cooling, and envelope components. // **Guidance for setting values:** By 2050, roughly 88% of the preexisting residential buildings and 83% of the preexisting commercial buildings will still survive without major renovations, so values of 88% and 83% in 2050 will retrofit all such surviving buildings by that year. Policy settings higher than this will retrofit all eligible buildings sooner than 2050. | K26: buildings-sector-main.html#retrofitting | L26: increased-retrofitting.html | M26: Calculated from model data; see the relevant variable(s) in the InputData folder for source information.
A27: Buildings and Appliances | B27: Rebate for Efficient Products | C27: Boolean Rebate Program for Efficient Components | D27: Rebate for Efficient Products | E27: bldgs rebate | F27: 0 | G27: 1 | H27: 1 | I27: on/off | J27: **Description:** This policy represents a modest rebate paid to customers who purchase energy-efficient building equipment of the selected type(s). Typical rebate amounts represented by this policy are $50-100 for a clothes washer and $25-50 for a dishwasher or refrigerator. | K27: buildings-sector-main.html#rebate | L27: rebate-for-efficient-products.html
A28: Electricity Supply | B28: Ban New Power Plants | C28: Boolean Ban New Power Plants | D28: Ban New Power Plants | E28: elec ban new power plants | F28: 0 | G28: 1 | H28: 1 | I28: on/off | J28: =_xlfn.XLOOKUP($C28,'State Policy Descriptions'!$C:$C,'State Policy Descriptions'!$L:$L,0,1,1) -> **Description:** This policy prevents new capacity of the selected type(s) from being built or deployed. // **Guidance for setting values:** No new coal is planned in New Jersey. | K28: electricity-sector-main.html#ban | L28: ban-new-capacity.html
A29: Electricity Supply | B29: Ban New Power Plant Retrofits | C29: Boolean Ban New Power Plant Retrofits | D29: Ban New Power Plant Retrofits | E29: elec ban new power plant retrofits | F29: 0 | G29: 1 | H29: 1 | I29: on/off | J29: **Description:** This policy prevents new capacity of the selected CCS plant type(s) from being built to replace existing non-CCS plants.
A30: Electricity Supply | B30: Clean Electricity Standard | C30: Renewable Portfolio Std Percentage | D30: Clean Electricity Standard | E30: elec renewable portfolio standards | F30: 0 | G30: 1 | H30: 0.01 | I30: % of electricity generation | J30: =_xlfn.XLOOKUP($C30,'State Policy Descriptions'!$C:$C,'State Policy Descriptions'!$L:$L,0,1,1) -> **Description:** This policy specifies an increase in the fraction of electricity generation that must come from qualifying carbon-free sources (wind, solar, biomass, nuclear, hydro, geothermal, ccs, and hydrogen) in 2050. This policy has no effect until the user-set value exceeds the existing fraction of carbon-free electricity and any carbon-free electricity standards which have been enacted at the state level. To use this policy, turn the associated 'Non BAU RPS Qualifying Resources' policy to ON and the 'Lift the Clean Electricity Standard Alternative Compliance Payment' policy to ON. // **Guidance for setting values:** Multiple states have set 100% clean energy or renewable energy laws or goals, not including New Jersey. When setting a high CES with this lever, users should also turn on supporting power sector policies (i.e., Grid-Scale Electricity Storage, Increase Transmission, and Demand Response) to avoid curtailment of renewables. At very high CES values, the associated policy costs are highly uncertain and should be complemented with other modeling. The business-as-usual CES value assumes the portion of an existing RPS standard met by imports remains constant. | K30: electricity-sector-main.html#ces | L30: clean-energy-standard.html | M30: White House, 2015, "Fact Sheet: President Obama to Announce Historic Carbon Pollution Standards for Power Plants", https://www.whitehouse.gov/the-press-office/2015/08/03/fact-sheet-president-obama-announce-historic-carbon-pollution-standards.
A31: Electricity Supply | B31: Clean Electricity Standard Foresight | C31: BESHFoFRV Boolean Electricity Suppliers Have Foresight of Future RPS Values | F31: 0 | G31: 1 | H31: 1 | I31: on/off | J31: **Description:** This setting indicates whether electricity suppliers have foresight of future-year CES values (both BAU case values and any values set by the user in the CES policy lever). With foresight, electricity suppliers will build some CES-qualifying resources in earlier years than would be strictly necessary to meet the CES requirement in those years if it allows them to approach a higher, future-year CES target more gradually, lessening the need to build power plants abruptly if the CES rises more steeply in the future.
A32: Electricity Supply | B32: Lift the Clean Electricity Standard Alternative Compliance Payment | C32: Boolean Use Non BAU RPS Alternative Compliance Payment | D32: Clean Electricity Standard | E32: elec non BAU RACP | F32: 0 | G32: 1 | H32: 1 | I32: on/off | J32: =_xlfn.XLOOKUP($C32,'State Policy Descriptions'!$C:$C,'State Policy Descriptions'!$L:$L,0,1,1) -> **Description:** The BAU scenario includes a CES alternative compliance payment of roughly 50 $/MWh. If the CES credit price hits this $/MWh amount in a given year, the model will not deploy any additional CES qualifying resources in an attempt to meet the CES. Enabling this policy lifts this cap, meaning there is no price constraint on new resources.
A33: Electricity Supply | B33: Change Electricity Exports | C33: Percent Change in Electricity Exports | D33: Electricity Imports and Exports | E33: elec change exports | F33: -0.5 | G33: 1 | H33: 0.1 | I33: % change in exports | J33: =_xlfn.XLOOKUP($C33,'State Policy Descriptions'!$C:$C,'State Policy Descriptions'!$L:$L,0,1,1) -> **Description:** This policy increases or decreases the amount of electricity exported from the United States to Canada and Mexico. It does not cause the construction or removal of transmission lines linking these countries. // **Guidance for setting values:** Multiple states have set 100% clean energy or renewable energy laws or goals, not including New Jersey. When setting a high CES with this lever, users should also turn on supporting power sector policies (i.e., Grid-Scale Electricity Storage, Increase Transmission, and Demand Response) to avoid curtailment of renewables. At very high CES values, the associated policy costs are highly uncertain and should be complemented with other modeling. The business-as-usual CES value assumes the portion of an existing RPS standard met by imports remains constant. | K33: electricity-sector-main.html#elec-exports | L33: electricity-imports-exports.html | M33: Energy Information Administation. 2016. Electric Power Annual. Table 2.13.
A34: Electricity Supply | B34: Change Electricity Imports | C34: Percent Change in Electricity Imports | D34: Electricity Imports and Exports | E34: elec change imports | F34: -0.5 | G34: 1 | H34: 0.02 | I34: % change in imports | J34: =_xlfn.XLOOKUP($C34,'State Policy Descriptions'!$C:$C,'State Policy Descriptions'!$L:$L,0,1,1) -> **Description:** This policy increases or decreases the amount of electricity imported to the United States from Canada and Mexico. It does not cause the construction or removal of transmission lines linking these countries. // **Guidance for setting values:** From 2008 to 2021, electricity imports grew by -32%. | K34: electricity-sector-main.html#elec-imports | L34: electricity-imports-exports.html | M34: Energy Information Administation. 2016. Electric Power Annual. Table 2.13.
A35: Electricity Supply | B35: Non BAU Guaranteed Dispatch | C35: Boolean Use Non BAU Guaranteed Dispatch Settings | D35: Non BAU Guaranteed Dispatch | E35: elec non BAU guaranteed dispatch | F35: 0 | G35: 1 | H35: 1 | I35: on/off
A36: Electricity Supply | B36: Decrease Cost of Capital | C36: Percentage Decrease in Cost of Capital for Power Plants | D36: Decrease Electricity Sector Cost of Capital | E36: elec power plant cost of capital | F36: 0 | G36: 1 | H36: 1 | I36: % decrease | J36: **Description:** This policy decreases the cost of capital for new power plant investments, making the specified plant type more attractive to deploy. // **Guidance for setting values:** The BAU cost of capital for all plant types is calculated as 7.4%, based on data from Lazard. | M36: https://www.lazard.com/media/451905/lazards-levelized-cost-of-energy-version-150-vf.pdf
A37: Electricity Supply | B37: Demand Response | C37: Fraction of Additional Demand Response Potential Achieved | D37: Demand Response | E37: elec demand response | F37: 0 | G37: 1 | H37: 0.01 | I37: % of potential achieved | J37: =_xlfn.XLOOKUP($C37,'State Policy Descriptions'!$C:$C,'State Policy Descriptions'!$L:$L,0,1,1) -> **Description:** This policy represents regulations that cause more demand response (DR) capacity to be added to the electric grid. Demand response provides flexibility that allows for the integration of more wind and solar PV, if the electricity system is flexibility-constrained. Demand response can be load-shedding (demand is reduced in the worst hours without adding demand in other hours) or load-shifting (demand is reduced in the worst hours and added in other hours). The type of demand response modeled here is load-shedding, which is by far the most common type of demand response that exists today. // **Guidance for setting values:**For New Jersey, a 100% setting provides for an additional 4751 MW of demand response capacity in 2050 (on top of a BAU quantity of 2272 MW). | K37: electricity-sector-main.html#dr | L37: demand-response.html | M37: Calculated from model data; see the relevant variable(s) in the InputData folder for source information.
A38: Electricity Supply | B38: Early Retirement of Power Plants | C38: Annual Additional Capacity Retired due to Early Retirement Policy | D38: Early Retirement of Power Plants | E38: elec early retirement | F38: 0 | G38: 5000 | H38: 50 | I38: MW/year | J38: =_xlfn.XLOOKUP($C38,'State Policy Descriptions'!$C:$C,'State Policy Descriptions'!$L:$L,0,1,1) -> **Description:** This policy causes the specified quantity of otherwise non-retiring capacity of the selected type(s) to be retired each year. // **Guidance for setting values:** // **Hard coal:** The EIA projects that New Jersey will retire 0 MW of coal by 2050. New Jersey currently has 463 MW of coal capacity.//**Natural gas non-peaker:** The EIA projects that NJ will retire 0 MW of natural gas by 2050. NJ currently has 8570 MW of natural gas non-peaker capacity.//**Nuclear:** The EIA projects that NJ will retire 0 MW of nuclear by 2050. NJ currently has 3467 MW of nuclear capacity.//**Natural gas peaker:** The EIA projects that NJ will retire 0 MW of natural gas by 2050. NJ currently has 2770 MW of natural gas peaker capacity.//**Lignite:** The EIA projects that NJ will retire 0 MW of lignite by 2050. NJ currently has 0 MW of lignite capacity. | K38: electricity-sector-main.html#early-ret | L38: early-retirement-of-power-plants.html | M38: Energy Information Administration, 2014, "Annual Energy Outlook 2014", http://www.eia.gov/oiaf/aeo/tablebrowser/#release=AEO2014&subject=6-AEO2014&table=9-AEO2014&region=0-0&cases=hccstom-d012314a,ref2014-d102413a, Table Browser. Select Electric Power Sector, Electricity Generating Capacity (and check Reference and Accelerated coal retirements scenarios). | N38: The Brattle Group, 2012, "Potential Coal Plant Retirements: 2012 Update," http://greatlakeslegalfoundation.org/wwcms/wp-content/uploads/documents/regulatory/TrainWreck/12Oct15_BrattleStudy.pdf, Page 8, Table 4
A39: Electricity Supply | B39: Non BAU Capacity Retirement Schedule | C39: Boolean Use Non BAU Capacity Retirement Schedule | D39: Non BAU Capacity Retirement Schedule | F39: 0 | G39: 1 | H39: 1 | I39: on/off | J39: **Description:** The EPS calculates economc capacity additions and retirements in each time step. In addition, it incorporates any announced retirements through input data files. This policy uses an alternate input data file specifying planned retirement schedules for existing capacity of the selected type(s). // **Guidance for setting values:** The Current Policies scenario includes all expected coal retirements resulting from EPA's Clean Air Act Section 111 regulations for power plants, as well as from other regulations and legislation like the Inflation Reduction Act. Turning this lever on removes the effect of those federal policies, resulting in fewer coal retirements.
A40: Electricity Supply | B40: Non BAU Mandated Capacity Construction | C40: Boolean Use Non BAU Mandated Capacity Construction Schedule | D40: Non BAU Mandated Capacity Construction | F40: 0 | G40: 1 | H40: 1 | I40: on/off | J40: **Description:** The BAU scenario includes all planned capacity additions (provided by the U.S. Energy Information Administration). This policy uses an alternative set of planned capacity additions. // **Guidance for setting values:** // **Offshore Wind:** When used in the context of the US NDC scenario, this policy results in roughly 30 GW of offshore wind by 2030 and 220 of offshore wind by 2050 nationwide.
...

Sheet State Policy Descriptions
A1: Sector | B1: Short Name | C1: Vensim Variable Name | D1: Policy Group | E1: Policy Schedule Subscript | F1: Min Slider Value | G1: Max Slider Value | H1: Slider Step Size | I1: Units | J1: Text for Pop-Over Panel Description (National model) | K1: Text for Pop-Over Panel Description (State concat) | L1: Text for Pop-Over Panel Description | M1: Text for Pop-Over Panel Description (state concat 2) | N1: Text for Pop-Over Panel Description (state concat 3) | O1: Text for Pop-Over Panel Description (state concat 4) | P1: Text for Pop-Over Panel Description (state concat 5) | Q1: Text for Pop-Over Panel Description (state concat 6) | R1: Text for Pop-Over Panel Description (state concat 7) | S1: Text for Pop-Over Panel Description (state concat 8) | T1: Text for Pop-Over Panel Description (state concat 9)
A2: Buildings and Appliances | B2: Building Component Electrification | C2: Fraction of New Bldg Components Shifted to Other Fuels | D2: Building Component Electrification | E2: bldgs new component fuel shifting | F2: 0 | G2: 1 | H2: 0.01 | I2: % of newly sold non-electric building components | J2: **Description:** This policy replaces the specified fraction of newly sold non-electric building components of the selected type(s) in buildings of the selected type(s) with electricity-using components. // **Guidance for setting values:** // | K2: =_xlfn.CONCAT("**Urban Residential Heating:** In the BAU case, in ",About!$C$2,", the share of electricity among fuels used for heating in urban, residential buildings will ",IF('Supporting Data'!$BW$3<'Supporting Data'!$BX$3,"rise","fall")," from ",'Supporting Data'!$BW$3,"% to ",'Supporting Data'!$BX$3,"% through 2050.") -> **Urban Residential Heating:** In the BAU case, in New Jersey, the share of electricity among fuels used for heating in urban, residential buildings will rise from 7% to 11% through 2050. | L2: =J2&K2&M2&N2&O2&P2&Q2&R2&S2&T2 -> **Description:** This policy replaces the specified fraction of newly sold non-electric building components of the selected type(s) in buildings of the selected type(s) with electricity-using components. // **Guidance for setting values:** //**Urban Residential Heating:** In the BAU case, in New Jersey, the share of electricity among fuels used for heating in urban, residential buildings will rise from 7% to 11% through 2050.//**Urban Residential Appliances:** In the BAU case, in New Jersey, the share of electricity among fuels used for appliances in urban, residential buildings will fall from 31% to 30% through 2050.//**Urban Residential Other Components:** In the United States, the share of electricity among fuels used by other components in urban, residential buildings is 100%.//**Rural Residential Heating:** In the BAU case, in New Jersey, the share of electricity among fuels used for heating in rural, residential buildings will rise from 7% to 11% through 2050.//**Rural Residential Appliances:** In the BAU case, in New Jersey, the share of electricity among fuels used for appliances in rural, residential buildings will fall from 30% to 30% through 2050.//**Rural Residential Other Components:** In the United States, the share of electricity among fuels used by other components in rural, residential buildings is 100%.//**Commercial Heating:** In the BAU case, in New Jersey, the share of electricity among fuels used for heating in commercial buildings will fall from 3% to 3% through 2050.//**Comercial Appliances:** In the BAU case, in New Jersey, the share of electricity among fuels used for appliances in commercial buildings will fall from 30% to 28% through 2050.//**Comercial Other Components:** In the BAU case, in New Jersey, the share of electricity among fuels used for other components in commercial buildings will rise from 66% to 76% through 2050. | M2: =_xlfn.CONCAT("//**Urban Residential Appliances:** In the BAU case, in ",About!$C$2,", the share of electricity among fuels used for appliances in urban, residential buildings will ",IF('Supporting Data'!$BY$3<'Supporting Data'!$BZ$3,"rise","fall")," from ",'Supporting Data'!$BY$3,"% to ",'Supporting Data'!$BZ$3,"% through 2050.") -> //**Urban Residential Appliances:** In the BAU case, in New Jersey, the share of electricity among fuels used for appliances in urban, residential buildings will fall from 31% to 30% through 2050. | N2: =_xlfn.CONCAT("//**Urban Residential Other Components:** In the United States, the share of electricity among fuels used by other components in urban, residential buildings is 100%.") -> //**Urban Residential Other Components:** In the United States, the share of electricity among fuels used by other components in urban, residential buildings is 100%. | O2: =_xlfn.CONCAT("//**Rural Residential Heating:** In the BAU case, in ",About!$C$2,", the share of electricity among fuels used for heating in rural, residential buildings will ",IF('Supporting Data'!$CC$3<'Supporting Data'!$CD$3,"rise","fall")," from ",'Supporting Data'!$CC$3,"% to ",'Supporting Data'!$CD$3,"% through 2050.") -> //**Rural Residential Heating:** In the BAU case, in New Jersey, the share of electricity among fuels used for heating in rural, residential buildings will rise from 7% to 11% through 2050. | P2: =_xlfn.CONCAT("//**Rural Residential Appliances:** In the BAU case, in ",About!$C$2,", the share of electricity among fuels used for appliances in rural, residential buildings will ",IF('Supporting Data'!$CE$3<'Supporting Data'!$CF$3,"rise","fall")," from ",'Supporting Data'!$CE$3,"% to ",'Supporting Data'!$CF$3,"% through 2050.") -> //**Rural Residential Appliances:** In the BAU case, in New Jersey, the share of electricity among fuels used for appliances in rural, residential buildings will fall from 30% to 30% through 2050. | Q2: =_xlfn.CONCAT("//**Rural Residential Other Components:** In the United States, the share of electricity among fuels used by other components in rural, residential buildings is 100%.") -> //**Rural Residential Other Components:** In the United States, the share of electricity among fuels used by other components in rural, residential buildings is 100%. | R2: =_xlfn.CONCAT("//**Commercial Heating:** In the BAU case, in ",About!$C$2,", the share of electricity among fuels used for heating in commercial buildings will ",IF('Supporting Data'!$BQ3<'Supporting Data'!$BR$3,"rise","fall")," from ",'Supporting Data'!$BQ$3,"% to ",'Supporting Data'!$BR$3,"% through 2050.") -> //**Commercial Heating:** In the BAU case, in New Jersey, the share of electricity among fuels used for heating in commercial buildings will fall from 3% to 3% through 2050. | S2: =_xlfn.CONCAT("//**Comercial Appliances:** In the BAU case, in ",About!$C$2,", the share of electricity among fuels used for appliances in commercial buildings will ",IF('Supporting Data'!$BS$3<'Supporting Data'!$BT$3,"rise","fall")," from ",'Supporting Data'!$BS$3,"% to ",'Supporting Data'!$BT$3,"% through 2050.") -> //**Comercial Appliances:** In the BAU case, in New Jersey, the share of electricity among fuels used for appliances in commercial buildings will fall from 30% to 28% through 2050. | T2: =_xlfn.CONCAT("//**Comercial Other Components:** In the BAU case, in ",About!$C$2,", the share of electricity among fuels used for other components in commercial buildings will ",IF('Supporting Data'!$BU3<'Supporting Data'!$BV$3,"rise","fall")," from ",'Supporting Data'!$BU$3,"% to ",'Supporting Data'!$BV$3,"% through 2050.") -> //**Comercial Other Components:** In the BAU case, in New Jersey, the share of electricity among fuels used for other components in commercial buildings will rise from 66% to 76% through 2050.
