Workbook

Sheet About
A1: BDbDT - BAU Deaths by Demographic Trait (state, 2024-2050) | B1: New Jersey
A2: State code (derived): | B2: =IFERROR(INDEX(Geography!B:B, MATCH($B$1, Geography!C:C, 0)), "") -> NJ
A3: Active state:
A5: Methodology (see docs/methodology/BDbDT.md):
A6: state_trait_deaths[year]
A7: = US_trait_deaths[year]
A8: * (state_total_pop[year] / US_total_pop[year])
A9: * K_trait
A10: K_trait = (state_pop_in_trait[2024] / state_total_pop[2024])
A11: / (US_pop_in_trait[2024] / US_total_pop[2024])
A13: Trait definitions (parallel layout - hispanic/nonhispanic are separate from race rows;
A14: race rows include all Hispanic origin per legacy BDbDT convention):
A15: male, female = SEX column
A16: white, black, asian = Census race-alone (any Hispanic origin)
... A36: Build: outputs/BDbDT/_build_bdbdt_workbook.py

Sheet Geography
A1: state_fips | B1: state_abbr | C1: state_name | D1: division_num | E1: division_name
A2: 01 | B2: AL | C2: Alabama | D2: 6 | E2: East South Central
A3: 04 | B3: AZ | C3: Arizona | D3: 9 | E3: Mountain South
A4: 05 | B4: AR | C4: Arkansas | D4: 7 | E4: West South Central
A5: 06 | B5: CA | C5: California | D5: 10 | E5: Pacific
A6: 08 | B6: CO | C6: Colorado | D6: 8 | E6: Mountain North
A7: 09 | B7: CT | C7: Connecticut | D7: 1 | E7: New England
A8: 10 | B8: DE | C8: Delaware | D8: 5 | E8: South Atlantic
A9: 12 | B9: FL | C9: Florida | D9: 5 | E9: South Atlantic
A10: 13 | B10: GA | C10: Georgia | D10: 5 | E10: South Atlantic
A11: 16 | B11: ID | C11: Idaho | D11: 8 | E11: Mountain North
A12: 17 | B12: IL | C12: Illinois | D12: 3 | E12: East North Central
A13: 18 | B13: IN | C13: Indiana | D13: 3 | E13: East North Central
... A49: 56 | B49: WY | C49: Wyoming | D49: 8 | E49: Mountain North

Sheet Keys
A1: trait | B1: d3_sex | C1: d3_rh_1 | D1: d3_rh_2 | E1: d3_rh_3 | F1: d3_rh_4 | G1: d3_rh_5 | H1: d3_rh_6 | I1: sce_sex | J1: sce_origin | K1: sce_race_1 | L1: sce_race_2 | M1: sce_race_3 | N1: sce_race_4 | O1: sce_race_5 | P1: sce_race_6 | Q1: d1_sex | R1: d1_origin | S1: d1_race_1 | T1: d1_race_2 | U1: d1_race_3 | V1: d1_race_4 | W1: d1_race_5 | X1: d1_race_6 | Y1: notes
A2: male | B2: 1 | C2: 0 | I2: 1 | J2: 0 | K2: 1 | L2: 2 | M2: 3 | N2: 4 | O2: 5 | P2: 6 | Q2: 1 | R2: 0 | S2: 0
A3: female | B3: 2 | C3: 0 | I3: 2 | J3: 0 | K3: 1 | L3: 2 | M3: 3 | N3: 4 | O3: 5 | P3: 6 | Q3: 2 | R3: 0 | S3: 0
A4: white | B4: 0 | C4: 1 | I4: 0 | J4: 0 | K4: 1 | Q4: 0 | R4: 0 | S4: 1
A5: black | B5: 0 | C5: 2 | I5: 0 | J5: 0 | K5: 2 | Q5: 0 | R5: 0 | S5: 2
A6: asian | B6: 0 | C6: 4 | I6: 0 | J6: 0 | K6: 4 | Q6: 0 | R6: 0 | S6: 4
A7: other race | B7: 0 | C7: 3 | D7: 5 | E7: 6 | I7: 0 | J7: 0 | K7: 3 | L7: 5 | M7: 6 | Q7: 0 | R7: 0 | S7: 3 | T7: 5 | U7: 6
A8: hispanic | B8: 0 | C8: 8 | I8: 0 | J8: 2 | K8: 1 | L8: 2 | M8: 3 | N8: 4 | O8: 5 | P8: 6 | Q8: 0 | R8: 2 | S8: 0
A9: nonhispanic | B9: 0 | C9: 7 | I9: 0 | J9: 1 | K9: 1 | L9: 2 | M9: 3 | N9: 4 | O9: 5 | P9: 6 | Q9: 0 | R9: 1 | S9: 0

Sheet NP2023_deaths
A1: RACE_HISP | B1: SEX | C1: YEAR | D1: TOTAL_DEATHS | E1: DTH_0_INFANT | F1: DTH_1PLUS_OTHER
A2: 0 | B2: 0 | C2: 2024 | D2: 2911571 | E2: 16915 | F2: =D2-E2 -> 2894656
A3: 0 | B3: 0 | C3: 2025 | D3: 2960487 | E3: 16803 | F3: =D3-E3 -> 2943684
A4: 0 | B4: 0 | C4: 2026 | D4: 3009069 | E4: 16690 | F4: =D4-E4 -> 2992379
A5: 0 | B5: 0 | C5: 2027 | D5: 3058180 | E5: 16576 | F5: =D5-E5 -> 3041604
A6: 0 | B6: 0 | C6: 2028 | D6: 3108324 | E6: 16458 | F6: =D6-E6 -> 3091866
A7: 0 | B7: 0 | C7: 2029 | D7: 3159601 | E7: 16338 | F7: =D7-E7 -> 3143263
A8: 0 | B8: 0 | C8: 2030 | D8: 3211992 | E8: 16215 | F8: =D8-E8 -> 3195777
A9: 0 | B9: 0 | C9: 2031 | D9: 3265202 | E9: 16090 | F9: =D9-E9 -> 3249112
A10: 0 | B10: 0 | C10: 2032 | D10: 3318855 | E10: 15961 | F10: =D10-E10 -> 3302894
A11: 0 | B11: 0 | C11: 2033 | D11: 3372599 | E11: 15827 | F11: =D11-E11 -> 3356772
A12: 0 | B12: 0 | C12: 2034 | D12: 3426224 | E12: 15689 | F12: =D12-E12 -> 3410535
A13: 0 | B13: 0 | C13: 2035 | D13: 3479569 | E13: 15546 | F13: =D13-E13 -> 3464023
... A811: 9 | B811: 2 | C811: 2050 | D811: 1308033 | E811: 1910 | F811: =D811-E811 -> 1306123

Sheet NP2023_pop
A1: SEX | B1: ORIGIN | C1: RACE | D1: YEAR | E1: TOTAL_POP
A2: 0 | B2: 0 | C2: 0 | D2: 2024 | E2: 336482168
A3: 0 | B3: 0 | C3: 0 | D3: 2025 | E3: 338016259
A4: 0 | B4: 0 | C4: 0 | D4: 2026 | E4: 339513045
A5: 0 | B5: 0 | C5: 0 | D5: 2027 | E5: 340970496
A6: 0 | B6: 0 | C6: 0 | D6: 2028 | E6: 342384777
A7: 0 | B7: 0 | C7: 0 | D7: 2029 | E7: 343753791
A8: 0 | B8: 0 | C8: 0 | D8: 2030 | E8: 345073565
A9: 0 | B9: 0 | C9: 0 | D9: 2031 | E9: 346339264
A10: 0 | B10: 0 | C10: 0 | D10: 2032 | E10: 347545098
A11: 0 | B11: 0 | C11: 0 | D11: 2033 | E11: 348701812
A12: 0 | B12: 0 | C12: 0 | D12: 2034 | E12: 349807647
A13: 0 | B13: 0 | C13: 0 | D13: 2035 | E13: 350861084
... A2917: 2 | B2917: 2 | C2917: 11 | D2917: 2050 | E2917: 334547

Sheet SCE_2024_state_pop
A1: STATE_FIPS | B1: STATE_NAME | C1: SEX | D1: ORIGIN | E1: RACE | F1: POP_2024
A2: 01 | B2: Alabama | C2: 0 | D2: 0 | E2: 1 | F2: 3545537
A3: 01 | B3: Alabama | C3: 0 | D3: 0 | E3: 2 | F3: 1368358
A4: 01 | B4: Alabama | C4: 0 | D4: 0 | E4: 3 | F4: 40544
A5: 01 | B5: Alabama | C5: 0 | D5: 0 | E5: 4 | F5: 89421
A6: 01 | B6: Alabama | C6: 0 | D6: 0 | E6: 5 | F6: 6630
A7: 01 | B7: Alabama | C7: 0 | D7: 0 | E7: 6 | F7: 107209
A8: 01 | B8: Alabama | C8: 0 | D8: 1 | E8: 1 | F8: 3284059
A9: 01 | B9: Alabama | C9: 0 | D9: 1 | E9: 2 | F9: 1347486
A10: 01 | B10: Alabama | C10: 0 | D10: 1 | E10: 3 | F10: 28411
A11: 01 | B11: Alabama | C11: 0 | D11: 1 | E11: 4 | F11: 86926
A12: 01 | B12: Alabama | C12: 0 | D12: 1 | E12: 5 | F12: 2916
A13: 01 | B13: Alabama | C13: 0 | D13: 1 | E13: 6 | F13: 96454
... A2593: 56 | B2593: Wyoming | C2593: 2 | D2593: 2 | E2593: 6 | F2593: 1460

Sheet Census_pop_2020_2025
A1: table with row headers in column A and column headers in rows 3 through 4. (leading dots indicate sub-parts)
A2: Annual Estimates of the Resident Population for the United States, Regions, States, District of Columbia, and Puerto Rico: April 1, 2020 to July 1, 2025
A3: Geographic Area | B3: April 1, 2020 Estimates Base | C3: Population Estimate (as of July 1)
C4: 2020 | D4: 2021 | E4: 2022 | F4: 2023 | G4: 2024 | H4: 2025
A5: United States | B5: 331516113 | C5: 331578104 | D5: 332100166 | E5: 333996304 | F5: 336755052 | G5: 340003797 | H5: 341784857
A6: Northeast | B6: 57617560 | C6: 57436027 | D6: 57234503 | E6: 57174375 | F6: 57458539 | G6: 57940522 | H6: 58042054
A7: Midwest | B7: 68999462 | C7: 68979566 | D7: 68867096 | E7: 68872112 | F7: 69132050 | G7: 69518281 | H7: 69762666
A8: South | B8: 126281605 | C8: 126473371 | D8: 127380165 | E8: 129066102 | F8: 130894372 | G8: 132662072 | H8: 133833983
A9: West | B9: 78617486 | C9: 78689140 | D9: 78618402 | E9: 78883715 | F9: 79270091 | G9: 79882922 | H9: 80146154
A10: .Alabama | B10: 5025437 | C10: 5032962 | D10: 5050058 | E10: 5076868 | F10: 5117850 | G10: 5163055 | H10: 5193088
A11: .Alaska | B11: 733383 | C11: 732906 | D11: 734590 | E11: 733659 | F11: 734654 | G11: 736537 | H11: 737270
A12: .Arizona | B12: 7158104 | C12: 7186647 | D12: 7274022 | E12: 7370065 | F12: 7452073 | G12: 7556424 | H12: 7623818
A13: .Arkansas | B13: 3011530 | C13: 3014399 | D13: 3027127 | E13: 3047429 | F13: 3069856 | G13: 3096080 | H13: 3114791
A14: .California | B14: 39555703 | C14: 39527808 | D14: 39152927 | E14: 39125347 | F14: 39181667 | G14: 39364774 | H14: 39355309
A15: .Colorado | B15: 5775326 | C15: 5786873 | D15: 5814368 | E15: 5853355 | F15: 5912240 | G15: 5988502 | H15: 6012561
A16: .Connecticut | B16: 3607750 | C16: 3579643 | D16: 3607765 | E16: 3618707 | F16: 3641369 | G16: 3674449 | H16: 3688496
... A62: .Puerto Rico | B62: 3285874 | C62: 3281591 | D62: 3262731 | E62: 3220148 | F62: 3203794 | G62: 3202521 | H62: 3184835
A63: The Census Bureau has reviewed this data product to ensure appropriate access, use, and disclosure avoidance protection of the confidential source data used to produce this product (Data Management System (DMS) number: P-6000042 and P-7501659. Disclosure Review Board (DRB) approval number: CBDRB-FY25-0466).
A64: The estimates are based on the 2020 Modified Age and Race Census (MARC) file and include changes from Count Question Resolution, the Post-Census Group Quarters Review, and geographic revisions. For population estimates methodology statements, see https://www.census.gov/programs-surveys/popest/technical-documentation/methodology.html. See Geographic Terms and Definitions at https://www.census.gov/programs-surveys/popest/guidance-geographies/terms-and-definitions.html for a list of the states that are included in each region. All geographic boundaries for the 2025 population estimates series are as of January 1, 2025.
A65: Suggested Citation:
A66: Annual Estimates of the Resident Population for the United States, Regions, States, District of Columbia, and Puerto Rico: April 1, 2020 to July 1, 2025 (NST-EST2025-POP)
A67: Source: U.S. Census Bureau, Population Division
A68: Release Date: January 2026

Sheet Cooper_pop_2030_2050
A1: Total Population for the U.S., the 50 States, and the District of Columbia: Census 2020 and Projections 2030-2050
A2: Released on July 1, 2024 by the University of Virginia, Weldon Cooper Center for Public Service, https://www.coopercenter.org/national-population-projections
A3: FIPS | B3: Geography Name | C3: Total Population
C4: 2020 | D4: 2030 | E4: 2040 | F4: 2050
A5: 0 | B5: United States | C5: 331449281 | D5: 3.4969586e+08 | E5: 3.6229347e+08 | F5: 3.7176698e+08
A6: 1 | B6: Alabama | C6: 5024279 | D6: 5213942 | E6: 5269412 | F6: 5263068.8
A7: 2 | B7: Alaska | C7: 733391 | D7: 751138.61 | E7: 745730.94 | F7: 731686.72
A8: 4 | B8: Arizona | C8: 7151502 | D8: 7766235.9 | E8: 8354030.3 | F8: 8881011.8
A9: 5 | B9: Arkansas | C9: 3011524 | D9: 3084795.8 | E9: 3063116.9 | F9: 3005949.3
A10: 6 | B10: California | C10: 39538223 | D10: 41321454 | E10: 42164453 | F10: 42520492
A11: 8 | B11: Colorado | C11: 5773714 | D11: 6387211.4 | E11: 7050081.3 | F11: 7690558.6
A12: 9 | B12: Connecticut | C12: 3605944 | D12: 3629971.1 | E12: 3521129 | F12: 3375527.4
A13: 10 | B13: Delaware | C13: 989948 | D13: 1063673 | E13: 1127462.8 | F13: 1181074.4
A14: 11 | B14: District of Columbia | C14: 689545 | D14: 761820.35 | E14: 839353.09 | F14: 913940.14
A15: 12 | B15: Florida | C15: 21538187 | D15: 23790046 | E15: 26202483 | F15: 28521380
A16: 13 | B16: Georgia | C16: 10711908 | D16: 11534245 | E16: 12262064 | F16: 12883056
... A56: 56 | B56: Wyoming | C56: 576851 | D56: 586924.91 | E56: 577538.97 | F56: 561643.82
A57: Subgroups may not sum to total due to rounding

Sheet BDbDT_calcs
A1: BDbDT_calcs - state deaths by trait, 2024-2050 (active state from About!B1)
A2: year -> | B2: 2024 | C2: 2025 | D2: 2026 | E2: 2027 | F2: 2028 | G2: 2029 | H2: 2030 | I2: 2031 | J2: 2032 | K2: 2033 | L2: 2034 | M2: 2035 | N2: 2036 | O2: 2037 | P2: 2038 | Q2: 2039 | R2: 2040 | S2: 2041 | T2: 2042 | U2: 2043 | V2: 2044 | W2: 2045 | X2: 2046 | Y2: 2047 | Z2: 2048 | AA2: 2049 | AB2: 2050
A3: trait | B3: state_pop_in_trait_2024 | C3: state_total_pop_2024 | D3: US_pop_in_trait_2024 | E3: US_total_pop_2024 | F3: K_trait
A4: male | B4: =IF(Keys!$K$2="", 0, IFERROR(SUMIFS(SCE_2024_state_pop!$F:$F, SCE_2024_state_pop!$B:$B, About!$B$1, SCE_2024_state_pop!$C:$C, Keys!$I2, SCE_2024_state_pop!$D:$D, Keys!$J2, SCE_2024_state_pop!$E:$E, Keys!$K$2), 0))+IF(Keys!$L$2="", 0, IFERROR(SUMIFS(SCE_2024_state_pop!$F:$F, SCE_2024_state_pop!$B:$B, About!$B$1, SCE_2024_state_pop!$C:$C, Keys!$I2, SCE_2024_state_pop!$D:$D, Keys!$J2, SCE_2024_state_pop!$E:$E, Keys!$L$2), 0))+IF(Keys!$M$2="", 0, IFERROR(SUMIFS(SCE_2024_state_pop!$F:$F, SCE_2024_state_pop!$B:$B, About!$B$1, SCE_2024_state_pop!$C:$C, Keys!$I2, SCE_2024_state_pop!$D:$D, Keys!$J2, SCE_2024_state_pop!$E:$E, Keys!$M$2), 0))+IF(Keys!$N$2="", 0, IFERROR(SUMIFS(SCE_2024_state_pop!$F:$F, SCE_2024_state_pop!$B:$B, About!$B$1, SCE_2024_state_pop!$C:$C, Keys!$I2, SCE_2024_state_pop!$D:$D, Keys!$J2, SCE_2024_state_pop!$E:$E, Keys!$N$2), 0))+IF(Keys!$O$2="", 0, IFERROR(SUMIFS(SCE_2024_state_pop!$F:$F, SCE_2024_state_pop!$B:$B, About!$B$1, SCE_2024_state_pop!$C:$C, Keys!$I2, SCE_2024_state_pop!$D:$D, Keys!$J2, SCE_2024_state_pop!$E:$E, Keys!$O$2), 0))+IF(Keys!$P$2="", 0, IFERROR(SUMIFS(SCE_2024_state_pop!$F:$F, SCE_2024_state_pop!$B:$B, About!$B$1, SCE_2024_state_pop!$C:$C, Keys!$I2, SCE_2024_state_pop!$D:$D, Keys!$J2, SCE_2024_state_pop!$E:$E, Keys!$P$2), 0)) -> 4677937 | C4: =SUMIFS(SCE_2024_state_pop!$F:$F, SCE_2024_state_pop!$B:$B, About!$B$1, SCE_2024_state_pop!$C:$C, 0, SCE_2024_state_pop!$D:$D, 0, SCE_2024_state_pop!$E:$E, 1)+SUMIFS(SCE_2024_state_pop!$F:$F, SCE_2024_state_pop!$B:$B, About!$B$1, SCE_2024_state_pop!$C:$C, 0, SCE_2024_state_pop!$D:$D, 0, SCE_2024_state_pop!$E:$E, 2)+SUMIFS(SCE_2024_state_pop!$F:$F, SCE_2024_state_pop!$B:$B, About!$B$1, SCE_2024_state_pop!$C:$C, 0, SCE_2024_state_pop!$D:$D, 0, SCE_2024_state_pop!$E:$E, 3)+SUMIFS(SCE_2024_state_pop!$F:$F, SCE_2024_state_pop!$B:$B, About!$B$1, SCE_2024_state_pop!$C:$C, 0, SCE_2024_state_pop!$D:$D, 0, SCE_2024_state_pop!$E:$E, 4)+SUMIFS(SCE_2024_state_pop!$F:$F, SCE_2024_state_pop!$B:$B, About!$B$1, SCE_2024_state_pop!$C:$C, 0, SCE_2024_state_pop!$D:$D, 0, SCE_2024_state_pop!$E:$E, 5)+SUMIFS(SCE_2024_state_pop!$F:$F, SCE_2024_state_pop!$B:$B, About!$B$1, SCE_2024_state_pop!$C:$C, 0, SCE_2024_state_pop!$D:$D, 0, SCE_2024_state_pop!$E:$E, 6) -> 9500851 | D4: =IF(Keys!$S$2="", 0, IFERROR(SUMIFS(NP2023_pop!$E:$E, NP2023_pop!$A:$A, Keys!$Q2, NP2023_pop!$B:$B, Keys!$R2, NP2023_pop!$C:$C, Keys!$S$2, NP2023_pop!$D:$D, 2024), 0))+IF(Keys!$T$2="", 0, IFERROR(SUMIFS(NP2023_pop!$E:$E, NP2023_pop!$A:$A, Keys!$Q2, NP2023_pop!$B:$B, Keys!$R2, NP2023_pop!$C:$C, Keys!$T$2, NP2023_pop!$D:$D, 2024), 0))+IF(Keys!$U$2="", 0, IFERROR(SUMIFS(NP2023_pop!$E:$E, NP2023_pop!$A:$A, Keys!$Q2, NP2023_pop!$B:$B, Keys!$R2, NP2023_pop!$C:$C, Keys!$U$2, NP2023_pop!$D:$D, 2024), 0))+IF(Keys!$V$2="", 0, IFERROR(SUMIFS(NP2023_pop!$E:$E, NP2023_pop!$A:$A, Keys!$Q2, NP2023_pop!$B:$B, Keys!$R2, NP2023_pop!$C:$C, Keys!$V$2, NP2023_pop!$D:$D, 2024), 0))+IF(Keys!$W$2="", 0, IFERROR(SUMIFS(NP2023_pop!$E:$E, NP2023_pop!$A:$A, Keys!$Q2, NP2023_pop!$B:$B, Keys!$R2, NP2023_pop!$C:$C, Keys!$W$2, NP2023_pop!$D:$D, 2024), 0))+IF(Keys!$X$2="", 0, IFERROR(SUMIFS(NP2023_pop!$E:$E, NP2023_pop!$A:$A, Keys!$Q2, NP2023_pop!$B:$B, Keys!$R2, NP2023_pop!$C:$C, Keys!$X$2, NP2023_pop!$D:$D, 2024), 0)) -> 166813721 | E4: =SUMIFS(NP2023_pop!$E:$E, NP2023_pop!$A:$A, 0, NP2023_pop!$B:$B, 0, NP2023_pop!$C:$C, 0, NP2023_pop!$D:$D, 2024) -> 336482168 | F4: =IFERROR((B4/C4)/(D4/E4), 0) -> 0.99316669
A5: female | B5: =IF(Keys!$K$3="", 0, IFERROR(SUMIFS(SCE_2024_state_pop!$F:$F, SCE_2024_state_pop!$B:$B, About!$B$1, SCE_2024_state_pop!$C:$C, Keys!$I3, SCE_2024_state_pop!$D:$D, Keys!$J3, SCE_2024_state_pop!$E:$E, Keys!$K$3), 0))+IF(Keys!$L$3="", 0, IFERROR(SUMIFS(SCE_2024_state_pop!$F:$F, SCE_2024_state_pop!$B:$B, About!$B$1, SCE_2024_state_pop!$C:$C, Keys!$I3, SCE_2024_state_pop!$D:$D, Keys!$J3, SCE_2024_state_pop!$E:$E, Keys!$L$3), 0))+IF(Keys!$M$3="", 0, IFERROR(SUMIFS(SCE_2024_state_pop!$F:$F, SCE_2024_state_pop!$B:$B, About!$B$1, SCE_2024_state_pop!$C:$C, Keys!$I3, SCE_2024_state_pop!$D:$D, Keys!$J3, SCE_2024_state_pop!$E:$E, Keys!$M$3), 0))+IF(Keys!$N$3="", 0, IFERROR(SUMIFS(SCE_2024_state_pop!$F:$F, SCE_2024_state_pop!$B:$B, About!$B$1, SCE_2024_state_pop!$C:$C, Keys!$I3, SCE_2024_state_pop!$D:$D, Keys!$J3, SCE_2024_state_pop!$E:$E, Keys!$N$3), 0))+IF(Keys!$O$3="", 0, IFERROR(SUMIFS(SCE_2024_state_pop!$F:$F, SCE_2024_state_pop!$B:$B, About!$B$1, SCE_2024_state_pop!$C:$C, Keys!$I3, SCE_2024_state_pop!$D:$D, Keys!$J3, SCE_2024_state_pop!$E:$E, Keys!$O$3), 0))+IF(Keys!$P$3="", 0, IFERROR(SUMIFS(SCE_2024_state_pop!$F:$F, SCE_2024_state_pop!$B:$B, About!$B$1, SCE_2024_state_pop!$C:$C, Keys!$I3, SCE_2024_state_pop!$D:$D, Keys!$J3, SCE_2024_state_pop!$E:$E, Keys!$P$3), 0)) -> 4822914 | C5: =SUMIFS(SCE_2024_state_pop!$F:$F, SCE_2024_state_pop!$B:$B, About!$B$1, SCE_2024_state_pop!$C:$C, 0, SCE_2024_state_pop!$D:$D, 0, SCE_2024_state_pop!$E:$E, 1)+SUMIFS(SCE_2024_state_pop!$F:$F, SCE_2024_state_pop!$B:$B, About!$B$1, SCE_2024_state_pop!$C:$C, 0, SCE_2024_state_pop!$D:$D, 0, SCE_2024_state_pop!$E:$E, 2)+SUMIFS(SCE_2024_state_pop!$F:$F, SCE_2024_state_pop!$B:$B, About!$B$1, SCE_2024_state_pop!$C:$C, 0, SCE_2024_state_pop!$D:$D, 0, SCE_2024_state_pop!$E:$E, 3)+SUMIFS(SCE_2024_state_pop!$F:$F, SCE_2024_state_pop!$B:$B, About!$B$1, SCE_2024_state_pop!$C:$C, 0, SCE_2024_state_pop!$D:$D, 0, SCE_2024_state_pop!$E:$E, 4)+SUMIFS(SCE_2024_state_pop!$F:$F, SCE_2024_state_pop!$B:$B, About!$B$1, SCE_2024_state_pop!$C:$C, 0, SCE_2024_state_pop!$D:$D, 0, SCE_2024_state_pop!$E:$E, 5)+SUMIFS(SCE_2024_state_pop!$F:$F, SCE_2024_state_pop!$B:$B, About!$B$1, SCE_2024_state_pop!$C:$C, 0, SCE_2024_state_pop!$D:$D, 0, SCE_2024_state_pop!$E:$E, 6) -> 9500851 | D5: =IF(Keys!$S$3="", 0, IFERROR(SUMIFS(NP2023_pop!$E:$E, NP2023_pop!$A:$A, Keys!$Q3, NP2023_pop!$B:$B, Keys!$R3, NP2023_pop!$C:$C, Keys!$S$3, NP2023_pop!$D:$D, 2024), 0))+IF(Keys!$T$3="", 0, IFERROR(SUMIFS(NP2023_pop!$E:$E, NP2023_pop!$A:$A, Keys!$Q3, NP2023_pop!$B:$B, Keys!$R3, NP2023_pop!$C:$C, Keys!$T$3, NP2023_pop!$D:$D, 2024), 0))+IF(Keys!$U$3="", 0, IFERROR(SUMIFS(NP2023_pop!$E:$E, NP2023_pop!$A:$A, Keys!$Q3, NP2023_pop!$B:$B, Keys!$R3, NP2023_pop!$C:$C, Keys!$U$3, NP2023_pop!$D:$D, 2024), 0))+IF(Keys!$V$3="", 0, IFERROR(SUMIFS(NP2023_pop!$E:$E, NP2023_pop!$A:$A, Keys!$Q3, NP2023_pop!$B:$B, Keys!$R3, NP2023_pop!$C:$C, Keys!$V$3, NP2023_pop!$D:$D, 2024), 0))+IF(Keys!$W$3="", 0, IFERROR(SUMIFS(NP2023_pop!$E:$E, NP2023_pop!$A:$A, Keys!$Q3, NP2023_pop!$B:$B, Keys!$R3, NP2023_pop!$C:$C, Keys!$W$3, NP2023_pop!$D:$D, 2024), 0))+IF(Keys!$X$3="", 0, IFERROR(SUMIFS(NP2023_pop!$E:$E, NP2023_pop!$A:$A, Keys!$Q3, NP2023_pop!$B:$B, Keys!$R3, NP2023_pop!$C:$C, Keys!$X$3, NP2023_pop!$D:$D, 2024), 0)) -> 169668447 | E5: =SUMIFS(NP2023_pop!$E:$E, NP2023_pop!$A:$A, 0, NP2023_pop!$B:$B, 0, NP2023_pop!$C:$C, 0, NP2023_pop!$D:$D, 2024) -> 336482168 | F5: =IFERROR((B5/C5)/(D5/E5), 0) -> 1.0067183
A6: white | B6: =IF(Keys!$K$4="", 0, IFERROR(SUMIFS(SCE_2024_state_pop!$F:$F, SCE_2024_state_pop!$B:$B, About!$B$1, SCE_2024_state_pop!$C:$C, Keys!$I4, SCE_2024_state_pop!$D:$D, Keys!$J4, SCE_2024_state_pop!$E:$E, Keys!$K$4), 0))+IF(Keys!$L$4="", 0, IFERROR(SUMIFS(SCE_2024_state_pop!$F:$F, SCE_2024_state_pop!$B:$B, About!$B$1, SCE_2024_state_pop!$C:$C, Keys!$I4, SCE_2024_state_pop!$D:$D, Keys!$J4, SCE_2024_state_pop!$E:$E, Keys!$L$4), 0))+IF(Keys!$M$4="", 0, IFERROR(SUMIFS(SCE_2024_state_pop!$F:$F, SCE_2024_state_pop!$B:$B, About!$B$1, SCE_2024_state_pop!$C:$C, Keys!$I4, SCE_2024_state_pop!$D:$D, Keys!$J4, SCE_2024_state_pop!$E:$E, Keys!$M$4), 0))+IF(Keys!$N$4="", 0, IFERROR(SUMIFS(SCE_2024_state_pop!$F:$F, SCE_2024_state_pop!$B:$B, About!$B$1, SCE_2024_state_pop!$C:$C, Keys!$I4, SCE_2024_state_pop!$D:$D, Keys!$J4, SCE_2024_state_pop!$E:$E, Keys!$N$4), 0))+IF(Keys!$O$4="", 0, IFERROR(SUMIFS(SCE_2024_state_pop!$F:$F, SCE_2024_state_pop!$B:$B, About!$B$1, SCE_2024_state_pop!$C:$C, Keys!$I4, SCE_2024_state_pop!$D:$D, Keys!$J4, SCE_2024_state_pop!$E:$E, Keys!$O$4), 0))+IF(Keys!$P$4="", 0, IFERROR(SUMIFS(SCE_2024_state_pop!$F:$F, SCE_2024_state_pop!$B:$B, About!$B$1, SCE_2024_state_pop!$C:$C, Keys!$I4, SCE_2024_state_pop!$D:$D, Keys!$J4, SCE_2024_state_pop!$E:$E, Keys!$P$4), 0)) -> 6612719 | C6: =SUMIFS(SCE_2024_state_pop!$F:$F, SCE_2024_state_pop!$B:$B, About!$B$1, SCE_2024_state_pop!$C:$C, 0, SCE_2024_state_pop!$D:$D, 0, SCE_2024_state_pop!$E:$E, 1)+SUMIFS(SCE_2024_state_pop!$F:$F, SCE_2024_state_pop!$B:$B, About!$B$1, SCE_2024_state_pop!$C:$C, 0, SCE_2024_state_pop!$D:$D, 0, SCE_2024_state_pop!$E:$E, 2)+SUMIFS(SCE_2024_state_pop!$F:$F, SCE_2024_state_pop!$B:$B, About!$B$1, SCE_2024_state_pop!$C:$C, 0, SCE_2024_state_pop!$D:$D, 0, SCE_2024_state_pop!$E:$E, 3)+SUMIFS(SCE_2024_state_pop!$F:$F, SCE_2024_state_pop!$B:$B, About!$B$1, SCE_2024_state_pop!$C:$C, 0, SCE_2024_state_pop!$D:$D, 0, SCE_2024_state_pop!$E:$E, 4)+SUMIFS(SCE_2024_state_pop!$F:$F, SCE_2024_state_pop!$B:$B, About!$B$1, SCE_2024_state_pop!$C:$C, 0, SCE_2024_state_pop!$D:$D, 0, SCE_2024_state_pop!$E:$E, 5)+SUMIFS(SCE_2024_state_pop!$F:$F, SCE_2024_state_pop!$B:$B, About!$B$1, SCE_2024_state_pop!$C:$C, 0, SCE_2024_state_pop!$D:$D, 0, SCE_2024_state_pop!$E:$E, 6) -> 9500851 | D6: =IF(Keys!$S$4="", 0, IFERROR(SUMIFS(NP2023_pop!$E:$E, NP2023_pop!$A:$A, Keys!$Q4, NP2023_pop!$B:$B, Keys!$R4, NP2023_pop!$C:$C, Keys!$S$4, NP2023_pop!$D:$D, 2024), 0))+IF(Keys!$T$4="", 0, IFERROR(SUMIFS(NP2023_pop!$E:$E, NP2023_pop!$A:$A, Keys!$Q4, NP2023_pop!$B:$B, Keys!$R4, NP2023_pop!$C:$C, Keys!$T$4, NP2023_pop!$D:$D, 2024), 0))+IF(Keys!$U$4="", 0, IFERROR(SUMIFS(NP2023_pop!$E:$E, NP2023_pop!$A:$A, Keys!$Q4, NP2023_pop!$B:$B, Keys!$R4, NP2023_pop!$C:$C, Keys!$U$4, NP2023_pop!$D:$D, 2024), 0))+IF(Keys!$V$4="", 0, IFERROR(SUMIFS(NP2023_pop!$E:$E, NP2023_pop!$A:$A, Keys!$Q4, NP2023_pop!$B:$B, Keys!$R4, NP2023_pop!$C:$C, Keys!$V$4, NP2023_pop!$D:$D, 2024), 0))+IF(Keys!$W$4="", 0, IFERROR(SUMIFS(NP2023_pop!$E:$E, NP2023_pop!$A:$A, Keys!$Q4, NP2023_pop!$B:$B, Keys!$R4, NP2023_pop!$C:$C, Keys!$W$4, NP2023_pop!$D:$D, 2024), 0))+IF(Keys!$X$4="", 0, IFERROR(SUMIFS(NP2023_pop!$E:$E, NP2023_pop!$A:$A, Keys!$Q4, NP2023_pop!$B:$B, Keys!$R4, NP2023_pop!$C:$C, Keys!$X$4, NP2023_pop!$D:$D, 2024), 0)) -> 252856984 | E6: =SUMIFS(NP2023_pop!$E:$E, NP2023_pop!$A:$A, 0, NP2023_pop!$B:$B, 0, NP2023_pop!$C:$C, 0, NP2023_pop!$D:$D, 2024) -> 336482168 | F6: =IFERROR((B6/C6)/(D6/E6), 0) -> 0.92619975
A7: black | B7: =IF(Keys!$K$5="", 0, IFERROR(SUMIFS(SCE_2024_state_pop!$F:$F, SCE_2024_state_pop!$B:$B, About!$B$1, SCE_2024_state_pop!$C:$C, Keys!$I5, SCE_2024_state_pop!$D:$D, Keys!$J5, SCE_2024_state_pop!$E:$E, Keys!$K$5), 0))+IF(Keys!$L$5="", 0, IFERROR(SUMIFS(SCE_2024_state_pop!$F:$F, SCE_2024_state_pop!$B:$B, About!$B$1, SCE_2024_state_pop!$C:$C, Keys!$I5, SCE_2024_state_pop!$D:$D, Keys!$J5, SCE_2024_state_pop!$E:$E, Keys!$L$5), 0))+IF(Keys!$M$5="", 0, IFERROR(SUMIFS(SCE_2024_state_pop!$F:$F, SCE_2024_state_pop!$B:$B, About!$B$1, SCE_2024_state_pop!$C:$C, Keys!$I5, SCE_2024_state_pop!$D:$D, Keys!$J5, SCE_2024_state_pop!$E:$E, Keys!$M$5), 0))+IF(Keys!$N$5="", 0, IFERROR(SUMIFS(SCE_2024_state_pop!$F:$F, SCE_2024_state_pop!$B:$B, About!$B$1, SCE_2024_state_pop!$C:$C, Keys!$I5, SCE_2024_state_pop!$D:$D, Keys!$J5, SCE_2024_state_pop!$E:$E, Keys!$N$5), 0))+IF(Keys!$O$5="", 0, IFERROR(SUMIFS(SCE_2024_state_pop!$F:$F, SCE_2024_state_pop!$B:$B, About!$B$1, SCE_2024_state_pop!$C:$C, Keys!$I5, SCE_2024_state_pop!$D:$D, Keys!$J5, SCE_2024_state_pop!$E:$E, Keys!$O$5), 0))+IF(Keys!$P$5="", 0, IFERROR(SUMIFS(SCE_2024_state_pop!$F:$F, SCE_2024_state_pop!$B:$B, About!$B$1, SCE_2024_state_pop!$C:$C, Keys!$I5, SCE_2024_state_pop!$D:$D, Keys!$J5, SCE_2024_state_pop!$E:$E, Keys!$P$5), 0)) -> 1481943 | C7: =SUMIFS(SCE_2024_state_pop!$F:$F, SCE_2024_state_pop!$B:$B, About!$B$1, SCE_2024_state_pop!$C:$C, 0, SCE_2024_state_pop!$D:$D, 0, SCE_2024_state_pop!$E:$E, 1)+SUMIFS(SCE_2024_state_pop!$F:$F, SCE_2024_state_pop!$B:$B, About!$B$1, SCE_2024_state_pop!$C:$C, 0, SCE_2024_state_pop!$D:$D, 0, SCE_2024_state_pop!$E:$E, 2)+SUMIFS(SCE_2024_state_pop!$F:$F, SCE_2024_state_pop!$B:$B, About!$B$1, SCE_2024_state_pop!$C:$C, 0, SCE_2024_state_pop!$D:$D, 0, SCE_2024_state_pop!$E:$E, 3)+SUMIFS(SCE_2024_state_pop!$F:$F, SCE_2024_state_pop!$B:$B, About!$B$1, SCE_2024_state_pop!$C:$C, 0, SCE_2024_state_pop!$D:$D, 0, SCE_2024_state_pop!$E:$E, 4)+SUMIFS(SCE_2024_state_pop!$F:$F, SCE_2024_state_pop!$B:$B, About!$B$1, SCE_2024_state_pop!$C:$C, 0, SCE_2024_state_pop!$D:$D, 0, SCE_2024_state_pop!$E:$E, 5)+SUMIFS(SCE_2024_state_pop!$F:$F, SCE_2024_state_pop!$B:$B, About!$B$1, SCE_2024_state_pop!$C:$C, 0, SCE_2024_state_pop!$D:$D, 0, SCE_2024_state_pop!$E:$E, 6) -> 9500851 | D7: =IF(Keys!$S$5="", 0, IFERROR(SUMIFS(NP2023_pop!$E:$E, NP2023_pop!$A:$A, Keys!$Q5, NP2023_pop!$B:$B, Keys!$R5, NP2023_pop!$C:$C, Keys!$S$5, NP2023_pop!$D:$D, 2024), 0))+IF(Keys!$T$5="", 0, IFERROR(SUMIFS(NP2023_pop!$E:$E, NP2023_pop!$A:$A, Keys!$Q5, NP2023_pop!$B:$B, Keys!$R5, NP2023_pop!$C:$C, Keys!$T$5, NP2023_pop!$D:$D, 2024), 0))+IF(Keys!$U$5="", 0, IFERROR(SUMIFS(NP2023_pop!$E:$E, NP2023_pop!$A:$A, Keys!$Q5, NP2023_pop!$B:$B, Keys!$R5, NP2023_pop!$C:$C, Keys!$U$5, NP2023_pop!$D:$D, 2024), 0))+IF(Keys!$V$5="", 0, IFERROR(SUMIFS(NP2023_pop!$E:$E, NP2023_pop!$A:$A, Keys!$Q5, NP2023_pop!$B:$B, Keys!$R5, NP2023_pop!$C:$C, Keys!$V$5, NP2023_pop!$D:$D, 2024), 0))+IF(Keys!$W$5="", 0, IFERROR(SUMIFS(NP2023_pop!$E:$E, NP2023_pop!$A:$A, Keys!$Q5, NP2023_pop!$B:$B, Keys!$R5, NP2023_pop!$C:$C, Keys!$W$5, NP2023_pop!$D:$D, 2024), 0))+IF(Keys!$X$5="", 0, IFERROR(SUMIFS(NP2023_pop!$E:$E, NP2023_pop!$A:$A, Keys!$Q5, NP2023_pop!$B:$B, Keys!$R5, NP2023_pop!$C:$C, Keys!$X$5, NP2023_pop!$D:$D, 2024), 0)) -> 45967323 | E7: =SUMIFS(NP2023_pop!$E:$E, NP2023_pop!$A:$A, 0, NP2023_pop!$B:$B, 0, NP2023_pop!$C:$C, 0, NP2023_pop!$D:$D, 2024) -> 336482168 | F7: =IFERROR((B7/C7)/(D7/E7), 0) -> 1.1417784
A8: asian | B8: =IF(Keys!$K$6="", 0, IFERROR(SUMIFS(SCE_2024_state_pop!$F:$F, SCE_2024_state_pop!$B:$B, About!$B$1, SCE_2024_state_pop!$C:$C, Keys!$I6, SCE_2024_state_pop!$D:$D, Keys!$J6, SCE_2024_state_pop!$E:$E, Keys!$K$6), 0))+IF(Keys!$L$6="", 0, IFERROR(SUMIFS(SCE_2024_state_pop!$F:$F, SCE_2024_state_pop!$B:$B, About!$B$1, SCE_2024_state_pop!$C:$C, Keys!$I6, SCE_2024_state_pop!$D:$D, Keys!$J6, SCE_2024_state_pop!$E:$E, Keys!$L$6), 0))+IF(Keys!$M$6="", 0, IFERROR(SUMIFS(SCE_2024_state_pop!$F:$F, SCE_2024_state_pop!$B:$B, About!$B$1, SCE_2024_state_pop!$C:$C, Keys!$I6, SCE_2024_state_pop!$D:$D, Keys!$J6, SCE_2024_state_pop!$E:$E, Keys!$M$6), 0))+IF(Keys!$N$6="", 0, IFERROR(SUMIFS(SCE_2024_state_pop!$F:$F, SCE_2024_state_pop!$B:$B, About!$B$1, SCE_2024_state_pop!$C:$C, Keys!$I6, SCE_2024_state_pop!$D:$D, Keys!$J6, SCE_2024_state_pop!$E:$E, Keys!$N$6), 0))+IF(Keys!$O$6="", 0, IFERROR(SUMIFS(SCE_2024_state_pop!$F:$F, SCE_2024_state_pop!$B:$B, About!$B$1, SCE_2024_state_pop!$C:$C, Keys!$I6, SCE_2024_state_pop!$D:$D, Keys!$J6, SCE_2024_state_pop!$E:$E, Keys!$O$6), 0))+IF(Keys!$P$6="", 0, IFERROR(SUMIFS(SCE_2024_state_pop!$F:$F, SCE_2024_state_pop!$B:$B, About!$B$1, SCE_2024_state_pop!$C:$C, Keys!$I6, SCE_2024_state_pop!$D:$D, Keys!$J6, SCE_2024_state_pop!$E:$E, Keys!$P$6), 0)) -> 1056776 | C8: =SUMIFS(SCE_2024_state_pop!$F:$F, SCE_2024_state_pop!$B:$B, About!$B$1, SCE_2024_state_pop!$C:$C, 0, SCE_2024_state_pop!$D:$D, 0, SCE_2024_state_pop!$E:$E, 1)+SUMIFS(SCE_2024_state_pop!$F:$F, SCE_2024_state_pop!$B:$B, About!$B$1, SCE_2024_state_pop!$C:$C, 0, SCE_2024_state_pop!$D:$D, 0, SCE_2024_state_pop!$E:$E, 2)+SUMIFS(SCE_2024_state_pop!$F:$F, SCE_2024_state_pop!$B:$B, About!$B$1, SCE_2024_state_pop!$C:$C, 0, SCE_2024_state_pop!$D:$D, 0, SCE_2024_state_pop!$E:$E, 3)+SUMIFS(SCE_2024_state_pop!$F:$F, SCE_2024_state_pop!$B:$B, About!$B$1, SCE_2024_state_pop!$C:$C, 0, SCE_2024_state_pop!$D:$D, 0, SCE_2024_state_pop!$E:$E, 4)+SUMIFS(SCE_2024_state_pop!$F:$F, SCE_2024_state_pop!$B:$B, About!$B$1, SCE_2024_state_pop!$C:$C, 0, SCE_2024_state_pop!$D:$D, 0, SCE_2024_state_pop!$E:$E, 5)+SUMIFS(SCE_2024_state_pop!$F:$F, SCE_2024_state_pop!$B:$B, About!$B$1, SCE_2024_state_pop!$C:$C, 0, SCE_2024_state_pop!$D:$D, 0, SCE_2024_state_pop!$E:$E, 6) -> 9500851 | D8: =IF(Keys!$S$6="", 0, IFERROR(SUMIFS(NP2023_pop!$E:$E, NP2023_pop!$A:$A, Keys!$Q6, NP2023_pop!$B:$B, Keys!$R6, NP2023_pop!$C:$C, Keys!$S$6, NP2023_pop!$D:$D, 2024), 0))+IF(Keys!$T$6="", 0, IFERROR(SUMIFS(NP2023_pop!$E:$E, NP2023_pop!$A:$A, Keys!$Q6, NP2023_pop!$B:$B, Keys!$R6, NP2023_pop!$C:$C, Keys!$T$6, NP2023_pop!$D:$D, 2024), 0))+IF(Keys!$U$6="", 0, IFERROR(SUMIFS(NP2023_pop!$E:$E, NP2023_pop!$A:$A, Keys!$Q6, NP2023_pop!$B:$B, Keys!$R6, NP2023_pop!$C:$C, Keys!$U$6, NP2023_pop!$D:$D, 2024), 0))+IF(Keys!$V$6="", 0, IFERROR(SUMIFS(NP2023_pop!$E:$E, NP2023_pop!$A:$A, Keys!$Q6, NP2023_pop!$B:$B, Keys!$R6, NP2023_pop!$C:$C, Keys!$V$6, NP2023_pop!$D:$D, 2024), 0))+IF(Keys!$W$6="", 0, IFERROR(SUMIFS(NP2023_pop!$E:$E, NP2023_pop!$A:$A, Keys!$Q6, NP2023_pop!$B:$B, Keys!$R6, NP2023_pop!$C:$C, Keys!$W$6, NP2023_pop!$D:$D, 2024), 0))+IF(Keys!$X$6="", 0, IFERROR(SUMIFS(NP2023_pop!$E:$E, NP2023_pop!$A:$A, Keys!$Q6, NP2023_pop!$B:$B, Keys!$R6, NP2023_pop!$C:$C, Keys!$X$6, NP2023_pop!$D:$D, 2024), 0)) -> 21726868 | E8: =SUMIFS(NP2023_pop!$E:$E, NP2023_pop!$A:$A, 0, NP2023_pop!$B:$B, 0, NP2023_pop!$C:$C, 0, NP2023_pop!$D:$D, 2024) -> 336482168 | F8: =IFERROR((B8/C8)/(D8/E8), 0) -> 1.7226036
A9: other race | B9: =IF(Keys!$K$7="", 0, IFERROR(SUMIFS(SCE_2024_state_pop!$F:$F, SCE_2024_state_pop!$B:$B, About!$B$1, SCE_2024_state_pop!$C:$C, Keys!$I7, SCE_2024_state_pop!$D:$D, Keys!$J7, SCE_2024_state_pop!$E:$E, Keys!$K$7), 0))+IF(Keys!$L$7="", 0, IFERROR(SUMIFS(SCE_2024_state_pop!$F:$F, SCE_2024_state_pop!$B:$B, About!$B$1, SCE_2024_state_pop!$C:$C, Keys!$I7, SCE_2024_state_pop!$D:$D, Keys!$J7, SCE_2024_state_pop!$E:$E, Keys!$L$7), 0))+IF(Keys!$M$7="", 0, IFERROR(SUMIFS(SCE_2024_state_pop!$F:$F, SCE_2024_state_pop!$B:$B, About!$B$1, SCE_2024_state_pop!$C:$C, Keys!$I7, SCE_2024_state_pop!$D:$D, Keys!$J7, SCE_2024_state_pop!$E:$E, Keys!$M$7), 0))+IF(Keys!$N$7="", 0, IFERROR(SUMIFS(SCE_2024_state_pop!$F:$F, SCE_2024_state_pop!$B:$B, About!$B$1, SCE_2024_state_pop!$C:$C, Keys!$I7, SCE_2024_state_pop!$D:$D, Keys!$J7, SCE_2024_state_pop!$E:$E, Keys!$N$7), 0))+IF(Keys!$O$7="", 0, IFERROR(SUMIFS(SCE_2024_state_pop!$F:$F, SCE_2024_state_pop!$B:$B, About!$B$1, SCE_2024_state_pop!$C:$C, Keys!$I7, SCE_2024_state_pop!$D:$D, Keys!$J7, SCE_2024_state_pop!$E:$E, Keys!$O$7), 0))+IF(Keys!$P$7="", 0, IFERROR(SUMIFS(SCE_2024_state_pop!$F:$F, SCE_2024_state_pop!$B:$B, About!$B$1, SCE_2024_state_pop!$C:$C, Keys!$I7, SCE_2024_state_pop!$D:$D, Keys!$J7, SCE_2024_state_pop!$E:$E, Keys!$P$7), 0)) -> 349413 | C9: =SUMIFS(SCE_2024_state_pop!$F:$F, SCE_2024_state_pop!$B:$B, About!$B$1, SCE_2024_state_pop!$C:$C, 0, SCE_2024_state_pop!$D:$D, 0, SCE_2024_state_pop!$E:$E, 1)+SUMIFS(SCE_2024_state_pop!$F:$F, SCE_2024_state_pop!$B:$B, About!$B$1, SCE_2024_state_pop!$C:$C, 0, SCE_2024_state_pop!$D:$D, 0, SCE_2024_state_pop!$E:$E, 2)+SUMIFS(SCE_2024_state_pop!$F:$F, SCE_2024_state_pop!$B:$B, About!$B$1, SCE_2024_state_pop!$C:$C, 0, SCE_2024_state_pop!$D:$D, 0, SCE_2024_state_pop!$E:$E, 3)+SUMIFS(SCE_2024_state_pop!$F:$F, SCE_2024_state_pop!$B:$B, About!$B$1, SCE_2024_state_pop!$C:$C, 0, SCE_2024_state_pop!$D:$D, 0, SCE_2024_state_pop!$E:$E, 4)+SUMIFS(SCE_2024_state_pop!$F:$F, SCE_2024_state_pop!$B:$B, About!$B$1, SCE_2024_state_pop!$C:$C, 0, SCE_2024_state_pop!$D:$D, 0, SCE_2024_state_pop!$E:$E, 5)+SUMIFS(SCE_2024_state_pop!$F:$F, SCE_2024_state_pop!$B:$B, About!$B$1, SCE_2024_state_pop!$C:$C, 0, SCE_2024_state_pop!$D:$D, 0, SCE_2024_state_pop!$E:$E, 6) -> 9500851 | D9: =IF(Keys!$S$7="", 0, IFERROR(SUMIFS(NP2023_pop!$E:$E, NP2023_pop!$A:$A, Keys!$Q7, NP2023_pop!$B:$B, Keys!$R7, NP2023_pop!$C:$C, Keys!$S$7, NP2023_pop!$D:$D, 2024), 0))+IF(Keys!$T$7="", 0, IFERROR(SUMIFS(NP2023_pop!$E:$E, NP2023_pop!$A:$A, Keys!$Q7, NP2023_pop!$B:$B, Keys!$R7, NP2023_pop!$C:$C, Keys!$T$7, NP2023_pop!$D:$D, 2024), 0))+IF(Keys!$U$7="", 0, IFERROR(SUMIFS(NP2023_pop!$E:$E, NP2023_pop!$A:$A, Keys!$Q7, NP2023_pop!$B:$B, Keys!$R7, NP2023_pop!$C:$C, Keys!$U$7, NP2023_pop!$D:$D, 2024), 0))+IF(Keys!$V$7="", 0, IFERROR(SUMIFS(NP2023_pop!$E:$E, NP2023_pop!$A:$A, Keys!$Q7, NP2023_pop!$B:$B, Keys!$R7, NP2023_pop!$C:$C, Keys!$V$7, NP2023_pop!$D:$D, 2024), 0))+IF(Keys!$W$7="", 0, IFERROR(SUMIFS(NP2023_pop!$E:$E, NP2023_pop!$A:$A, Keys!$Q7, NP2023_pop!$B:$B, Keys!$R7, NP2023_pop!$C:$C, Keys!$W$7, NP2023_pop!$D:$D, 2024), 0))+IF(Keys!$X$7="", 0, IFERROR(SUMIFS(NP2023_pop!$E:$E, NP2023_pop!$A:$A, Keys!$Q7, NP2023_pop!$B:$B, Keys!$R7, NP2023_pop!$C:$C, Keys!$X$7, NP2023_pop!$D:$D, 2024), 0)) -> 15930993 | E9: =SUMIFS(NP2023_pop!$E:$E, NP2023_pop!$A:$A, 0, NP2023_pop!$B:$B, 0, NP2023_pop!$C:$C, 0, NP2023_pop!$D:$D, 2024) -> 336482168 | F9: =IFERROR((B9/C9)/(D9/E9), 0) -> 0.77677593
A10: hispanic | B10: =IF(Keys!$K$8="", 0, IFERROR(SUMIFS(SCE_2024_state_pop!$F:$F, SCE_2024_state_pop!$B:$B, About!$B$1, SCE_2024_state_pop!$C:$C, Keys!$I8, SCE_2024_state_pop!$D:$D, Keys!$J8, SCE_2024_state_pop!$E:$E, Keys!$K$8), 0))+IF(Keys!$L$8="", 0, IFERROR(SUMIFS(SCE_2024_state_pop!$F:$F, SCE_2024_state_pop!$B:$B, About!$B$1, SCE_2024_state_pop!$C:$C, Keys!$I8, SCE_2024_state_pop!$D:$D, Keys!$J8, SCE_2024_state_pop!$E:$E, Keys!$L$8), 0))+IF(Keys!$M$8="", 0, IFERROR(SUMIFS(SCE_2024_state_pop!$F:$F, SCE_2024_state_pop!$B:$B, About!$B$1, SCE_2024_state_pop!$C:$C, Keys!$I8, SCE_2024_state_pop!$D:$D, Keys!$J8, SCE_2024_state_pop!$E:$E, Keys!$M$8), 0))+IF(Keys!$N$8="", 0, IFERROR(SUMIFS(SCE_2024_state_pop!$F:$F, SCE_2024_state_pop!$B:$B, About!$B$1, SCE_2024_state_pop!$C:$C, Keys!$I8, SCE_2024_state_pop!$D:$D, Keys!$J8, SCE_2024_state_pop!$E:$E, Keys!$N$8), 0))+IF(Keys!$O$8="", 0, IFERROR(SUMIFS(SCE_2024_state_pop!$F:$F, SCE_2024_state_pop!$B:$B, About!$B$1, SCE_2024_state_pop!$C:$C, Keys!$I8, SCE_2024_state_pop!$D:$D, Keys!$J8, SCE_2024_state_pop!$E:$E, Keys!$O$8), 0))+IF(Keys!$P$8="", 0, IFERROR(SUMIFS(SCE_2024_state_pop!$F:$F, SCE_2024_state_pop!$B:$B, About!$B$1, SCE_2024_state_pop!$C:$C, Keys!$I8, SCE_2024_state_pop!$D:$D, Keys!$J8, SCE_2024_state_pop!$E:$E, Keys!$P$8), 0)) -> 2229461 | C10: =SUMIFS(SCE_2024_state_pop!$F:$F, SCE_2024_state_pop!$B:$B, About!$B$1, SCE_2024_state_pop!$C:$C, 0, SCE_2024_state_pop!$D:$D, 0, SCE_2024_state_pop!$E:$E, 1)+SUMIFS(SCE_2024_state_pop!$F:$F, SCE_2024_state_pop!$B:$B, About!$B$1, SCE_2024_state_pop!$C:$C, 0, SCE_2024_state_pop!$D:$D, 0, SCE_2024_state_pop!$E:$E, 2)+SUMIFS(SCE_2024_state_pop!$F:$F, SCE_2024_state_pop!$B:$B, About!$B$1, SCE_2024_state_pop!$C:$C, 0, SCE_2024_state_pop!$D:$D, 0, SCE_2024_state_pop!$E:$E, 3)+SUMIFS(SCE_2024_state_pop!$F:$F, SCE_2024_state_pop!$B:$B, About!$B$1, SCE_2024_state_pop!$C:$C, 0, SCE_2024_state_pop!$D:$D, 0, SCE_2024_state_pop!$E:$E, 4)+SUMIFS(SCE_2024_state_pop!$F:$F, SCE_2024_state_pop!$B:$B, About!$B$1, SCE_2024_state_pop!$C:$C, 0, SCE_2024_state_pop!$D:$D, 0, SCE_2024_state_pop!$E:$E, 5)+SUMIFS(SCE_2024_state_pop!$F:$F, SCE_2024_state_pop!$B:$B, About!$B$1, SCE_2024_state_pop!$C:$C, 0, SCE_2024_state_pop!$D:$D, 0, SCE_2024_state_pop!$E:$E, 6) -> 9500851 | D10: =IF(Keys!$S$8="", 0, IFERROR(SUMIFS(NP2023_pop!$E:$E, NP2023_pop!$A:$A, Keys!$Q8, NP2023_pop!$B:$B, Keys!$R8, NP2023_pop!$C:$C, Keys!$S$8, NP2023_pop!$D:$D, 2024), 0))+IF(Keys!$T$8="", 0, IFERROR(SUMIFS(NP2023_pop!$E:$E, NP2023_pop!$A:$A, Keys!$Q8, NP2023_pop!$B:$B, Keys!$R8, NP2023_pop!$C:$C, Keys!$T$8, NP2023_pop!$D:$D, 2024), 0))+IF(Keys!$U$8="", 0, IFERROR(SUMIFS(NP2023_pop!$E:$E, NP2023_pop!$A:$A, Keys!$Q8, NP2023_pop!$B:$B, Keys!$R8, NP2023_pop!$C:$C, Keys!$U$8, NP2023_pop!$D:$D, 2024), 0))+IF(Keys!$V$8="", 0, IFERROR(SUMIFS(NP2023_pop!$E:$E, NP2023_pop!$A:$A, Keys!$Q8, NP2023_pop!$B:$B, Keys!$R8, NP2023_pop!$C:$C, Keys!$V$8, NP2023_pop!$D:$D, 2024), 0))+IF(Keys!$W$8="", 0, IFERROR(SUMIFS(NP2023_pop!$E:$E, NP2023_pop!$A:$A, Keys!$Q8, NP2023_pop!$B:$B, Keys!$R8, NP2023_pop!$C:$C, Keys!$W$8, NP2023_pop!$D:$D, 2024), 0))+IF(Keys!$X$8="", 0, IFERROR(SUMIFS(NP2023_pop!$E:$E, NP2023_pop!$A:$A, Keys!$Q8, NP2023_pop!$B:$B, Keys!$R8, NP2023_pop!$C:$C, Keys!$X$8, NP2023_pop!$D:$D, 2024), 0)) -> 65661023 | E10: =SUMIFS(NP2023_pop!$E:$E, NP2023_pop!$A:$A, 0, NP2023_pop!$B:$B, 0, NP2023_pop!$C:$C, 0, NP2023_pop!$D:$D, 2024) -> 336482168 | F10: =IFERROR((B10/C10)/(D10/E10), 0) -> 1.2025185
A11: nonhispanic | B11: =IF(Keys!$K$9="", 0, IFERROR(SUMIFS(SCE_2024_state_pop!$F:$F, SCE_2024_state_pop!$B:$B, About!$B$1, SCE_2024_state_pop!$C:$C, Keys!$I9, SCE_2024_state_pop!$D:$D, Keys!$J9, SCE_2024_state_pop!$E:$E, Keys!$K$9), 0))+IF(Keys!$L$9="", 0, IFERROR(SUMIFS(SCE_2024_state_pop!$F:$F, SCE_2024_state_pop!$B:$B, About!$B$1, SCE_2024_state_pop!$C:$C, Keys!$I9, SCE_2024_state_pop!$D:$D, Keys!$J9, SCE_2024_state_pop!$E:$E, Keys!$L$9), 0))+IF(Keys!$M$9="", 0, IFERROR(SUMIFS(SCE_2024_state_pop!$F:$F, SCE_2024_state_pop!$B:$B, About!$B$1, SCE_2024_state_pop!$C:$C, Keys!$I9, SCE_2024_state_pop!$D:$D, Keys!$J9, SCE_2024_state_pop!$E:$E, Keys!$M$9), 0))+IF(Keys!$N$9="", 0, IFERROR(SUMIFS(SCE_2024_state_pop!$F:$F, SCE_2024_state_pop!$B:$B, About!$B$1, SCE_2024_state_pop!$C:$C, Keys!$I9, SCE_2024_state_pop!$D:$D, Keys!$J9, SCE_2024_state_pop!$E:$E, Keys!$N$9), 0))+IF(Keys!$O$9="", 0, IFERROR(SUMIFS(SCE_2024_state_pop!$F:$F, SCE_2024_state_pop!$B:$B, About!$B$1, SCE_2024_state_pop!$C:$C, Keys!$I9, SCE_2024_state_pop!$D:$D, Keys!$J9, SCE_2024_state_pop!$E:$E, Keys!$O$9), 0))+IF(Keys!$P$9="", 0, IFERROR(SUMIFS(SCE_2024_state_pop!$F:$F, SCE_2024_state_pop!$B:$B, About!$B$1, SCE_2024_state_pop!$C:$C, Keys!$I9, SCE_2024_state_pop!$D:$D, Keys!$J9, SCE_2024_state_pop!$E:$E, Keys!$P$9), 0)) -> 7271390 | C11: =SUMIFS(SCE_2024_state_pop!$F:$F, SCE_2024_state_pop!$B:$B, About!$B$1, SCE_2024_state_pop!$C:$C, 0, SCE_2024_state_pop!$D:$D, 0, SCE_2024_state_pop!$E:$E, 1)+SUMIFS(SCE_2024_state_pop!$F:$F, SCE_2024_state_pop!$B:$B, About!$B$1, SCE_2024_state_pop!$C:$C, 0, SCE_2024_state_pop!$D:$D, 0, SCE_2024_state_pop!$E:$E, 2)+SUMIFS(SCE_2024_state_pop!$F:$F, SCE_2024_state_pop!$B:$B, About!$B$1, SCE_2024_state_pop!$C:$C, 0, SCE_2024_state_pop!$D:$D, 0, SCE_2024_state_pop!$E:$E, 3)+SUMIFS(SCE_2024_state_pop!$F:$F, SCE_2024_state_pop!$B:$B, About!$B$1, SCE_2024_state_pop!$C:$C, 0, SCE_2024_state_pop!$D:$D, 0, SCE_2024_state_pop!$E:$E, 4)+SUMIFS(SCE_2024_state_pop!$F:$F, SCE_2024_state_pop!$B:$B, About!$B$1, SCE_2024_state_pop!$C:$C, 0, SCE_2024_state_pop!$D:$D, 0, SCE_2024_state_pop!$E:$E, 5)+SUMIFS(SCE_2024_state_pop!$F:$F, SCE_2024_state_pop!$B:$B, About!$B$1, SCE_2024_state_pop!$C:$C, 0, SCE_2024_state_pop!$D:$D, 0, SCE_2024_state_pop!$E:$E, 6) -> 9500851 | D11: =IF(Keys!$S$9="", 0, IFERROR(SUMIFS(NP2023_pop!$E:$E, NP2023_pop!$A:$A, Keys!$Q9, NP2023_pop!$B:$B, Keys!$R9, NP2023_pop!$C:$C, Keys!$S$9, NP2023_pop!$D:$D, 2024), 0))+IF(Keys!$T$9="", 0, IFERROR(SUMIFS(NP2023_pop!$E:$E, NP2023_pop!$A:$A, Keys!$Q9, NP2023_pop!$B:$B, Keys!$R9, NP2023_pop!$C:$C, Keys!$T$9, NP2023_pop!$D:$D, 2024), 0))+IF(Keys!$U$9="", 0, IFERROR(SUMIFS(NP2023_pop!$E:$E, NP2023_pop!$A:$A, Keys!$Q9, NP2023_pop!$B:$B, Keys!$R9, NP2023_pop!$C:$C, Keys!$U$9, NP2023_pop!$D:$D, 2024), 0))+IF(Keys!$V$9="", 0, IFERROR(SUMIFS(NP2023_pop!$E:$E, NP2023_pop!$A:$A, Keys!$Q9, NP2023_pop!$B:$B, Keys!$R9, NP2023_pop!$C:$C, Keys!$V$9, NP2023_pop!$D:$D, 2024), 0))+IF(Keys!$W$9="", 0, IFERROR(SUMIFS(NP2023_pop!$E:$E, NP2023_pop!$A:$A, Keys!$Q9, NP2023_pop!$B:$B, Keys!$R9, NP2023_pop!$C:$C, Keys!$W$9, NP2023_pop!$D:$D, 2024), 0))+IF(Keys!$X$9="", 0, IFERROR(SUMIFS(NP2023_pop!$E:$E, NP2023_pop!$A:$A, Keys!$Q9, NP2023_pop!$B:$B, Keys!$R9, NP2023_pop!$C:$C, Keys!$X$9, NP2023_pop!$D:$D, 2024), 0)) -> 270821145 | E11: =SUMIFS(NP2023_pop!$E:$E, NP2023_pop!$A:$A, 0, NP2023_pop!$B:$B, 0, NP2023_pop!$C:$C, 0, NP2023_pop!$D:$D, 2024) -> 336482168 | F11: =IFERROR((B11/C11)/(D11/E11), 0) -> 0.95089905
A12: Total population trajectory (state + US, by year)
A13: state_total_pop | B13: =INDEX(Census_pop_2020_2025!G:G, MATCH("."&About!$B$1, Census_pop_2020_2025!A:A, 0)) -> 9506354 | C13: =INDEX(Census_pop_2020_2025!H:H, MATCH("."&About!$B$1, Census_pop_2020_2025!A:A, 0)) -> 9548215 | D13: =INDEX(Census_pop_2020_2025!H:H, MATCH("."&About!$B$1, Census_pop_2020_2025!A:A, 0))+0.2*(INDEX(Cooper_pop_2030_2050!D:D, MATCH(About!$B$1, Cooper_pop_2030_2050!B:B, 0))-INDEX(Census_pop_2020_2025!H:H, MATCH("."&About!$B$1, Census_pop_2020_2025!A:A, 0))) -> 9573746.4 | E13: =INDEX(Census_pop_2020_2025!H:H, MATCH("."&About!$B$1, Census_pop_2020_2025!A:A, 0))+0.4*(INDEX(Cooper_pop_2030_2050!D:D, MATCH(About!$B$1, Cooper_pop_2030_2050!B:B, 0))-INDEX(Census_pop_2020_2025!H:H, MATCH("."&About!$B$1, Census_pop_2020_2025!A:A, 0))) -> 9599277.9 | F13: =INDEX(Census_pop_2020_2025!H:H, MATCH("."&About!$B$1, Census_pop_2020_2025!A:A, 0))+0.6*(INDEX(Cooper_pop_2030_2050!D:D, MATCH(About!$B$1, Cooper_pop_2030_2050!B:B, 0))-INDEX(Census_pop_2020_2025!H:H, MATCH("."&About!$B$1, Census_pop_2020_2025!A:A, 0))) -> 9624809.3 | G13: =INDEX(Census_pop_2020_2025!H:H, MATCH("."&About!$B$1, Census_pop_2020_2025!A:A, 0))+0.8*(INDEX(Cooper_pop_2030_2050!D:D, MATCH(About!$B$1, Cooper_pop_2030_2050!B:B, 0))-INDEX(Census_pop_2020_2025!H:H, MATCH("."&About!$B$1, Census_pop_2020_2025!A:A, 0))) -> 9650340.8 | H13: =INDEX(Cooper_pop_2030_2050!D:D, MATCH(About!$B$1, Cooper_pop_2030_2050!B:B, 0)) -> 9675872.2 | I13: =INDEX(Cooper_pop_2030_2050!D:D, MATCH(About!$B$1, Cooper_pop_2030_2050!B:B, 0))+0.1*(INDEX(Cooper_pop_2030_2050!E:E, MATCH(About!$B$1, Cooper_pop_2030_2050!B:B, 0))-INDEX(Cooper_pop_2030_2050!D:D, MATCH(About!$B$1, Cooper_pop_2030_2050!B:B, 0))) -> 9691169.5 | J13: =INDEX(Cooper_pop_2030_2050!D:D, MATCH(About!$B$1, Cooper_pop_2030_2050!B:B, 0))+0.2*(INDEX(Cooper_pop_2030_2050!E:E, MATCH(About!$B$1, Cooper_pop_2030_2050!B:B, 0))-INDEX(Cooper_pop_2030_2050!D:D, MATCH(About!$B$1, Cooper_pop_2030_2050!B:B, 0))) -> 9706466.8 | K13: =INDEX(Cooper_pop_2030_2050!D:D, MATCH(About!$B$1, Cooper_pop_2030_2050!B:B, 0))+0.3*(INDEX(Cooper_pop_2030_2050!E:E, MATCH(About!$B$1, Cooper_pop_2030_2050!B:B, 0))-INDEX(Cooper_pop_2030_2050!D:D, MATCH(About!$B$1, Cooper_pop_2030_2050!B:B, 0))) -> 9721764 | L13: =INDEX(Cooper_pop_2030_2050!D:D, MATCH(About!$B$1, Cooper_pop_2030_2050!B:B, 0))+0.4*(INDEX(Cooper_pop_2030_2050!E:E, MATCH(About!$B$1, Cooper_pop_2030_2050!B:B, 0))-INDEX(Cooper_pop_2030_2050!D:D, MATCH(About!$B$1, Cooper_pop_2030_2050!B:B, 0))) -> 9737061.3 | M13: =INDEX(Cooper_pop_2030_2050!D:D, MATCH(About!$B$1, Cooper_pop_2030_2050!B:B, 0))+0.5*(INDEX(Cooper_pop_2030_2050!E:E, MATCH(About!$B$1, Cooper_pop_2030_2050!B:B, 0))-INDEX(Cooper_pop_2030_2050!D:D, MATCH(About!$B$1, Cooper_pop_2030_2050!B:B, 0))) -> 9752358.6 | N13: =INDEX(Cooper_pop_2030_2050!D:D, MATCH(About!$B$1, Cooper_pop_2030_2050!B:B, 0))+0.6*(INDEX(Cooper_pop_2030_2050!E:E, MATCH(About!$B$1, Cooper_pop_2030_2050!B:B, 0))-INDEX(Cooper_pop_2030_2050!D:D, MATCH(About!$B$1, Cooper_pop_2030_2050!B:B, 0))) -> 9767655.9 | O13: =INDEX(Cooper_pop_2030_2050!D:D, MATCH(About!$B$1, Cooper_pop_2030_2050!B:B, 0))+0.7*(INDEX(Cooper_pop_2030_2050!E:E, MATCH(About!$B$1, Cooper_pop_2030_2050!B:B, 0))-INDEX(Cooper_pop_2030_2050!D:D, MATCH(About!$B$1, Cooper_pop_2030_2050!B:B, 0))) -> 9782953.2 | P13: =INDEX(Cooper_pop_2030_2050!D:D, MATCH(About!$B$1, Cooper_pop_2030_2050!B:B, 0))+0.8*(INDEX(Cooper_pop_2030_2050!E:E, MATCH(About!$B$1, Cooper_pop_2030_2050!B:B, 0))-INDEX(Cooper_pop_2030_2050!D:D, MATCH(About!$B$1, Cooper_pop_2030_2050!B:B, 0))) -> 9798250.5 | Q13: =INDEX(Cooper_pop_2030_2050!D:D, MATCH(About!$B$1, Cooper_pop_2030_2050!B:B, 0))+0.9*(INDEX(Cooper_pop_2030_2050!E:E, MATCH(About!$B$1, Cooper_pop_2030_2050!B:B, 0))-INDEX(Cooper_pop_2030_2050!D:D, MATCH(About!$B$1, Cooper_pop_2030_2050!B:B, 0))) -> 9813547.7 | R13: =INDEX(Cooper_pop_2030_2050!E:E, MATCH(About!$B$1, Cooper_pop_2030_2050!B:B, 0)) -> 9828845 | S13: =INDEX(Cooper_pop_2030_2050!E:E, MATCH(About!$B$1, Cooper_pop_2030_2050!B:B, 0))+0.1*(INDEX(Cooper_pop_2030_2050!F:F, MATCH(About!$B$1, Cooper_pop_2030_2050!B:B, 0))-INDEX(Cooper_pop_2030_2050!E:E, MATCH(About!$B$1, Cooper_pop_2030_2050!B:B, 0))) -> 9832684.7 | T13: =INDEX(Cooper_pop_2030_2050!E:E, MATCH(About!$B$1, Cooper_pop_2030_2050!B:B, 0))+0.2*(INDEX(Cooper_pop_2030_2050!F:F, MATCH(About!$B$1, Cooper_pop_2030_2050!B:B, 0))-INDEX(Cooper_pop_2030_2050!E:E, MATCH(About!$B$1, Cooper_pop_2030_2050!B:B, 0))) -> 9836524.4 | U13: =INDEX(Cooper_pop_2030_2050!E:E, MATCH(About!$B$1, Cooper_pop_2030_2050!B:B, 0))+0.3*(INDEX(Cooper_pop_2030_2050!F:F, MATCH(About!$B$1, Cooper_pop_2030_2050!B:B, 0))-INDEX(Cooper_pop_2030_2050!E:E, MATCH(About!$B$1, Cooper_pop_2030_2050!B:B, 0))) -> 9840364.1 | V13: =INDEX(Cooper_pop_2030_2050!E:E, MATCH(About!$B$1, Cooper_pop_2030_2050!B:B, 0))+0.4*(INDEX(Cooper_pop_2030_2050!F:F, MATCH(About!$B$1, Cooper_pop_2030_2050!B:B, 0))-INDEX(Cooper_pop_2030_2050!E:E, MATCH(About!$B$1, Cooper_pop_2030_2050!B:B, 0))) -> 9844203.8 | W13: =INDEX(Cooper_pop_2030_2050!E:E, MATCH(About!$B$1, Cooper_pop_2030_2050!B:B, 0))+0.5*(INDEX(Cooper_pop_2030_2050!F:F, MATCH(About!$B$1, Cooper_pop_2030_2050!B:B, 0))-INDEX(Cooper_pop_2030_2050!E:E, MATCH(About!$B$1, Cooper_pop_2030_2050!B:B, 0))) -> 9848043.5 | X13: =INDEX(Cooper_pop_2030_2050!E:E, MATCH(About!$B$1, Cooper_pop_2030_2050!B:B, 0))+0.6*(INDEX(Cooper_pop_2030_2050!F:F, MATCH(About!$B$1, Cooper_pop_2030_2050!B:B, 0))-INDEX(Cooper_pop_2030_2050!E:E, MATCH(About!$B$1, Cooper_pop_2030_2050!B:B, 0))) -> 9851883.2 | Y13: =INDEX(Cooper_pop_2030_2050!E:E, MATCH(About!$B$1, Cooper_pop_2030_2050!B:B, 0))+0.7*(INDEX(Cooper_pop_2030_2050!F:F, MATCH(About!$B$1, Cooper_pop_2030_2050!B:B, 0))-INDEX(Cooper_pop_2030_2050!E:E, MATCH(About!$B$1, Cooper_pop_2030_2050!B:B, 0))) -> 9855722.9 | Z13: =INDEX(Cooper_pop_2030_2050!E:E, MATCH(About!$B$1, Cooper_pop_2030_2050!B:B, 0))+0.8*(INDEX(Cooper_pop_2030_2050!F:F, MATCH(About!$B$1, Cooper_pop_2030_2050!B:B, 0))-INDEX(Cooper_pop_2030_2050!E:E, MATCH(About!$B$1, Cooper_pop_2030_2050!B:B, 0))) -> 9859562.7 | AA13: =INDEX(Cooper_pop_2030_2050!E:E, MATCH(About!$B$1, Cooper_pop_2030_2050!B:B, 0))+0.9*(INDEX(Cooper_pop_2030_2050!F:F, MATCH(About!$B$1, Cooper_pop_2030_2050!B:B, 0))-INDEX(Cooper_pop_2030_2050!E:E, MATCH(About!$B$1, Cooper_pop_2030_2050!B:B, 0))) -> 9863402.4 | AB13: =INDEX(Cooper_pop_2030_2050!F:F, MATCH(About!$B$1, Cooper_pop_2030_2050!B:B, 0)) -> 9867242.1
A14: US_total_pop | B14: =SUMIFS(NP2023_pop!$E:$E, NP2023_pop!$A:$A, 0, NP2023_pop!$B:$B, 0, NP2023_pop!$C:$C, 0, NP2023_pop!$D:$D, 2024) -> 336482168 | C14: =SUMIFS(NP2023_pop!$E:$E, NP2023_pop!$A:$A, 0, NP2023_pop!$B:$B, 0, NP2023_pop!$C:$C, 0, NP2023_pop!$D:$D, 2025) -> 338016259 | D14: =SUMIFS(NP2023_pop!$E:$E, NP2023_pop!$A:$A, 0, NP2023_pop!$B:$B, 0, NP2023_pop!$C:$C, 0, NP2023_pop!$D:$D, 2026) -> 339513045 | E14: =SUMIFS(NP2023_pop!$E:$E, NP2023_pop!$A:$A, 0, NP2023_pop!$B:$B, 0, NP2023_pop!$C:$C, 0, NP2023_pop!$D:$D, 2027) -> 340970496 | F14: =SUMIFS(NP2023_pop!$E:$E, NP2023_pop!$A:$A, 0, NP2023_pop!$B:$B, 0, NP2023_pop!$C:$C, 0, NP2023_pop!$D:$D, 2028) -> 342384777 | G14: =SUMIFS(NP2023_pop!$E:$E, NP2023_pop!$A:$A, 0, NP2023_pop!$B:$B, 0, NP2023_pop!$C:$C, 0, NP2023_pop!$D:$D, 2029) -> 343753791 | H14: =SUMIFS(NP2023_pop!$E:$E, NP2023_pop!$A:$A, 0, NP2023_pop!$B:$B, 0, NP2023_pop!$C:$C, 0, NP2023_pop!$D:$D, 2030) -> 345073565 | I14: =SUMIFS(NP2023_pop!$E:$E, NP2023_pop!$A:$A, 0, NP2023_pop!$B:$B, 0, NP2023_pop!$C:$C, 0, NP2023_pop!$D:$D, 2031) -> 346339264 | J14: =SUMIFS(NP2023_pop!$E:$E, NP2023_pop!$A:$A, 0, NP2023_pop!$B:$B, 0, NP2023_pop!$C:$C, 0, NP2023_pop!$D:$D, 2032) -> 347545098 | K14: =SUMIFS(NP2023_pop!$E:$E, NP2023_pop!$A:$A, 0, NP2023_pop!$B:$B, 0, NP2023_pop!$C:$C, 0, NP2023_pop!$D:$D, 2033) -> 348701812 | L14: =SUMIFS(NP2023_pop!$E:$E, NP2023_pop!$A:$A, 0, NP2023_pop!$B:$B, 0, NP2023_pop!$C:$C, 0, NP2023_pop!$D:$D, 2034) -> 349807647 | M14: =SUMIFS(NP2023_pop!$E:$E, NP2023_pop!$A:$A, 0, NP2023_pop!$B:$B, 0, NP2023_pop!$C:$C, 0, NP2023_pop!$D:$D, 2035) -> 350861084 | N14: =SUMIFS(NP2023_pop!$E:$E, NP2023_pop!$A:$A, 0, NP2023_pop!$B:$B, 0, NP2023_pop!$C:$C, 0, NP2023_pop!$D:$D, 2036) -> 351860944 | O14: =SUMIFS(NP2023_pop!$E:$E, NP2023_pop!$A:$A, 0, NP2023_pop!$B:$B, 0, NP2023_pop!$C:$C, 0, NP2023_pop!$D:$D, 2037) -> 352806047 | P14: =SUMIFS(NP2023_pop!$E:$E, NP2023_pop!$A:$A, 0, NP2023_pop!$B:$B, 0, NP2023_pop!$C:$C, 0, NP2023_pop!$D:$D, 2038) -> 353695674 | Q14: =SUMIFS(NP2023_pop!$E:$E, NP2023_pop!$A:$A, 0, NP2023_pop!$B:$B, 0, NP2023_pop!$C:$C, 0, NP2023_pop!$D:$D, 2039) -> 354529853 | R14: =SUMIFS(NP2023_pop!$E:$E, NP2023_pop!$A:$A, 0, NP2023_pop!$B:$B, 0, NP2023_pop!$C:$C, 0, NP2023_pop!$D:$D, 2040) -> 355309062 | S14: =SUMIFS(NP2023_pop!$E:$E, NP2023_pop!$A:$A, 0, NP2023_pop!$B:$B, 0, NP2023_pop!$C:$C, 0, NP2023_pop!$D:$D, 2041) -> 356033543 | T14: =SUMIFS(NP2023_pop!$E:$E, NP2023_pop!$A:$A, 0, NP2023_pop!$B:$B, 0, NP2023_pop!$C:$C, 0, NP2023_pop!$D:$D, 2042) -> 356705435 | U14: =SUMIFS(NP2023_pop!$E:$E, NP2023_pop!$A:$A, 0, NP2023_pop!$B:$B, 0, NP2023_pop!$C:$C, 0, NP2023_pop!$D:$D, 2043) -> 357327409 | V14: =SUMIFS(NP2023_pop!$E:$E, NP2023_pop!$A:$A, 0, NP2023_pop!$B:$B, 0, NP2023_pop!$C:$C, 0, NP2023_pop!$D:$D, 2044) -> 357903394 | W14: =SUMIFS(NP2023_pop!$E:$E, NP2023_pop!$A:$A, 0, NP2023_pop!$B:$B, 0, NP2023_pop!$C:$C, 0, NP2023_pop!$D:$D, 2045) -> 358437973 | X14: =SUMIFS(NP2023_pop!$E:$E, NP2023_pop!$A:$A, 0, NP2023_pop!$B:$B, 0, NP2023_pop!$C:$C, 0, NP2023_pop!$D:$D, 2046) -> 358935938 | Y14: =SUMIFS(NP2023_pop!$E:$E, NP2023_pop!$A:$A, 0, NP2023_pop!$B:$B, 0, NP2023_pop!$C:$C, 0, NP2023_pop!$D:$D, 2047) -> 359400325 | Z14: =SUMIFS(NP2023_pop!$E:$E, NP2023_pop!$A:$A, 0, NP2023_pop!$B:$B, 0, NP2023_pop!$C:$C, 0, NP2023_pop!$D:$D, 2048) -> 359835763 | AA14: =SUMIFS(NP2023_pop!$E:$E, NP2023_pop!$A:$A, 0, NP2023_pop!$B:$B, 0, NP2023_pop!$C:$C, 0, NP2023_pop!$D:$D, 2049) -> 360246998 | AB14: =SUMIFS(NP2023_pop!$E:$E, NP2023_pop!$A:$A, 0, NP2023_pop!$B:$B, 0, NP2023_pop!$C:$C, 0, NP2023_pop!$D:$D, 2050) -> 360638734
A15: share = state/US | B15: =B13/B14 -> 0.028252178 | C15: =C13/C14 -> 0.028247798 | D15: =D13/D14 -> 0.028198464 | E15: =E13/E14 -> 0.028152811 | F15: =F13/F14 -> 0.02811109 | G15: =G13/G14 -> 0.028073409 | H15: =H13/H14 -> 0.028040027 | I15: =I13/I14 -> 0.027981723 | ... AB15: =AB13/AB14 -> 0.027360461
A17: US TOTAL deaths by trait by year (SUMIFS over NP2023_deaths col D)
