Workbook

Sheet About
A1: RZSPbS Required ZEV Sales Percentage by Subregion | B1: New Jersey | C1: 46274 | F1: Alabama | G1: AL
B2: =LOOKUP(B1,F1:G50,G1:G50) -> NJ | F2: Alaska | G2: AK
A3: Sources: | B3: State Passenger LDVs | F3: Arizona | G3: AZ
B4: California Air Resources Board | F4: Arkansas | G4: AR
B5: 2022 | F5: California | G5: CA
B6: Final Regulation Order, Section 1962.4, Title 13, California Code of Regulations | F6: Colorado | G6: CO
B7: https://ww2.arb.ca.gov/sites/default/files/barcu/regact/2022/accii/acciifro1962.4.pdf | F7: Connecticut | G7: CT
B8: Page 4 | F8: Delaware | G8: DE
F9: Florida | G9: FL
B10: State Freight LDVs and HDVs | F10: Georgia | G10: GA
B11: California Air Resources Board | F11: Hawaii | G11: HI
B12: 2022 | F12: Idaho | G12: ID
B13: Final Regulation Order: Advanced Clean Trucks Regulation | F13: Illinois | G13: IL
B14: https://ww2.arb.ca.gov/sites/default/files/barcu/regact/2019/act2019/fro2.pdf | F14: Indiana | G14: IN
B15: Page 5, Table A-1 | F15: Iowa | G15: IA
F16: Kansas | G16: KS
B17: Which States Follow ACC I Standards? | F17: Kentucky | G17: KY
B18: California Air Resources Board + state regs | F18: Louisiana | G18: LA
B19: 2019-2022 | F19: Maine | G19: ME
B20: 177 States | F20: Maryland | G20: MD
B21: https://ww2.arb.ca.gov/sites/default/files/2019-03/177-states.pdf | F21: Massachusetts | G21: MA
B22: https://ecology.wa.gov/Regulations-Permits/Laws-rules-rulemaking/Rulemaking/WAC-173-423-400 | F22: Michigan | G22: MI
B23: https://ndep.nv.gov/uploads/air-ccn-docs/clean_cars_nv_reg.pdf | F23: Minnesota | G23: MN
B24: https://cloud.env.nm.gov/air/resources/_translator.php/NoP4Wd1EyorPC~sl~BWz~sl~H2+PXdCQEKefUZ7Ou8Vgq~sl~x2ZYzqa1zexRjaNVbxGMCgU8AVirLkjjLdev8vysjOadSflGgbBfGQtLEpGCtN+kDVh1YPy2q5u9L4gGZ4Ls+vKK.pdf | F24: Mississippi | G24: MS
B25: https://lis.virginia.gov/cgi-bin/legp604.exe?212+ful+HB1965ER | F25: Missouri | G25: MO
F26: Montana | G26: MT
B27: Which States Follow ACC II and Advanced Clean Truck Standards? | F27: Nebraska | G27: NE
B28: Sierra Club | F28: Nevada | G28: NV
B29: 2023 | F29: New Hampshire | G29: NH
B30: Clean Vehicle Programs: State Tracker | F30: New Jersey | G30: NJ
B31: https://www.sierraclub.org/transportation/clean-vehicle-programs-state-tracker | F31: New Mexico | G31: NM
B32: Last Accessed January 9, 2024 | F32: New York | G32: NY
F33: North Carolina | G33: NC
B34: Transportation Data | F34: North Dakota | G34: ND
B35: Oak Ridge National Laboratory | F35: Ohio | G35: OH
B36: 2022 | F36: Oklahoma | G36: OK
B37: Transportation Energy Data Book: Edition 40 | F37: Oregon | G37: OR
B38: https://tedb.ornl.gov/data/ | F38: Pennsylvania | G38: PA
F39: Rhode Island | G39: RI
B40: Bus Registration Data | F40: South Carolina | G40: SC
...

Sheet EPS Vehicle Class Mapping
A1: The ZEV sales standards imposed by a region or subregion may have schedules that
A2: do not overlap with EPS classifications. In this sheet, the California Air Resource Board (CARB)
A3: Advanced Clean Cars I/II (ACC I/II) and Advanced Clean Trucks (ACT) schedules are mapped
A4: onto EPS vehicle classes using U.S. vehicle registration & sales data.
A6: EPS Vehicle Classes | C6: Description
A7: passenger LDVs | B7: Cars | C7: most light-duty road vehicles (such as cars and SUVs)
A8: passenger HDVs | B8: Buses | C8: buses (including school, transit, and intercity buses)
A9: passenger motorbikes | C9: registered motorcycles
A10: freight LDVs | B10: Class 2b-6 | C10: light commercial trucks
A11: freight HDVs | B11: Class 7-8 | C11: all other heavy road vehicles (mostly freight trucks)
A12: freight motorbikes | C12: registered motorcycles
A14: CARB Schedules
A15: Year | B15: 2020 | C15: 2021 | D15: 2022 | E15: 2023 | F15: 2024 | G15: 2025 | H15: 2026 | I15: 2027 | J15: 2028 | K15: 2029 | L15: 2030 | M15: 2031 | N15: 2032 | O15: 2033 | P15: 2034 | Q15: 2035 | R15: 2036 | S15: 2037 | T15: 2038 | U15: 2039 | V15: 2040 | W15: 2041 | X15: 2042 | Y15: 2043 | Z15: 2044 | AA15: 2045 | AB15: 2046 | AC15: 2047 | AD15: 2048 | AE15: 2049 | AF15: 2050
A16: ACC I passenger cars | B16: =(B15-2018)/(2025-2018)*(0.22-0.045)+0.045 -> 0.095 | C16: =(C15-2018)/(2025-2018)*(0.22-0.045)+0.045 -> 0.12 | D16: =(D15-2018)/(2025-2018)*(0.22-0.045)+0.045 -> 0.145 | E16: =(E15-2018)/(2025-2018)*(0.22-0.045)+0.045 -> 0.17 | F16: =(F15-2018)/(2025-2018)*(0.22-0.045)+0.045 -> 0.195 | G16: =(G15-2018)/(2025-2018)*(0.22-0.045)+0.045 -> 0.22 | H16: 0.22 | I16: 0.22 | J16: 0.22 | K16: 0.22 | L16: 0.22 | M16: 0.22 | N16: 0.22 | O16: 0.22 | P16: 0.22 | Q16: 0.22 | R16: =Q16 -> 0.22 | S16: =R16 -> 0.22 | T16: =S16 -> 0.22 | U16: =T16 -> 0.22 | V16: =U16 -> 0.22 | W16: =V16 -> 0.22 | X16: =W16 -> 0.22 | Y16: =X16 -> 0.22 | ... AF16: =AE16 -> 0.22
A17: ACC II passenger cars | B17: =B16 -> 0.095 | C17: =C16 -> 0.12 | D17: =D16 -> 0.145 | E17: =E16 -> 0.17 | F17: =F16 -> 0.195 | G17: =G16 -> 0.22 | H17: 0.35 | I17: 0.43 | J17: 0.51 | K17: 0.59 | L17: 0.68 | M17: 0.76 | N17: 0.82 | O17: 0.88 | P17: 0.94 | Q17: 1 | R17: =Q17 -> 1 | S17: =R17 -> 1 | T17: =S17 -> 1 | U17: =T17 -> 1 | V17: =U17 -> 1 | W17: =V17 -> 1 | X17: =W17 -> 1 | Y17: =X17 -> 1 | ... AF17: =AE17 -> 1
A18: ACT Class 2b-3 pickup trucks and vans | B18: 0 | C18: 0 | D18: 0 | E18: 0 | F18: 0.05 | G18: 0.07 | H18: 0.1 | I18: 0.15 | J18: 0.2 | K18: 0.25 | L18: 0.3 | M18: 0.35 | N18: 0.4 | O18: 0.45 | P18: 0.5 | Q18: 0.55 | R18: =Q18 -> 0.55 | S18: =R18 -> 0.55 | T18: =S18 -> 0.55 | U18: =T18 -> 0.55 | V18: =U18 -> 0.55 | W18: =V18 -> 0.55 | X18: =W18 -> 0.55 | Y18: =X18 -> 0.55 | ... AF18: =AE18 -> 0.55
A19: ACT Class 4-8 rigid (i.e., non-tractor) trucks | B19: 0 | C19: 0 | D19: 0 | E19: 0 | F19: 0.09 | G19: 0.11 | H19: 0.13 | I19: 0.2 | J19: 0.3 | K19: 0.4 | L19: 0.5 | M19: 0.55 | N19: 0.6 | O19: 0.65 | P19: 0.7 | Q19: 0.75 | R19: =Q19 -> 0.75 | S19: =R19 -> 0.75 | T19: =S19 -> 0.75 | U19: =T19 -> 0.75 | V19: =U19 -> 0.75 | W19: =V19 -> 0.75 | X19: =W19 -> 0.75 | Y19: =X19 -> 0.75 | ... AF19: =AE19 -> 0.75
A20: ACT Class 7-8 tractor trucks | B20: 0 | C20: 0 | D20: 0 | E20: 0 | F20: 0.05 | G20: 0.07 | H20: 0.1 | I20: 0.15 | J20: 0.2 | K20: 0.25 | L20: 0.3 | M20: 0.35 | N20: 0.4 | O20: 0.4 | P20: 0.4 | Q20: 0.4 | R20: =Q20 -> 0.4 | S20: =R20 -> 0.4 | T20: =S20 -> 0.4 | U20: =T20 -> 0.4 | V20: =U20 -> 0.4 | W20: =V20 -> 0.4 | X20: =W20 -> 0.4 | Y20: =X20 -> 0.4 | ... AF20: =AE20 -> 0.4
A22: Class 2b-3 VMT | C22: =SUM('AEO by Class'!B3:B4) -> 162858256786 | D22: =SUM('AEO by Class'!C3:C4) -> 171035865319 | E22: =SUM('AEO by Class'!D3:D4) -> 173544893263 | F22: =SUM('AEO by Class'!E3:E4) -> 175151360297 | G22: =SUM('AEO by Class'!F3:F4) -> 176642088958 | H22: =SUM('AEO by Class'!G3:G4) -> 179046425003 | I22: =SUM('AEO by Class'!H3:H4) -> 181640723246 | J22: =SUM('AEO by Class'!I3:I4) -> 184184673851 | ... AF22: =SUM('AEO by Class'!AE3:AE4) -> 253966556134
A23: Class 4-8 rigid truck VMT | C23: =SUM('AEO by Class'!B5:B8) -> 60343802126 | D23: =SUM('AEO by Class'!C5:C8) -> 61265916527 | E23: =SUM('AEO by Class'!D5:D8) -> 60770468811 | F23: =SUM('AEO by Class'!E5:E8) -> 60621853767 | G23: =SUM('AEO by Class'!F5:F8) -> 60956381365 | H23: =SUM('AEO by Class'!G5:G8) -> 61694583706 | I23: =SUM('AEO by Class'!H5:H8) -> 62460976106 | J23: =SUM('AEO by Class'!I5:I8) -> 63287516270 | ... AF23: =SUM('AEO by Class'!AE5:AE8) -> 86169767894
A24: Class 7-8 tractor truck VMT | C24: =SUM('AEO by Class'!B9:B10) -> 181451501319 | D24: =SUM('AEO by Class'!C9:C10) -> 185622287850 | E24: =SUM('AEO by Class'!D9:D10) -> 185197254875 | F24: =SUM('AEO by Class'!E9:E10) -> 185421480578 | G24: =SUM('AEO by Class'!F9:F10) -> 186898742848 | H24: =SUM('AEO by Class'!G9:G10) -> 189159842657 | I24: =SUM('AEO by Class'!H9:H10) -> 191006166106 | J24: =SUM('AEO by Class'!I9:I10) -> 192510372713 | ... AF24: =SUM('AEO by Class'!AE9:AE10) -> 203649410349
A26: Percent of Class 4-8 truck VMT in freight LDV EPS category | C26: =SUM('AEO by Class'!B5:B7)/SUM('AEO by Class'!B5:B8) -> 0.97399343 | D26: =SUM('AEO by Class'!C5:C7)/SUM('AEO by Class'!C5:C8) -> 0.97438178 | E26: =SUM('AEO by Class'!D5:D7)/SUM('AEO by Class'!D5:D8) -> 0.97470042 | F26: =SUM('AEO by Class'!E5:E7)/SUM('AEO by Class'!E5:E8) -> 0.97497706 | G26: =SUM('AEO by Class'!F5:F7)/SUM('AEO by Class'!F5:F8) -> 0.97520525 | H26: =SUM('AEO by Class'!G5:G7)/SUM('AEO by Class'!G5:G8) -> 0.97543856 | I26: =SUM('AEO by Class'!H5:H7)/SUM('AEO by Class'!H5:H8) -> 0.97570205 | J26: =SUM('AEO by Class'!I5:I7)/SUM('AEO by Class'!I5:I8) -> 0.97600379 | ... AF26: =SUM('AEO by Class'!AE5:AE7)/SUM('AEO by Class'!AE5:AE8) -> 0.98228881
A27: Percent of Class 4-8 truck VMT in freight HDV EPS category | C27: =1-C26 -> 0.02600657 | D27: =1-D26 -> 0.025618221 | E27: =1-E26 -> 0.025299582 | F27: =1-F26 -> 0.025022939 | G27: =1-G26 -> 0.024794745 | H27: =1-H26 -> 0.024561445 | I27: =1-I26 -> 0.024297953 | J27: =1-J26 -> 0.023996212 | ... AF27: =1-AF26 -> 0.01771119
A29: Class 2b-3 percent of freight LDV VMT | C29: =C22/SUM(C22,C23*C26) -> 0.73481142 | D29: =D22/SUM(D22,D23*D26) -> 0.74127418 | E29: =E22/SUM(E22,E23*E26) -> 0.74553855 | F29: =F22/SUM(F22,F23*F26) -> 0.74769121 | G29: =G22/SUM(G22,G23*G26) -> 0.74820738 | H29: =H22/SUM(H22,H23*H26) -> 0.74844143 | I29: =I22/SUM(I22,I23*I26) -> 0.74877446 | J29: =J22/SUM(J22,J23*J26) -> 0.74885965 | ... AF29: =AF22/SUM(AF22,AF23*AF26) -> 0.7500264
A30: Class 4-8 rigid truck percent of freight LDV VMT | C30: =1-C29 -> 0.26518858 | D30: =1-D29 -> 0.25872582 | E30: =1-E29 -> 0.25446145 | F30: =1-F29 -> 0.25230879 | G30: =1-G29 -> 0.25179262 | H30: =1-H29 -> 0.25155857 | I30: =1-I29 -> 0.25122554 | J30: =1-J29 -> 0.25114035 | ... AF30: =1-AF29 -> 0.2499736
A31: Class 4-8 rigid truck percent of freight HDV VMT | C31: =(C23*C27)/SUM(C23*C27,C24) -> 0.0085746266 | D31: =(D23*D27)/SUM(D23*D27,D24) -> 0.0083845752 | E31: =(E23*E27)/SUM(E23*E27,E24) -> 0.0082334311 | F31: =(F23*F27)/SUM(F23*F27,F24) -> 0.0081146347 | G31: =(G23*G27)/SUM(G23*G27,G24) -> 0.0080218503 | H31: =(H23*H27)/SUM(H23*H27,H24) -> 0.0079470666 | I31: =(I23*I27)/SUM(I23*I27,I24) -> 0.0078830439 | J31: =(J23*J27)/SUM(J23*J27,J24) -> 0.0078269763 | ... AF31: =(AF23*AF27)/SUM(AF23*AF27,AF24) -> 0.0074383567
A32: Class 7-8 tractor truck percent of freight HDV VMT | C32: =1-C31 -> 0.99142537 | D32: =1-D31 -> 0.99161542 | E32: =1-E31 -> 0.99176657 | F32: =1-F31 -> 0.99188537 | G32: =1-G31 -> 0.99197815 | H32: =1-H31 -> 0.99205293 | I32: =1-I31 -> 0.99211696 | J32: =1-J31 -> 0.99217302 | ... AF32: =1-AF31 -> 0.99256164
A35: U.S. DOT Federal Highway Administration, Highway Statistics Table MV-10 - 2020
A36: Bus Registrations
A37: TOTAL BUSES
A39: TOTAL | B39: TOTAL
A40: SCHOOL | B40: NON-SCHOOL | C40: GRAND
B41: AND FEDERAL | C41: TOTAL
A43: 441729.58 | B43: 420505.55 | C43: 967456.95
A45: EPS Schedules
A46: Year | B46: 2020 | C46: 2021 | D46: 2022 | E46: 2023 | F46: 2024 | G46: 2025 | H46: 2026 | I46: 2027 | J46: 2028 | K46: 2029 | L46: 2030 | M46: 2031 | N46: 2032 | O46: 2033 | P46: 2034 | Q46: 2035 | R46: 2036 | S46: 2037 | T46: 2038 | U46: 2039 | V46: 2040 | W46: 2041 | X46: 2042 | Y46: 2043 | Z46: 2044 | AA46: 2045 | AB46: 2046 | AC46: 2047 | AD46: 2048 | AE46: 2049 | AF46: 2050
A47: passenger LDVs ACC I | B47: =B16 -> 0.095 | C47: =C16 -> 0.12 | D47: =D16 -> 0.145 | E47: =E16 -> 0.17 | F47: =F16 -> 0.195 | G47: =G16 -> 0.22 | H47: =H16 -> 0.22 | I47: =I16 -> 0.22 | ... AF47: =AF16 -> 0.22
A48: passenger LDVs ACC II | B48: =B17 -> 0.095 | C48: =C17 -> 0.12 | D48: =D17 -> 0.145 | E48: =E17 -> 0.17 | F48: =F17 -> 0.195 | G48: =G17 -> 0.22 | H48: =H17 -> 0.35 | I48: =I17 -> 0.43 | ... AF48: =AF17 -> 1
A49: passenger HDVs | B49: 0 | C49: 0 | D49: 0 | E49: 0 | F49: =($A$43*0+$B$43*F19)/($C$43) -> 0.039118536 | G49: =($A$43*0+$B$43*G19)/($C$43) -> 0.047811544 | H49: =($A$43*0+$B$43*H19)/($C$43) -> 0.056504552 | I49: =($A$43*0+$B$43*I19)/($C$43) -> 0.086930079 | J49: =($A$43*0+$B$43*J19)/($C$43) -> 0.13039512 | K49: =($A$43*0+$B$43*K19)/($C$43) -> 0.17386016 | L49: =($A$43*0+$B$43*L19)/($C$43) -> 0.2173252 | M49: =($A$43*0+$B$43*M19)/($C$43) -> 0.23905772 | ... AF49: =($A$43*0+$B$43*AF19)/($C$43) -> 0.3259878
A50: passenger motorbikes | B50: 0 | C50: 0 | D50: 0 | E50: 0 | F50: 0 | G50: 0 | H50: 0 | I50: 0 | J50: 0 | K50: 0 | L50: 0 | M50: 0 | N50: 0 | O50: 0 | P50: 0 | Q50: 0 | R50: 0 | S50: 0 | T50: 0 | U50: 0 | V50: 0 | W50: 0 | X50: 0 | Y50: 0 | Z50: 0 | AA50: 0 | AB50: 0 | AC50: 0 | AD50: 0 | AE50: 0 | AF50: 0
...

Sheet CA Standards and Followers
B1: 2020 | C1: 2021 | D1: 2022 | E1: 2023 | F1: 2024 | G1: 2025 | H1: 2026 | I1: 2027 | J1: 2028 | K1: 2029 | L1: 2030 | M1: 2031 | N1: 2032 | O1: 2033 | P1: 2034 | Q1: 2035 | R1: 2036 | S1: 2037 | T1: 2038 | U1: 2039 | V1: 2040 | W1: 2041 | X1: 2042 | Y1: 2043 | Z1: 2044 | AA1: 2045 | AB1: 2046 | AC1: 2047 | AD1: 2048 | AE1: 2049 | AF1: 2050
A2: passenger LDVs ACC I | B2: 0 | C2: 0 | D2: 0 | E2: 0 | F2: =8% -> 0.08 | G2: =8% -> 0.08 | H2: 0 | I2: 0 | J2: 0 | K2: 0 | L2: 0 | M2: 0 | N2: 0 | O2: 0 | P2: 0 | Q2: 0 | R2: 0 | S2: 0 | T2: 0 | U2: 0 | V2: 0 | W2: 0 | X2: 0 | Y2: 0 | Z2: 0 | AA2: 0 | AB2: 0 | AC2: 0 | AD2: 0 | AE2: 0 | AF2: 0
A3: passenger LDVs ACC II | B3: =B2 -> 0 | C3: =C2 -> 0 | D3: =D2 -> 0 | E3: =E2 -> 0 | F3: =F2 -> 0.08 | G3: =G2 -> 0.08 | H3: ='EPS Vehicle Class Mapping'!H48 -> 0.35 | I3: ='EPS Vehicle Class Mapping'!I48 -> 0.43 | J3: ='EPS Vehicle Class Mapping'!J48 -> 0.51 | K3: ='EPS Vehicle Class Mapping'!K48 -> 0.59 | L3: ='EPS Vehicle Class Mapping'!L48 -> 0.68 | M3: ='EPS Vehicle Class Mapping'!M48 -> 0.76 | N3: ='EPS Vehicle Class Mapping'!N48 -> 0.82 | O3: ='EPS Vehicle Class Mapping'!O48 -> 0.88 | ... AF3: ='EPS Vehicle Class Mapping'!AF48 -> 1
A4: passenger LDVs ACC II - CO | B4: =B3 -> 0 | C4: =C3 -> 0 | D4: =D3 -> 0 | E4: =E3 -> 0 | F4: =F3 -> 0.08 | G4: =G3 -> 0.08 | H4: =H3 -> 0.35 | I4: =I3 -> 0.43 | ... N4: =N3 -> 0.82 | O4: =$N$4 -> 0.82 | P4: =$N$4 -> 0.82 | Q4: =$N$4 -> 0.82 | R4: =$N$4 -> 0.82 | S4: =$N$4 -> 0.82 | T4: =$N$4 -> 0.82 | U4: =$N$4 -> 0.82 | V4: =$N$4 -> 0.82 | ... AF4: =$N$4 -> 0.82
A5: passenger HDVs | B5: ='EPS Vehicle Class Mapping'!B49 -> 0 | C5: ='EPS Vehicle Class Mapping'!C49 -> 0 | D5: ='EPS Vehicle Class Mapping'!D49 -> 0 | E5: ='EPS Vehicle Class Mapping'!E49 -> 0 | F5: ='EPS Vehicle Class Mapping'!F49 -> 0.039118536 | G5: ='EPS Vehicle Class Mapping'!G49 -> 0.047811544 | H5: ='EPS Vehicle Class Mapping'!H49 -> 0.056504552 | I5: ='EPS Vehicle Class Mapping'!I49 -> 0.086930079 | ... AF5: ='EPS Vehicle Class Mapping'!AF49 -> 0.3259878
A6: passenger motorbikes | B6: ='EPS Vehicle Class Mapping'!B50 -> 0 | C6: ='EPS Vehicle Class Mapping'!C50 -> 0 | D6: ='EPS Vehicle Class Mapping'!D50 -> 0 | E6: ='EPS Vehicle Class Mapping'!E50 -> 0 | F6: ='EPS Vehicle Class Mapping'!F50 -> 0 | G6: ='EPS Vehicle Class Mapping'!G50 -> 0 | H6: ='EPS Vehicle Class Mapping'!H50 -> 0 | I6: ='EPS Vehicle Class Mapping'!I50 -> 0 | ... AF6: ='EPS Vehicle Class Mapping'!AF50 -> 0
A7: freight LDVs | B7: ='EPS Vehicle Class Mapping'!B51 -> 0 | C7: ='EPS Vehicle Class Mapping'!C51 -> 0 | D7: ='EPS Vehicle Class Mapping'!D51 -> 0 | E7: ='EPS Vehicle Class Mapping'!E51 -> 0 | F7: ='EPS Vehicle Class Mapping'!F51 -> 0.060092351 | G7: ='EPS Vehicle Class Mapping'!G51 -> 0.080071705 | H7: ='EPS Vehicle Class Mapping'!H51 -> 0.10754676 | I7: ='EPS Vehicle Class Mapping'!I51 -> 0.16256128 | ... AF7: ='EPS Vehicle Class Mapping'!AF51 -> 0.59999472
A8: freight HDVs | B8: ='EPS Vehicle Class Mapping'!B52 -> 0 | C8: ='EPS Vehicle Class Mapping'!C52 -> 0 | D8: ='EPS Vehicle Class Mapping'!D52 -> 0 | E8: ='EPS Vehicle Class Mapping'!E52 -> 0 | F8: ='EPS Vehicle Class Mapping'!F52 -> 0.050324585 | G8: ='EPS Vehicle Class Mapping'!G52 -> 0.070320874 | H8: ='EPS Vehicle Class Mapping'!H52 -> 0.10023841 | I8: ='EPS Vehicle Class Mapping'!I52 -> 0.15039415 | ... AF8: ='EPS Vehicle Class Mapping'!AF52 -> 0.40260342
A9: freight motorbikes | B9: ='EPS Vehicle Class Mapping'!B53 -> 0 | C9: ='EPS Vehicle Class Mapping'!C53 -> 0 | D9: ='EPS Vehicle Class Mapping'!D53 -> 0 | E9: ='EPS Vehicle Class Mapping'!E53 -> 0 | F9: ='EPS Vehicle Class Mapping'!F53 -> 0 | G9: ='EPS Vehicle Class Mapping'!G53 -> 0 | H9: ='EPS Vehicle Class Mapping'!H53 -> 0 | I9: ='EPS Vehicle Class Mapping'!I53 -> 0 | ... AF9: ='EPS Vehicle Class Mapping'!AF53 -> 0
A12: use '1' to indicate that the state follows the rule | B12: Calibration Values for EPA LDV Stds Applied? | C12: Calibration Values for EPA HDV Stds Applied? | D12: Does this state follow: | G12: What model year does this state begin regulating:
D13: ACC I | E13: ACC II | F13: ACT | G13: ACC I Cars | H13: ACC II Cars | I13: Trucks
A14: Alabama | B14: =IF(E14>0,0,1) -> 1 | C14: =IF(F14=0,1) -> 1 | D14: 0 | E14: 0 | F14: 0
A15: Alaska | B15: =IF(E15>0,0,1) -> 1 | C15: =IF(F15=0,1) -> 1 | D15: 0 | E15: 0 | F15: 0
A16: Arizona | B16: =IF(E16>0,0,1) -> 1 | C16: =IF(F16=0,1) -> 1 | D16: 0 | E16: 0 | F16: 0
A17: Arkansas | B17: =IF(E17>0,0,1) -> 1 | C17: =IF(F17=0,1) -> 1 | D17: 0 | E17: 0 | F17: 0
A18: California | B18: =IF(E18>0,0,1) -> 0 | C18: =IF(F18=0,1) -> FALSE | D18: 1 | E18: 1 | F18: 1 | G18: 1990 | H18: 2026 | I18: 2024
A19: Colorado | B19: =IF(E19>0,0,1) -> 0 | C19: =IF(F19=0,1) -> FALSE | D19: 1 | E19: 0.82 | F19: 1 | G19: 2023 | H19: 2026 | I19: 2027
A20: Connecticut | B20: =IF(E20>0,0,1) -> 1 | C20: =IF(F20=0,1) -> 1 | D20: 1 | E20: 0 | F20: 0 | G20: 2008
A21: Delaware | B21: =IF(E21>0,0,1) -> 0 | C21: =IF(F21=0,1) -> 1 | D21: 0 | E21: 0.82 | F21: 0 | H21: 2026
A22: District of Columbia | B22: =IF(E22>0,0,1) -> 0 | C22: =IF(F22=0,1) -> 1 | D22: 0 | E22: 1 | F22: 0 | H22: 2026
A23: Florida | B23: =IF(E23>0,0,1) -> 1 | C23: =IF(F23=0,1) -> 1 | D23: 0 | E23: 0 | F23: 0
A24: Georgia | B24: =IF(E24>0,0,1) -> 1 | C24: =IF(F24=0,1) -> 1 | D24: 0 | E24: 0 | F24: 0
A25: Hawaii | B25: =IF(E25>0,0,1) -> 1 | C25: =IF(F25=0,1) -> 1 | D25: 0 | E25: 0 | F25: 0
A26: Idaho | B26: =IF(E26>0,0,1) -> 1 | C26: =IF(F26=0,1) -> 1 | D26: 0 | E26: 0 | F26: 0
A27: Illinois | B27: =IF(E27>0,0,1) -> 1 | C27: =IF(F27=0,1) -> 1 | D27: 0 | E27: 0 | F27: 0
A28: Indiana | B28: =IF(E28>0,0,1) -> 1 | C28: =IF(F28=0,1) -> 1 | D28: 0 | E28: 0 | F28: 0
A29: Iowa | B29: =IF(E29>0,0,1) -> 1 | C29: =IF(F29=0,1) -> 1 | D29: 0 | E29: 0 | F29: 0
A30: Kansas | B30: =IF(E30>0,0,1) -> 1 | C30: =IF(F30=0,1) -> 1 | D30: 0 | E30: 0 | F30: 0
A31: Kentucky | B31: =IF(E31>0,0,1) -> 1 | C31: =IF(F31=0,1) -> 1 | D31: 0 | E31: 0 | F31: 0
A32: Louisiana | B32: =IF(E32>0,0,1) -> 1 | C32: =IF(F32=0,1) -> 1 | D32: 0 | E32: 0 | F32: 0
A33: Maine | B33: =IF(E33>0,0,1) -> 1 | C33: =IF(F33=0,1) -> 1 | D33: 1 | E33: 0 | F33: 0 | G33: 2001
A34: Maryland | B34: =IF(E34>0,0,1) -> 0 | C34: =IF(F34=0,1) -> FALSE | D34: 1 | E34: 1 | F34: 1 | G34: 2011 | H34: 2026 | I34: 2027
A35: Massachusetts | B35: =IF(E35>0,0,1) -> 0 | C35: =IF(F35=0,1) -> FALSE | D35: 1 | E35: 1 | F35: 1 | G35: 1995 | H35: 2026 | I35: 2025
A36: Michigan | B36: =IF(E36>0,0,1) -> 1 | C36: =IF(F36=0,1) -> 1 | D36: 0 | E36: 0 | F36: 0
A37: Minnesota | B37: =IF(E37>0,0,1) -> 1 | C37: =IF(F37=0,1) -> 1 | D37: 1 | E37: 0 | F37: 0 | G37: 2025
A38: Mississippi | B38: =IF(E38>0,0,1) -> 1 | C38: =IF(F38=0,1) -> 1 | D38: 0 | E38: 0 | F38: 0
A39: Missouri | B39: =IF(E39>0,0,1) -> 1 | C39: =IF(F39=0,1) -> 1 | D39: 0 | E39: 0 | F39: 0
A40: Montana | B40: =IF(E40>0,0,1) -> 1 | C40: =IF(F40=0,1) -> 1 | D40: 0 | E40: 0 | F40: 0
A41: Nebraska | B41: =IF(E41>0,0,1) -> 1 | C41: =IF(F41=0,1) -> 1 | D41: 0 | E41: 0 | F41: 0
A42: Nevada | B42: =IF(E42>0,0,1) -> 1 | C42: =IF(F42=0,1) -> 1 | D42: 1 | E42: 0 | F42: 0 | G42: 2025
...

Sheet AEO Table 7
B1: ref2023.d020623a | C1: 2022 | D1: 2023 | E1: 2024 | F1: 2025 | G1: 2026 | H1: 2027 | I1: 2028 | J1: 2029 | K1: 2030 | L1: 2031 | M1: 2032 | N1: 2033 | O1: 2034 | P1: 2035 | Q1: 2036 | R1: 2037 | S1: 2038 | T1: 2039 | U1: 2040 | V1: 2041 | W1: 2042 | X1: 2043 | Y1: 2044 | Z1: 2045 | AA1: 2046 | AB1: 2047 | AC1: 2048 | AD1: 2049 | AE1: 2050
C3: Report | D3: Annual Energy Outlook 2023
C4: Scenario | D4: ref2023 | G4: Reference
C5: Datekey | D5: d020623a
C6: Release Date | E6: March 2023
A10: TKI000 | B10: 7. Transportation Sector Key Indicators and Delivered Energy Consumption | AF10: Average
AF11: Annual
AF12: Change
B13: Key Indicators and Consumption | C13: 2022 | D13: 2023 | E13: 2024 | F13: 2025 | G13: 2026 | H13: 2027 | I13: 2028 | J13: 2029 | K13: 2030 | L13: 2031 | M13: 2032 | N13: 2033 | O13: 2034 | P13: 2035 | Q13: 2036 | R13: 2037 | S13: 2038 | T13: 2039 | U13: 2040 | V13: 2041 | W13: 2042 | X13: 2043 | Y13: 2044 | Z13: 2045 | AA13: 2046 | AB13: 2047 | AC13: 2048 | AD13: 2049 | AE13: 2050 | AF13: 2022–2050
B15: Key Indicators
B16: Travel Indicators
B17: (billion vehicle miles traveled)
A18: TKI000:ba_Light-DutyVeh | B18: Light-Duty Vehicles less than 8,501 pounds | C18: 2843.2981 | D18: 2901.3589 | E18: 2922.5066 | F18: 2933.3601 | G18: 2954.238 | H18: 2981.9343 | I18: 3007.5581 | J18: 3027.573 | K18: 3042.8433 | L18: 3055.7747 | M18: 3066.6516 | N18: 3082.3594 | O18: 3102.4182 | P18: 3120.7375 | Q18: 3135.6208 | R18: 3152.9177 | S18: 3172.4355 | T18: 3192.1006 | U18: 3214.563 | V18: 3237.5806 | W18: 3261.5847 | X18: 3284.8975 | Y18: 3309.0391 | Z18: 3334.7034 | AA18: 3364.5225 | AB18: 3396.5352 | AC18: 3429.5627 | AD18: 3463.0249 | AE18: 3499.543 | AF18: 0.007444
A19: TKI000:ba_CommercialLig | B19: Commercial Light Trucks 1/ | C19: 102.21495 | D19: 103.34346 | E19: 103.55378 | F19: 104.36999 | G19: 105.65627 | H19: 107.00255 | I19: 108.20406 | J19: 109.32984 | K19: 110.21457 | L19: 111.0637 | M19: 112.17591 | N19: 113.26731 | O19: 114.36133 | P19: 115.53986 | Q19: 116.6934 | R19: 117.93478 | S19: 119.26325 | T19: 120.51714 | U19: 121.9657 | V19: 123.54321 | W19: 125.05544 | X19: 126.4902 | Y19: 127.8319 | Z19: 129.14803 | AA19: 130.64792 | AB19: 132.25534 | AC19: 133.71924 | AD19: 135.16911 | AE19: 137.06503 | AF19: 0.010533
A20: TKI000:ba_FreightTrucks | B20: Freight Trucks greater than 10,000 pounds | C20: 321.95499 | D20: 320.72061 | E20: 321.15665 | F20: 324.03918 | G20: 328.45148 | H20: 332.31928 | I20: 335.87875 | J20: 338.621 | K20: 341.15326 | L20: 344.16229 | M20: 348.16583 | N20: 351.54123 | O20: 354.83011 | P20: 358.3447 | Q20: 361.39355 | R20: 364.92679 | S20: 368.38065 | T20: 371.81143 | U20: 375.58807 | V20: 379.58752 | W20: 383.51465 | X20: 387.20883 | Y20: 390.63339 | Z20: 393.83795 | AA20: 397.54263 | AB20: 401.35467 | AC20: 404.65982 | AD20: 408.22446 | AE20: 413.08252 | AF20: 0.008941
B21: (billion passenger miles traveled)
A22: TKI000:buspassmiles | B22: Bus Transportation | C22: 175.47365 | D22: 186.88329 | E22: 193.3692 | F22: 197.39229 | G22: 200.32752 | H22: 202.52968 | I22: 204.21141 | J22: 205.46838 | K22: 206.39357 | L22: 207.0294 | M22: 207.54085 | N22: 207.99565 | O22: 208.43976 | P22: 208.79684 | Q22: 209.10339 | R22: 209.37013 | S22: 209.49379 | T22: 209.54416 | U22: 209.54358 | V22: 209.49118 | W22: 209.41185 | X22: 209.25844 | Y22: 209.10913 | Z22: 208.93102 | AA22: 208.81189 | AB22: 208.60612 | AC22: 208.41769 | AD22: 208.19235 | AE22: 207.99593 | AF22: 0.006091
A23: TKI000:railpassmiles | B23: Passenger Rail | C23: 30.144947 | D23: 32.030231 | E23: 33.06411 | F23: 33.706196 | G23: 34.620327 | H23: 35.443916 | I23: 36.137474 | J23: 36.650322 | K23: 37.00806 | L23: 37.264553 | M23: 37.633518 | N23: 38.06789 | O23: 38.564194 | P23: 38.985653 | Q23: 39.398945 | R23: 39.809189 | S23: 40.237045 | T23: 40.652229 | U23: 41.127975 | V23: 41.567631 | W23: 42.019573 | X23: 42.40731 | Y23: 42.842342 | Z23: 43.266335 | AA23: 43.867863 | AB23: 44.361511 | AC23: 44.905075 | AD23: 45.395485 | AE23: 46.002594 | AF23: 0.01521
B24: (billion seat miles available)
A25: TKI000:ba_Air | B25: Air | C25: 1173.0347 | D25: 1318.6946 | E25: 1361.6111 | F25: 1371.6552 | G25: 1402.928 | H25: 1433.8398 | I25: 1461.4722 | J25: 1484.8291 | K25: 1504.2688 | L25: 1524.7269 | M25: 1552.2568 | N25: 1583.9248 | O25: 1615.3802 | P25: 1647.3462 | Q25: 1682.5896 | R25: 1721.0469 | S25: 1761.139 | T25: 1801.941 | U25: 1848.072 | V25: 1894.2041 | W25: 1941.463 | X25: 1990.3643 | Y25: 2038.4374 | Z25: 2085.6875 | AA25: 2134.0049 | AB25: 2185.897 | AC25: 2238.8362 | AD25: 2292.3555 | AE25: 2350.269 | AF25: 0.02513
B26: (billion ton miles traveled)
A27: TKI000:ba_Rail | B27: Rail | C27: 1620.4949 | D27: 1600.1008 | E27: 1666.9198 | F27: 1628.4084 | G27: 1561.4207 | H27: 1509.6494 | I27: 1489.7312 | J27: 1507.5151 | K27: 1500.1649 | L27: 1506.9524 | M27: 1522.1982 | N27: 1534.7394 | O27: 1543.2374 | P27: 1554.5907 | Q27: 1557.5254 | R27: 1562.4816 | S27: 1568.9661 | T27: 1568.3395 | U27: 1571.7775 | V27: 1585.6112 | W27: 1597.307 | X27: 1600.1909 | Y27: 1601.8328 | Z27: 1602.9988 | AA27: 1608.1294 | AB27: 1618.0824 | AC27: 1630.808 | AD27: 1636.8905 | AE27: 1649.4695 | AF27: 0.000633
A28: TKI000:ba_DomesticShipp | B28: Domestic Shipping | C28: 444.89887 | D28: 450.42761 | E28: 448.61005 | F28: 446.74628 | G28: 445.22772 | H28: 442.84778 | I28: 440.43005 | J28: 437.0246 | K28: 434.03641 | L28: 431.39212 | M28: 429.99737 | N28: 428.16068 | O28: 426.27862 | P28: 424.17816 | Q28: 421.71698 | R28: 419.81464 | S28: 417.56705 | T28: 415.80768 | U28: 414.04514 | V28: 412.52209 | W28: 411.24774 | X28: 409.97736 | Y28: 408.52225 | Z28: 406.63034 | AA28: 405.35852 | AB28: 403.86591 | AC28: 401.97906 | AD28: 400.55664 | AE28: 400.09833 | AF28: -0.003783
B30: Energy Efficiency Indicators
B31: (miles per gallon)
A32: TKI000:ca_AvgCAFEStand | B32: New Light-Duty Vehicle CAFE Standard 2/ | C32: 35.855949 | D32: 36.277985 | E32: 39.337013 | F32: 42.578201 | G32: 47.262627 | H32: 47.227249 | I32: 47.18121 | J32: 47.168774 | K32: 47.163849 | L32: 47.152081 | M32: 47.159279 | N32: 47.152672 | O32: 47.146118 | P32: 47.131687 | Q32: 47.138325 | R32: 47.119869 | S32: 47.100937 | T32: 47.084251 | U32: 47.059879 | V32: 47.032314 | W32: 47.004074 | X32: 46.960155 | Y32: 46.939564 | Z32: 46.91069 | AA32: 46.948238 | AB32: 46.913113 | AC32: 46.90683 | AD32: 46.880138 | AE32: 46.870857 | AF32: 0.009613
A33: TKI000:ca_CarCAFEStand | B33: New Car 2/ | C33: 45.004654 | D33: 45.471119 | E33: 49.460312 | F33: 53.789036 | G33: 59.791531 | H33: 59.80352 | I33: 59.817413 | J33: 59.819332 | K33: 59.821598 | L33: 59.822445 | M33: 59.827473 | N33: 59.828793 | O33: 59.83078 | P33: 59.83112 | Q33: 59.842136 | R33: 59.842136 | S33: 59.842136 | T33: 59.843197 | U33: 59.843197 | V33: 59.843231 | W33: 59.845177 | X33: 59.845177 | Y33: 59.848228 | Z33: 59.848228 | AA33: 59.867775 | AB33: 59.867775 | AC33: 59.867775 | AD33: 59.867775 | AE33: 59.867775 | AF33: 0.010244
A34: TKI000:ca_TwukCAFEStand | B34: New Light Truck 2/ | C34: 32.047302 | D34: 32.608868 | E34: 35.403008 | F34: 38.46349 | G34: 42.755749 | H34: 42.75658 | I34: 42.76173 | J34: 42.76173 | K34: 42.761841 | L34: 42.762085 | M34: 42.762169 | N34: 42.76236 | O34: 42.76239 | P34: 42.76252 | Q34: 42.762554 | R34: 42.762699 | S34: 42.762756 | T34: 42.762825 | U34: 42.762897 | V34: 42.762962 | W34: 42.763016 | X34: 42.763103 | Y34: 42.763103 | Z34: 42.763184 | AA34: 42.763184 | AB34: 42.763294 | AC34: 42.763294 | AD34: 42.763393 | AE34: 42.763393 | AF34: 0.010356
A35: TKI000:ca_NewVehCred | B35: Compliance New Light-Duty Vehicle 3/ | C35: 41.802036 | D35: 43.2672 | E35: 44.448151 | F35: 47.052715 | G35: 48.571758 | H35: 49.79253 | I35: 52.281479 | J35: 53.248959 | K35: 53.962006 | L35: 54.332035 | M35: 54.872646 | N35: 55.329353 | O35: 55.771633 | P35: 56.242725 | Q35: 56.632603 | R35: 56.856194 | S35: 57.030457 | T35: 57.310715 | U35: 57.240421 | V35: 57.306023 | W35: 57.371868 | X35: 57.326744 | Y35: 57.237999 | Z35: 57.125122 | AA35: 57.475964 | AB35: 57.327747 | AC35: 57.273457 | AD35: 57.524818 | AE35: 57.479156 | AF35: 0.011439
A36: TKI000:ca_NewCarCred | B36: New Car 3/ | C36: 56.582645 | D36: 58.322227 | E36: 59.783314 | F36: 64.222374 | G36: 65.997482 | H36: 68.148636 | I36: 72.759445 | J36: 74.876167 | K36: 76.446304 | L36: 77.157303 | M36: 78.145363 | N36: 78.735664 | O36: 79.269257 | P36: 79.864815 | Q36: 80.311752 | R36: 80.510567 | S36: 80.643074 | T36: 81.042244 | U36: 80.790894 | V36: 80.999863 | W36: 81.213394 | X36: 81.251564 | Y36: 81.126785 | Z36: 80.963654 | AA36: 81.962257 | AB36: 81.685669 | AC36: 81.57402 | AD36: 82.338425 | AE36: 82.243484 | AF36: 0.013446
A37: TKI000:ca_NewTwukCred | B37: New Light Truck 3/ | C37: 36.263931 | D37: 37.832123 | E37: 39.014805 | F37: 41.375153 | G37: 42.876762 | H37: 43.911583 | I37: 45.953789 | J37: 46.678478 | K37: 47.207012 | L37: 47.518375 | M37: 47.939487 | N37: 48.362621 | O37: 48.779861 | P37: 49.233047 | Q37: 49.585567 | R37: 49.838345 | S37: 50.048077 | T37: 50.325745 | U37: 50.338009 | V37: 50.426777 | W37: 50.517311 | X37: 50.542614 | Y37: 50.50412 | Z37: 50.459385 | AA37: 50.61805 | AB37: 50.565735 | AC37: 50.535652 | AD37: 50.739391 | AE37: 50.721836 | AF37: 0.012055
A38: TKI000:ca_TestedNewVeh | B38: Tested New Light-Duty Vehicle 4/ | C38: 37.621078 | D38: 38.382416 | E38: 39.075672 | F38: 40.794502 | G38: 41.684994 | H38: 42.387779 | I38: 43.992405 | J38: 44.482399 | K38: 44.828846 | L38: 45.012852 | M38: 45.295109 | N38: 45.54966 | O38: 45.800465 | P38: 46.072914 | Q38: 46.308186 | R38: 46.454895 | S38: 46.573441 | T38: 46.763412 | U38: 46.743324 | V38: 46.781216 | W38: 46.812752 | X38: 46.781078 | Y38: 46.720787 | Z38: 46.649311 | AA38: 46.812588 | AB38: 46.721981 | AC38: 46.686661 | AD38: 46.844208 | AE38: 46.809135 | AF38: 0.007835
A39: TKI000:ca_TestedNewCar | B39: New Car 4/ | C39: 49.658657 | D39: 50.63982 | E39: 51.418789 | F39: 54.041267 | G39: 54.808311 | H39: 55.812794 | I39: 58.414131 | J39: 59.295654 | K39: 59.885937 | L39: 60.128426 | M39: 60.482559 | N39: 60.696911 | O39: 60.896141 | P39: 61.139969 | Q39: 61.34211 | R39: 61.456459 | S39: 61.54549 | T39: 61.791069 | U39: 61.720493 | V39: 61.820892 | W39: 61.909645 | X39: 61.923454 | Y39: 61.848679 | Z39: 61.762375 | AA39: 62.120819 | AB39: 61.989952 | AC39: 61.932671 | AD39: 62.331699 | AE39: 62.272804 | AF39: 0.008117
A40: TKI000:ca_TestedNewTwuk | B40: New Light Truck 4/ | C40: 32.951321 | D40: 33.82571 | E40: 34.570251 | F40: 36.235542 | G40: 37.203815 | H40: 37.859802 | I40: 39.251301 | J40: 39.65464 | K40: 39.942871 | L40: 40.123779 | M40: 40.372108 | N40: 40.635685 | O40: 40.898228 | P40: 41.187042 | Q40: 41.415565 | R40: 41.589336 | S40: 41.735809 | T40: 41.930031 | U40: 41.954327 | V40: 42.014381 | W40: 42.070942 | X40: 42.089371 | Y40: 42.062252 | Z40: 42.034523 | AA40: 42.106945 | AB40: 42.074627 | AC40: 42.053329 | AD40: 42.192116 | AE40: 42.17543 | AF40: 0.008853
A41: TKI000:ca_OnRoadNewVeh | B41: On-Road New Light-Duty Vehicle 5/ | C41: 30.687853 | D41: 31.308468 | E41: 31.873775 | F41: 33.275242 | G41: 34.001518 | H41: 34.574638 | I41: 35.883228 | J41: 36.28281 | K41: 36.56535 | L41: 36.715401 | M41: 36.945652 | N41: 37.153278 | O41: 37.357868 | P41: 37.580082 | Q41: 37.772026 | R41: 37.891651 | S41: 37.988308 | T41: 38.143211 | U41: 38.126759 | V41: 38.157574 | W41: 38.183201 | X41: 38.157219 | Y41: 38.107975 | Z41: 38.049587 | AA41: 38.182838 | AB41: 38.108822 | AC41: 38.080002 | AD41: 38.208389 | AE41: 38.179749 | AF41: 0.007832
A42: TKI000:ca_OnRoadNewCar | B42: New Car 5/ | C42: 40.552002 | D42: 41.353237 | E42: 41.989353 | F42: 44.130909 | G42: 44.75729 | H42: 45.577564 | I42: 47.701855 | J42: 48.421719 | K42: 48.903755 | L42: 49.101772 | M42: 49.390965 | N42: 49.566006 | O42: 49.728703 | P42: 49.927814 | Q42: 50.092888 | R42: 50.186264 | S42: 50.258968 | T42: 50.459515 | U42: 50.401878 | V42: 50.483868 | W42: 50.556343 | X42: 50.567619 | Y42: 50.506557 | Z42: 50.436081 | AA42: 50.72879 | AB42: 50.621925 | AC42: 50.575146 | AD42: 50.901001 | AE42: 50.852905 | AF42: 0.008117
A43: TKI000:ca_OnRoadNewTwuk | B43: New Light Truck 5/ | C43: 26.867123 | D43: 27.580063 | E43: 28.18713 | F43: 29.544939 | G43: 30.334429 | H43: 30.869291 | I43: 32.00386 | J43: 32.332729 | K43: 32.567738 | L43: 32.715244 | M43: 32.917721 | N43: 33.132629 | O43: 33.346695 | P43: 33.582184 | Q43: 33.768513 | R43: 33.910198 | S43: 34.029625 | T43: 34.187984 | U43: 34.207794 | V43: 34.25676 | W43: 34.302879 | X43: 34.317905 | Y43: 34.295792 | Z43: 34.273186 | AA43: 34.332233 | AB43: 34.305882 | AC43: 34.288517 | AD43: 34.40168 | AE43: 34.388073 | AF43: 0.008853
... A47: TKI000:ca_FreightTruck | B47: Freight Truck | C47: 7.472406 | D47: 7.578529 | E47: 7.705323 | F47: 7.84859 | G47: 8.002383 | H47: 8.163677 | I47: 8.321285 | J47: 8.479755 | K47: 8.638294 | L47: 8.79593 | M47: 8.948549 | N47: 9.090997 | O47: 9.222516 | P47: 9.343068 | Q47: 9.453315 | R47: 9.553063 | S47: 9.643444 | T47: 9.72671 | U47: 9.804593 | V47: 9.877275 | W47: 9.942431 | X47: 10.001567 | Y47: 10.055841 | Z47: 10.108454 | AA47: 10.161228 | AB47: 10.213311 | AC47: 10.263764 | AD47: 10.314513 | AE47: 10.365861 | AF47: 0.011758
B48: (seat miles per gallon)
A49: TKI000:ca_Aircraft | B49: Aircraft | C49: 72.717087 | D49: 73.091972 | E49: 73.492531 | F49: 74.018456 | G49: 74.683121 | H49: 75.131767 | I49: 75.59214 | J49: 76.024017 | K49: 76.492363 | L49: 77.014214 | M49: 77.60096 | N49: 78.266678 | O49: 78.981506 | P49: 79.730591 | Q49: 80.48922 | R49: 81.260979 | S49: 82.048454 | T49: 82.814575 | U49: 83.594772 | V49: 84.382309 | W49: 85.171204 | X49: 85.974022 | Y49: 86.764038 | Z49: 87.549927 | AA49: 88.321091 | AB49: 89.091156 | AC49: 89.849762 | AD49: 90.593376 | AE49: 91.328148 | AF49: 0.008172
...

Sheet AEO Table 44
B1: ref2023.d020623a | C1: 2022 | D1: 2023 | E1: 2024 | F1: 2025 | G1: 2026 | H1: 2027 | I1: 2028 | J1: 2029 | K1: 2030 | L1: 2031 | M1: 2032 | N1: 2033 | O1: 2034 | P1: 2035 | Q1: 2036 | R1: 2037 | S1: 2038 | T1: 2039 | U1: 2040 | V1: 2041 | W1: 2042 | X1: 2043 | Y1: 2044 | Z1: 2045 | AA1: 2046 | AB1: 2047 | AC1: 2048 | AD1: 2049 | AE1: 2050
C3: Report | D3: Annual Energy Outlook 2023
C4: Scenario | D4: ref2023 | G4: Reference
C5: Datekey | D5: d020623a
C6: Release Date | E6: March 2023
A10: TFS000 | B10: 44. Transportation Fleet Car and Truck Sales by Type and Technology | AF10: Annual
B11: (thousands) | AF11: Change
AF12: 2022–2050
B13: Technology Type | C13: 2022 | D13: 2023 | E13: 2024 | F13: 2025 | G13: 2026 | H13: 2027 | I13: 2028 | J13: 2029 | K13: 2030 | L13: 2031 | M13: 2032 | N13: 2033 | O13: 2034 | P13: 2035 | Q13: 2036 | R13: 2037 | S13: 2038 | T13: 2039 | U13: 2040 | V13: 2041 | W13: 2042 | X13: 2043 | Y13: 2044 | Z13: 2045 | AA13: 2046 | AB13: 2047 | AC13: 2048 | AD13: 2049 | AE13: 2050 | AF13: 2050
B15: New Car Sales 1/
B16: Conventional Cars
A17: TFS000:ba_GasolineICEVe | B17: Gasoline ICE Vehicles | C17: 745.48859 | D17: 752.84778 | E17: 752.35828 | F17: 735.73346 | G17: 714.39777 | H17: 699.98785 | I17: 685.04047 | J17: 673.87494 | K17: 663.85052 | L17: 653.93219 | M17: 646.67609 | N17: 638 | O17: 632.65363 | P17: 629.94421 | Q17: 630.54657 | R17: 627.93366 | S17: 625.11896 | T17: 622.16144 | U17: 618.44098 | V17: 611.17291 | W17: 603.78058 | X17: 594.08051 | Y17: 586.63452 | Z17: 582.1673 | AA17: 581.98822 | AB17: 575.44702 | AC17: 569.67371 | AD17: 564.75281 | AE17: 561.18835 | AF17: -0.010091
A18: TFS000:ba_TDIDieselICE | B18: TDI Diesel ICE | C18: 0 | D18: 0 | E18: 0 | F18: 0 | G18: 0 | H18: 0 | I18: 0 | J18: 0 | K18: 0 | L18: 0 | M18: 0 | N18: 0 | O18: 0 | P18: 0 | Q18: 0 | R18: 0 | S18: 0 | T18: 0 | U18: 0 | V18: 0 | W18: 0 | X18: 0 | Y18: 0 | Z18: 0 | AA18: 0 | AB18: 0 | AC18: 0 | AD18: 0 | AE18: 0 | AF18: --
A19: TFS000:ba_TotalConventi | B19: Total Conventional Cars | C19: 745.48859 | D19: 752.84778 | E19: 752.35828 | F19: 735.73346 | G19: 714.39777 | H19: 699.98785 | I19: 685.04047 | J19: 673.87494 | K19: 663.85052 | L19: 653.93219 | M19: 646.67609 | N19: 638 | O19: 632.65363 | P19: 629.94421 | Q19: 630.54657 | R19: 627.93366 | S19: 625.11896 | T19: 622.16144 | U19: 618.44098 | V19: 611.17291 | W19: 603.78058 | X19: 594.08051 | Y19: 586.63452 | Z19: 582.1673 | AA19: 581.98822 | AB19: 575.44702 | AC19: 569.67371 | AD19: 564.75281 | AE19: 561.18835 | AF19: -0.010091
B21: Alternative-Fuel Cars
A22: TFS000:ca_Ethanol-FlexF | B22: Ethanol-Flex Fuel ICE | C22: 27.701494 | D22: 28.161213 | E22: 28.336246 | F22: 27.930389 | G22: 27.360483 | H22: 27.062561 | I22: 26.745171 | J22: 26.574789 | K22: 26.450092 | L22: 26.327152 | M22: 26.309853 | N22: 26.236437 | O22: 26.300083 | P22: 26.476437 | Q22: 26.802656 | R22: 26.993179 | S22: 27.175011 | T22: 27.3564 | U22: 27.506229 | V22: 27.497744 | W22: 27.48558 | X22: 27.36544 | Y22: 27.347322 | Z22: 27.466482 | AA22: 27.77367 | AB22: 27.796991 | AC22: 27.862095 | AD22: 27.968414 | AE22: 27.940855 | AF22: 0.000307
A23: TFS000:ca_100mileEV | B23: 100-Mile Electric Vehicle | C23: 1.733732 | D23: 2.015718 | E23: 2.282101 | F23: 2.494302 | G23: 2.678695 | H23: 2.879138 | I23: 3.07065 | J23: 3.273858 | K23: 3.479208 | L23: 3.682477 | M23: 3.899189 | N23: 4.106014 | O23: 4.333928 | P23: 4.58201 | Q23: 4.858603 | R23: 5.115785 | S23: 5.375243 | T23: 5.636921 | U23: 5.89505 | V23: 6.120733 | W23: 6.344616 | X23: 6.542595 | Y23: 6.763642 | Z23: 7.019996 | AA23: 7.332982 | AB23: 7.569391 | AC23: 7.816744 | AD23: 8.077607 | AE23: 8.358113 | AF23: 0.057785
A24: TFS000:ca_ElectricVehic | B24: 200-Mile Electric Vehicle | C24: 2.34727 | D24: 4.423422 | E24: 6.51033 | F24: 8.447515 | G24: 10.260118 | H24: 12.106405 | I24: 13.894964 | J24: 15.720405 | K24: 17.546631 | L24: 19.353251 | M24: 21.224617 | N24: 23.038656 | O24: 24.968584 | P24: 27.018316 | Q24: 29.246431 | R24: 31.364456 | S24: 33.500416 | T24: 35.655449 | U24: 37.791504 | V24: 39.719631 | W24: 41.633911 | X24: 43.373734 | Y24: 45.262123 | Z24: 47.386185 | AA24: 49.898258 | AB24: 51.892063 | AC24: 53.95982 | AD24: 56.121365 | AE24: 58.420788 | AF24: 0.12165
A25: TFS000:ea_FuelCellGasol | B25: 300-Mile Electric Vehicle | C25: 16.660831 | D25: 19.503101 | E25: 22.200615 | F25: 24.367395 | G25: 26.25774 | H25: 28.301954 | I25: 30.256197 | J25: 32.324257 | K25: 34.412506 | L25: 36.479725 | M25: 38.679714 | N25: 40.781128 | O25: 43.091831 | P25: 45.603497 | Q25: 48.399467 | R25: 51.002945 | S25: 53.629681 | T25: 56.278992 | U25: 58.893322 | V25: 61.18375 | W25: 63.455978 | X25: 65.468964 | Y25: 67.712502 | Z25: 70.309715 | AA25: 73.47554 | AB25: 75.873489 | AC25: 78.380974 | AD25: 81.024094 | AE25: 83.864441 | AF25: 0.059418
A26: TFS000:ca_Plug-inGasoli | B26: Plug-in 20 Gasoline Hybrid | C26: 2.416381 | D26: 2.779324 | E26: 3.120898 | F26: 3.388887 | G26: 3.61952 | H26: 3.871928 | I26: 4.112279 | J26: 4.368149 | K26: 4.626535 | L26: 4.881974 | M26: 5.155017 | N26: 5.414467 | O26: 5.701344 | P26: 6.014175 | Q26: 6.363098 | R26: 6.686507 | S26: 7.012915 | T26: 7.341406 | U26: 7.665002 | V26: 7.946321 | W26: 8.224556 | X26: 8.469109 | Y26: 8.743222 | Z26: 9.063097 | AA26: 9.459611 | AB26: 9.753787 | AC26: 10.060923 | AD26: 10.385608 | AE26: 10.734817 | AF26: 0.054702
A27: TFS000:ca_Plug-in40Hybd | B27: Plug-in 50 Gasoline Hybrid | C27: 0.85057 | D27: 1.23013 | E27: 1.607591 | F27: 1.947863 | G27: 2.261849 | H27: 2.585001 | I27: 2.896867 | J27: 3.217093 | K27: 3.53761 | L27: 3.854425 | M27: 4.184191 | N27: 4.502318 | O27: 4.842849 | P27: 5.205986 | Q27: 5.601945 | R27: 5.976532 | S27: 6.354444 | T27: 6.735092 | U27: 7.111816 | V27: 7.449342 | W27: 7.783675 | X27: 8.085442 | Y27: 8.414771 | Z27: 8.788048 | AA27: 9.236242 | AB27: 9.585274 | AC27: 9.946996 | AD27: 10.326148 | AE27: 10.729992 | AF27: 0.094756
A28: TFS000:ca_Electric-Dies | B28: Electric-Diesel Hybrid | C28: 0 | D28: 0 | E28: 0 | F28: 0 | G28: 0 | H28: 0 | I28: 0 | J28: 0 | K28: 0 | L28: 0 | M28: 0 | N28: 0 | O28: 0 | P28: 0 | Q28: 0 | R28: 0 | S28: 0 | T28: 0 | U28: 0 | V28: 0 | W28: 0 | X28: 0 | Y28: 0 | Z28: 0 | AA28: 0 | AB28: 0 | AC28: 0 | AD28: 0 | AE28: 0 | AF28: --
A29: TFS000:ca_Electric-Gaso | B29: Electric-Gasoline Hybrid | C29: 32.527454 | D29: 34.683559 | E29: 36.517467 | F29: 37.527821 | G29: 38.211796 | H29: 39.194439 | I29: 40.098598 | J29: 41.186401 | K29: 42.318878 | L29: 43.439339 | M29: 44.725349 | N29: 45.902386 | O29: 47.315739 | P29: 48.939678 | Q29: 50.848152 | R29: 52.535007 | S29: 54.232723 | T29: 55.940033 | U29: 57.601685 | V29: 58.942471 | W29: 60.265564 | X29: 61.346802 | Y29: 62.647991 | Z29: 64.274544 | AA29: 66.418465 | AB29: 67.85157 | AC29: 69.378136 | AD29: 71.021629 | AE29: 72.830383 | AF29: 0.029206
A30: TFS000:ca_CompressedNat | B30: Natural Gas ICE | C30: 0 | D30: 0 | E30: 0 | F30: 0 | G30: 0 | H30: 0 | I30: 0 | J30: 0 | K30: 0 | L30: 0 | M30: 0 | N30: 0 | O30: 0 | P30: 0 | Q30: 0 | R30: 0 | S30: 0 | T30: 0 | U30: 0 | V30: 0 | W30: 0 | X30: 0 | Y30: 0 | Z30: 0 | AA30: 0 | AB30: 0 | AC30: 0 | AD30: 0 | AE30: 0 | AF30: --
A31: TFS000:da_CompressedNat | B31: Natural Gas Bi-fuel | C31: 0 | D31: 0 | E31: 0 | F31: 0 | G31: 0 | H31: 0 | I31: 0 | J31: 0 | K31: 0 | L31: 0 | M31: 0 | N31: 0 | O31: 0 | P31: 0 | Q31: 0 | R31: 0 | S31: 0 | T31: 0 | U31: 0 | V31: 0 | W31: 0 | X31: 0 | Y31: 0 | Z31: 0 | AA31: 0 | AB31: 0 | AC31: 0 | AD31: 0 | AE31: 0 | AF31: --
A32: TFS000:da_LiquefiedPetr | B32: Propane ICE | C32: 0 | D32: 0 | E32: 0 | F32: 0 | G32: 0 | H32: 0 | I32: 0 | J32: 0 | K32: 0 | L32: 0 | M32: 0 | N32: 0 | O32: 0 | P32: 0 | Q32: 0 | R32: 0 | S32: 0 | T32: 0 | U32: 0 | V32: 0 | W32: 0 | X32: 0 | Y32: 0 | Z32: 0 | AA32: 0 | AB32: 0 | AC32: 0 | AD32: 0 | AE32: 0 | AF32: --
A33: TFS000:ea_LiquefiedPetr | B33: Propane Bi-fuel | C33: 0 | D33: 0 | E33: 0 | F33: 0 | G33: 0 | H33: 0 | I33: 0 | J33: 0 | K33: 0 | L33: 0 | M33: 0 | N33: 0 | O33: 0 | P33: 0 | Q33: 0 | R33: 0 | S33: 0 | T33: 0 | U33: 0 | V33: 0 | W33: 0 | X33: 0 | Y33: 0 | Z33: 0 | AA33: 0 | AB33: 0 | AC33: 0 | AD33: 0 | AE33: 0 | AF33: --
A34: TFS000:ea_FuelCellMetha | B34: Fuel Cell Methanol | C34: 0 | D34: 0 | E34: 0 | F34: 0 | G34: 0 | H34: 0 | I34: 0 | J34: 0 | K34: 0 | L34: 0 | M34: 0 | N34: 0 | O34: 0 | P34: 0 | Q34: 0 | R34: 0 | S34: 0 | T34: 0 | U34: 0 | V34: 0 | W34: 0 | X34: 0 | Y34: 0 | Z34: 0 | AA34: 0 | AB34: 0 | AC34: 0 | AD34: 0 | AE34: 0 | AF34: --
A35: TFS000:ea_FuelCellHydro | B35: Fuel Cell Hydrogen | C35: 0.048113 | D35: 0.092384 | E35: 0.137451 | F35: 0.179425 | G35: 0.218551 | H35: 0.258121 | I35: 0.29623 | J35: 0.334905 | K35: 0.373342 | L35: 0.411207 | M35: 0.450298 | N35: 0.487883 | O35: 0.527722 | P35: 0.569856 | Q35: 0.615191 | R35: 0.65825 | S35: 0.701748 | T35: 0.745306 | U35: 0.78838 | V35: 0.827084 | W35: 0.865125 | X35: 0.89946 | Y35: 0.936702 | Z35: 0.978884 | AA35: 1.03084 | AB35: 1.070397 | AC35: 1.110929 | AD35: 1.153482 | AE35: 1.19854 | AF35: 0.121686
A36: TFS000:ea_TotalAlternat | B36: Total Alternative Cars | C36: 84.285843 | D36: 92.888847 | E36: 100.7127 | F36: 106.28359 | G36: 110.86876 | H36: 116.25954 | I36: 121.37095 | J36: 126.99986 | K36: 132.7448 | L36: 138.42955 | M36: 144.62823 | N36: 150.46928 | O36: 157.08208 | P36: 164.40996 | Q36: 172.73555 | R36: 180.33266 | S36: 187.98219 | T36: 195.68961 | U36: 203.25299 | V36: 209.68707 | W36: 216.05902 | X36: 221.55154 | Y36: 227.82828 | Z36: 235.28696 | AA36: 244.62561 | AB36: 251.39296 | AC36: 258.51663 | AD36: 266.07834 | AE36: 274.07794 | AF36: 0.043014
A38: TFS000:fa_PercentAltern | B38: Percent Alternative Car Sales | C38: 10.157681 | D38: 10.983189 | E38: 11.8059 | F38: 12.622499 | G38: 13.434297 | H38: 14.243176 | I38: 15.050748 | J38: 15.857643 | K38: 16.664019 | L38: 17.470499 | M38: 18.277195 | N38: 19.083721 | O38: 19.890461 | P38: 20.697311 | Q38: 21.503721 | R38: 22.311045 | S38: 23.119165 | T38: 23.92729 | U38: 24.735849 | V38: 25.544804 | W38: 26.353815 | X38: 27.163172 | Y38: 27.97283 | Z38: 28.782892 | AA38: 29.5937 | AB38: 30.404064 | AC38: 31.214642 | AD38: 32.025562 | AE38: 32.813244 | AF38: 0.042768
A39: TFS000:fa_TotalNewCarSa | B39: Total New Car Sales | C39: 829.77441 | D39: 845.73663 | E39: 853.07098 | F39: 842.01703 | G39: 825.26654 | H39: 816.24738 | I39: 806.41144 | J39: 800.87482 | K39: 796.59534 | L39: 792.36176 | M39: 791.30432 | N39: 788.4693 | O39: 789.73572 | P39: 794.35419 | Q39: 803.2821 | R39: 808.2663 | S39: 813.10113 | T39: 817.85107 | U39: 821.69397 | V39: 820.85999 | W39: 819.8396 | X39: 815.63208 | Y39: 814.46277 | Z39: 817.45422 | AA39: 826.61383 | AB39: 826.83997 | AC39: 828.19031 | AD39: 830.83118 | AE39: 835.2663 | AF39: 0.000236
B41: New Light Truck Sales 1/
B42: Conventional Light Trucks
A43: TFS000:ga_GasolineICEVe | B43: Gasoline ICE Vehicles | C43: 1139.8827 | D43: 1177.5922 | E43: 1225.1962 | F43: 1266.6293 | G43: 1280.5264 | H43: 1273.6564 | I43: 1266.3192 | J43: 1266.3704 | K43: 1255.4795 | L43: 1247.1234 | M43: 1238.2233 | N43: 1229.917 | O43: 1228.6764 | P43: 1234.7007 | Q43: 1240.9656 | R43: 1247.8655 | S43: 1256.8419 | T43: 1264.0477 | U43: 1273.665 | V43: 1276.9398 | W43: 1280.7981 | X43: 1284.9028 | Y43: 1287.0942 | Z43: 1296.9729 | AA43: 1299.4546 | AB43: 1304.3114 | AC43: 1303.999 | AD43: 1310.5312 | AE43: 1318.3575 | AF43: 0.005209
A44: TFS000:ga_TDIDieselICE | B44: TDI Diesel ICE | C44: 0.042834 | D44: 0.0448 | E44: 0.047137 | F44: 0.049205 | G44: 0.050164 | H44: 0.05028 | I44: 0.050354 | J44: 0.050707 | K44: 0.050606 | L44: 0.050601 | M44: 0.050573 | N44: 0.05056 | O44: 0.050837 | P44: 0.051416 | Q44: 0.051999 | R44: 0.052623 | S44: 0.053332 | T44: 0.053966 | U44: 0.054716 | V44: 0.055203 | W44: 0.05572 | X44: 0.056254 | Y44: 0.056709 | Z44: 0.057515 | AA44: 0.058032 | AB44: 0.058632 | AC44: 0.058999 | AD44: 0.059676 | AE44: 0.06041 | AF44: 0.012355
A45: TFS000:ga_TotalConventi | B45: Total Conventional Light Trucks | C45: 1139.9255 | D45: 1177.637 | E45: 1225.2433 | F45: 1266.6785 | G45: 1280.5765 | H45: 1273.7067 | I45: 1266.3696 | J45: 1266.421 | K45: 1255.5302 | L45: 1247.1741 | M45: 1238.2738 | N45: 1229.9675 | O45: 1228.7272 | P45: 1234.7521 | Q45: 1241.0176 | R45: 1247.9181 | S45: 1256.8953 | T45: 1264.1017 | U45: 1273.7197 | V45: 1276.995 | W45: 1280.8538 | X45: 1284.9591 | Y45: 1287.151 | Z45: 1297.0304 | AA45: 1299.5126 | AB45: 1304.37 | AC45: 1304.058 | AD45: 1310.5909 | AE45: 1318.418 | AF45: 0.005209
B47: Alternative-Fuel Light Trucks
A48: TFS000:ha_Ethanol-FlexF | B48: Ethanol-Flex Fuel ICE | C48: 97.975632 | D48: 102.39687 | E48: 107.67007 | F48: 112.33575 | G48: 114.48013 | H48: 114.70761 | I48: 114.84385 | J48: 115.61748 | K48: 115.36041 | L48: 115.32437 | M48: 115.23352 | N48: 115.18002 | O48: 115.78656 | P48: 117.08218 | Q48: 118.38756 | R48: 119.78483 | S48: 121.37783 | T48: 122.8025 | U48: 124.48741 | V48: 125.57402 | W48: 126.72716 | X48: 127.91966 | Y48: 128.93149 | Z48: 130.74116 | AA48: 131.88454 | AB48: 133.22308 | AC48: 134.03351 | AD48: 135.54968 | AE48: 137.19547 | AF48: 0.012097
A49: TFS000:ha_100mileEV | B49: 100-Mile Electric Vehicle | C49: 0.077187 | D49: 0.076893 | E49: 0.07708 | F49: 0.076725 | G49: 0.074614 | H49: 0.071291 | I49: 0.067977 | J49: 0.065073 | K49: 0.061625 | L49: 0.058332 | M49: 0.055036 | N49: 0.051793 | O49: 0.048852 | P49: 0.046172 | Q49: 0.043459 | R49: 0.040714 | S49: 0.037982 | T49: 0.035139 | U49: 0.0323 | V49: 0.029246 | W49: 0.026166 | X49: 0.02305 | Y49: 0.019861 | Z49: 0.016736 | AA49: 0.013458 | AB49: 0.010167 | AC49: 0.006801 | AD49: 0.00343 | AE49: 0 | AF49: --
...

Sheet AEO Table 45
B1: ref2023.d020623a | C1: 2022 | D1: 2023 | E1: 2024 | F1: 2025 | G1: 2026 | H1: 2027 | I1: 2028 | J1: 2029 | K1: 2030 | L1: 2031 | M1: 2032 | N1: 2033 | O1: 2034 | P1: 2035 | Q1: 2036 | R1: 2037 | S1: 2038 | T1: 2039 | U1: 2040 | V1: 2041 | W1: 2042 | X1: 2043 | Y1: 2044 | Z1: 2045 | AA1: 2046 | AB1: 2047 | AC1: 2048 | AD1: 2049 | AE1: 2050
C3: Report | D3: Annual Energy Outlook 2023
C4: Scenario | D4: ref2023 | G4: Reference
C5: Datekey | D5: d020623a
C6: Release Date | E6: March 2023
A10: TFL000 | B10: 45. Transportation Fleet Car and Truck Stock by Type and Technology | AF10: Annual
B11: (thousands) | AF11: Change
AF12: 2022–2050
B13: Technology Type | C13: 2022 | D13: 2023 | E13: 2024 | F13: 2025 | G13: 2026 | H13: 2027 | I13: 2028 | J13: 2029 | K13: 2030 | L13: 2031 | M13: 2032 | N13: 2033 | O13: 2034 | P13: 2035 | Q13: 2036 | R13: 2037 | S13: 2038 | T13: 2039 | U13: 2040 | V13: 2041 | W13: 2042 | X13: 2043 | Y13: 2044 | Z13: 2045 | AA13: 2046 | AB13: 2047 | AC13: 2048 | AD13: 2049 | AE13: 2050 | AF13: 2050
B15: Car Stock 1/
B16: Conventional Cars
A17: TFL000:ba_GasolineICEVe | B17: Gasoline ICE Vehicles | C17: 5006.5488 | D17: 4623.4966 | E17: 4322.0991 | F17: 4050.3804 | G17: 3798.4448 | H17: 3573.9875 | I17: 3375.2903 | J17: 3201.9536 | K17: 3049.9338 | L17: 2915.8713 | M17: 2799.1982 | N17: 2695.3247 | O17: 2605.9509 | P17: 2531.2725 | Q17: 2471.8772 | R17: 2420.7988 | S17: 2375.9214 | T17: 2335.8723 | U17: 2299.6143 | V17: 2263.064 | W17: 2226.7246 | X17: 2188.9048 | Y17: 2153.0828 | Z17: 2121.8831 | AA17: 2098.4036 | AB17: 2073.5654 | AC17: 2048.2012 | AD17: 2023.4009 | AE17: 2001.2681 | AF17: -0.032218
A18: TFL000:ba_TDIDieselICE | B18: TDI Diesel ICE | C18: 16.267254 | D18: 14.041601 | E18: 12.078984 | F18: 10.34063 | G18: 8.810128 | H18: 7.452874 | I18: 6.247537 | J18: 5.194445 | K18: 4.291502 | L18: 3.527866 | M18: 2.892869 | N18: 2.376716 | O18: 1.965617 | P18: 1.6438 | Q18: 1.393396 | R18: 1.198524 | S18: 1.047394 | T18: 0.928337 | U18: 0.828804 | V18: 0.742408 | W18: 0.667005 | X18: 0.600459 | Y18: 0.541114 | Z18: 0.488003 | AA18: 0.440443 | AB18: 0.39783 | AC18: 0.359624 | AD18: 0.325348 | AE18: 0.294577 | AF18: -0.133474
A19: TFL000:ba_TotalConventi | B19: Total Conventional Cars | C19: 5022.8159 | D19: 4637.5381 | E19: 4334.1782 | F19: 4060.7209 | G19: 3807.2549 | H19: 3581.4404 | I19: 3381.5378 | J19: 3207.1479 | K19: 3054.2253 | L19: 2919.3992 | M19: 2802.0911 | N19: 2697.7014 | O19: 2607.9165 | P19: 2532.9163 | Q19: 2473.2705 | R19: 2421.9973 | S19: 2376.9688 | T19: 2336.8005 | U19: 2300.4431 | V19: 2263.8064 | W19: 2227.3916 | X19: 2189.5051 | Y19: 2153.6238 | Z19: 2122.3711 | AA19: 2098.844 | AB19: 2073.9634 | AC19: 2048.5608 | AD19: 2023.7262 | AE19: 2001.5626 | AF19: -0.032325
B21: Alternative-Fuel Cars
A22: TFL000:ca_Ethanol-FlexF | B22: Ethanol-Flex Fuel ICE | C22: 260.40921 | D22: 233.98811 | E22: 209.63817 | F22: 186.64131 | G22: 165.97789 | H22: 147.82109 | I22: 132.07271 | J22: 118.78522 | K22: 107.73377 | L22: 98.722214 | M22: 91.63073 | N22: 86.220879 | O22: 82.223007 | P22: 79.438202 | Q22: 77.735916 | R22: 76.54174 | S22: 75.666542 | T22: 75.034683 | U22: 74.555443 | V22: 74.032272 | W22: 73.489876 | X22: 72.862831 | Y22: 72.320984 | Z22: 71.990898 | AA22: 72.008469 | AB22: 71.941269 | AC22: 71.822685 | AD22: 71.715027 | AE22: 71.534599 | AF22: -0.045097
A23: TFL000:ca_100mileEV | B23: 100-Mile Electric Vehicle | C23: 11.328024 | D23: 11.751799 | E23: 12.242356 | F23: 12.619924 | G23: 12.897101 | H23: 13.181957 | I23: 13.471307 | J23: 13.783559 | K23: 14.123207 | L23: 14.488546 | M23: 14.888898 | N23: 15.317131 | O23: 15.79207 | P23: 16.327549 | Q23: 16.936695 | R23: 17.57663 | S23: 18.235157 | T23: 18.903063 | U23: 19.57601 | V23: 20.217279 | W23: 20.833857 | X23: 21.407917 | Y23: 21.97821 | Z23: 22.581919 | AA23: 23.266811 | AB23: 23.926888 | AC23: 24.574036 | AD23: 25.223347 | AE23: 25.902096 | AF23: 0.029978
A24: TFL000:ca_ElectricVehic | B24: 200-Mile Electric Vehicle | C24: 17.462101 | D24: 18.744711 | E24: 21.541321 | F24: 25.222059 | G24: 29.118896 | H24: 33.20546 | I24: 37.426132 | J24: 41.846264 | K24: 46.466694 | L24: 51.259415 | M24: 56.27491 | N24: 61.416988 | O24: 66.797653 | P24: 72.494194 | Q24: 78.615685 | R24: 84.929886 | S24: 91.387436 | T24: 97.968834 | U24: 104.64284 | V24: 111.18373 | W24: 117.62488 | X24: 123.84116 | Y24: 130.07907 | Z24: 136.56813 | AA24: 143.62234 | AB24: 150.50897 | AC24: 157.30911 | AD24: 164.12808 | AE24: 171.15567 | AF24: 0.084934
A25: TFL000:ea_FuelCellGasol | B25: 300-Mile Electric Vehicle | C25: 55.467815 | D25: 63.862431 | E25: 72.749718 | F25: 81.883339 | G25: 90.405708 | H25: 98.471451 | I25: 106.06701 | J25: 113.40288 | K25: 120.48434 | L25: 127.29469 | M25: 133.98381 | N25: 140.44589 | O25: 146.91003 | P25: 153.54129 | Q25: 160.5623 | R25: 167.61523 | S25: 174.68607 | T25: 181.77106 | U25: 188.8676 | V25: 195.65595 | W25: 202.22496 | X25: 208.40951 | Y25: 214.59907 | Z25: 221.16119 | AA25: 228.55313 | AB25: 235.69231 | AC25: 242.69841 | AD25: 249.72317 | AE25: 257.04065 | AF25: 0.056293
A26: TFL000:ca_Plug-inGasoli | B26: Plug-in 20 Gasoline Hybrid | C26: 18.620897 | D26: 18.742386 | E26: 19.225786 | F26: 19.769812 | G26: 20.255058 | H26: 20.684639 | I26: 21.07461 | J26: 21.458031 | K26: 21.848562 | L26: 22.249832 | M26: 22.686924 | N26: 23.151102 | O26: 23.674931 | P26: 24.288008 | Q26: 25.015554 | R26: 25.810991 | S26: 26.663719 | T26: 27.561453 | U26: 28.491934 | V26: 29.406263 | W26: 30.308496 | X26: 31.167662 | Y26: 32.028728 | Z26: 32.935436 | AA26: 33.948967 | AB26: 34.930641 | AC26: 35.897713 | AD26: 36.868179 | AE26: 37.873577 | AF26: 0.02568
A27: TFL000:ca_Plug-in40Hybd | B27: Plug-in 50 Gasoline Hybrid | C27: 9.18985 | D27: 9.232191 | E27: 9.513065 | F27: 9.890547 | G27: 10.297814 | H27: 10.742392 | I27: 11.226655 | J27: 11.782159 | K27: 12.41293 | L27: 13.113447 | M27: 13.8957 | N27: 14.741248 | O27: 15.667826 | P27: 16.685068 | Q27: 17.809175 | R27: 18.991947 | S27: 20.221149 | T27: 21.486172 | U27: 22.775742 | V27: 24.045906 | W27: 25.302801 | X27: 26.519762 | Y27: 27.738804 | Z27: 29.00321 | AA27: 30.374689 | AB27: 31.715918 | AC27: 33.043564 | AD27: 34.375633 | AE27: 35.743801 | AF27: 0.049706
A28: TFL000:ca_Electric-Dies | B28: Electric-Diesel Hybrid | C28: 0 | D28: 0 | E28: 0 | F28: 0 | G28: 0 | H28: 0 | I28: 0 | J28: 0 | K28: 0 | L28: 0 | M28: 0 | N28: 0 | O28: 0 | P28: 0 | Q28: 0 | R28: 0 | S28: 0 | T28: 0 | U28: 0 | V28: 0 | W28: 0 | X28: 0 | Y28: 0 | Z28: 0 | AA28: 0 | AB28: 0 | AC28: 0 | AD28: 0 | AE28: 0 | AF28: --
A29: TFL000:ca_Electric-Gaso | B29: Electric-Gasoline Hybrid | C29: 223.61549 | D29: 216.07962 | E29: 210.16901 | F29: 203.94279 | G29: 198.138 | H29: 193.12856 | I29: 188.94823 | J29: 185.78183 | K29: 183.58957 | L29: 182.24689 | M29: 181.81209 | N29: 182.02373 | O29: 183.03459 | P29: 184.91509 | Q29: 187.75081 | R29: 191.07138 | S29: 194.74928 | T29: 198.696 | U29: 202.83295 | V29: 206.79274 | W29: 210.62627 | X29: 214.1521 | Y29: 217.71721 | Z29: 221.63664 | AA29: 226.31955 | AB29: 230.77928 | AC29: 235.12669 | AD29: 239.49492 | AE29: 244.11679 | AF29: 0.003138
A30: TFL000:ca_CompressedNat | B30: Natural Gas ICE | C30: 11.524047 | D30: 10.680966 | E30: 9.790733 | F30: 8.885427 | G30: 7.990345 | H30: 7.103336 | I30: 6.237593 | J30: 5.428048 | K30: 4.758622 | L30: 4.129239 | M30: 3.577585 | N30: 3.107362 | O30: 2.721086 | P30: 2.399466 | Q30: 2.138429 | R30: 1.966115 | S30: 1.819323 | T30: 1.697581 | U30: 1.589439 | V30: 1.488186 | W30: 1.393384 | X30: 1.30462 | Y30: 1.221511 | Z30: 1.143696 | AA30: 1.070839 | AB30: 1.002622 | AC30: 0.938752 | AD30: 0.87895 | AE30: 0.822958 | AF30: -0.089954
A31: TFL000:da_CompressedNat | B31: Natural Gas Bi-fuel | C31: 0.307861 | D31: 0.264919 | E31: 0.239802 | F31: 0.224525 | G31: 0.210222 | H31: 0.19683 | I31: 0.184292 | J31: 0.172551 | K31: 0.161559 | L31: 0.151267 | M31: 0.141631 | N31: 0.132609 | O31: 0.124161 | P31: 0.116252 | Q31: 0.108846 | R31: 0.101912 | S31: 0.09542 | T31: 0.089341 | U31: 0.08365 | V31: 0.078321 | W31: 0.073332 | X31: 0.06866 | Y31: 0.064286 | Z31: 0.060191 | AA31: 0.056357 | AB31: 0.052767 | AC31: 0.049405 | AD31: 0.046258 | AE31: 0.043311 | AF31: -0.067647
A32: TFL000:da_LiquefiedPetr | B32: Propane ICE | C32: 2.087991 | D32: 1.784609 | E32: 1.535312 | F32: 1.333347 | G32: 1.206512 | H32: 1.127065 | I32: 1.055267 | J32: 0.988043 | K32: 0.925101 | L32: 0.866168 | M32: 0.810991 | N32: 0.759328 | O32: 0.710956 | P32: 0.665665 | Q32: 0.62326 | R32: 0.583556 | S32: 0.546381 | T32: 0.511575 | U32: 0.478986 | V32: 0.448473 | W32: 0.419903 | X32: 0.393154 | Y32: 0.368109 | Z32: 0.344659 | AA32: 0.322703 | AB32: 0.302145 | AC32: 0.282898 | AD32: 0.264876 | AE32: 0.248003 | AF32: -0.073267
A33: TFL000:ea_LiquefiedPetr | B33: Propane Bi-fuel | C33: 4.082679 | D33: 3.480398 | E33: 2.97779 | F33: 2.565041 | G33: 2.283806 | H33: 2.108607 | I33: 1.959856 | J33: 1.835006 | K33: 1.718109 | L33: 1.60866 | M33: 1.506182 | N33: 1.410233 | O33: 1.320396 | P33: 1.236282 | Q33: 1.157526 | R33: 1.083788 | S33: 1.014747 | T33: 0.950104 | U33: 0.889579 | V33: 0.832909 | W33: 0.77985 | X33: 0.730171 | Y33: 0.683656 | Z33: 0.640105 | AA33: 0.599328 | AB33: 0.561149 | AC33: 0.525401 | AD33: 0.491931 | AE33: 0.460594 | AF33: -0.074969
A34: TFL000:ea_FuelCellMetha | B34: Fuel Cell Methanol | C34: 0 | D34: 0 | E34: 0 | F34: 0 | G34: 0 | H34: 0 | I34: 0 | J34: 0 | K34: 0 | L34: 0 | M34: 0 | N34: 0 | O34: 0 | P34: 0 | Q34: 0 | R34: 0 | S34: 0 | T34: 0 | U34: 0 | V34: 0 | W34: 0 | X34: 0 | Y34: 0 | Z34: 0 | AA34: 0 | AB34: 0 | AC34: 0 | AD34: 0 | AE34: 0 | AF34: --
A35: TFL000:ea_FuelCellHydro | B35: Fuel Cell Hydrogen | C35: 0.695658 | D35: 0.693525 | E35: 0.730931 | F35: 0.79699 | G35: 0.88554 | H35: 0.9894 | I35: 1.10531 | J35: 1.234237 | K35: 1.374475 | L35: 1.524476 | M35: 1.685228 | N35: 1.854181 | O35: 2.033293 | P35: 2.223712 | Q35: 2.427094 | R35: 2.639039 | S35: 2.858608 | T35: 3.08428 | U35: 3.314411 | V35: 3.544198 | W35: 3.773129 | X35: 3.997288 | Y35: 4.220754 | Z35: 4.448301 | AA35: 4.688444 | AB35: 4.925473 | AC35: 5.161976 | AD35: 5.399414 | AE35: 5.639956 | AF35: 0.077606
A36: TFL000:ea_TotalAlternat | B36: Total Alternative Cars | C36: 614.79175 | D36: 589.30566 | E36: 570.354 | F36: 553.77508 | G36: 539.66693 | H36: 528.7608 | I36: 520.82898 | J36: 516.4978 | K36: 515.59692 | L36: 517.65485 | M36: 522.89471 | N36: 530.58075 | O36: 541.01001 | P36: 554.33075 | Q36: 570.88135 | R36: 588.91223 | S36: 607.94379 | T36: 627.75415 | U36: 648.09857 | V36: 667.7262 | W36: 686.85071 | X36: 704.85486 | Y36: 723.02039 | Z36: 742.51434 | AA36: 764.8316 | AB36: 786.33948 | AC36: 807.43066 | AD36: 828.60986 | AE36: 850.58197 | AF36: 0.011662
A38: TFL000:fa_TotalNewCarSa | B38: Total Car Stock | C38: 5637.6074 | D38: 5226.8438 | E38: 4904.5322 | F38: 4614.4961 | G38: 4346.9219 | H38: 4110.2012 | I38: 3902.3667 | J38: 3723.6458 | K38: 3569.8223 | L38: 3437.054 | M38: 3324.9858 | N38: 3228.2822 | O38: 3148.9265 | P38: 3087.2471 | Q38: 3044.1519 | R38: 3010.9097 | S38: 2984.9126 | T38: 2964.5547 | U38: 2948.5417 | V38: 2931.5327 | W38: 2914.2422 | X38: 2894.3599 | Y38: 2876.644 | Z38: 2864.8855 | AA38: 2863.6755 | AB38: 2860.3027 | AC38: 2855.9915 | AD38: 2852.3359 | AE38: 2852.1445 | AF38: -0.024042
B40: Light Truck Stock 1/
B41: Conventional Light Trucks
A42: TFL000:ga_GasolineICEVe | B42: Gasoline ICE Vehicles | C42: 7639.083 | D42: 7655.0962 | E42: 7760.314 | F42: 7895.3628 | G42: 8023.1143 | H42: 8127.6328 | I42: 8212.9814 | J42: 8290.5889 | K42: 8349.9736 | L42: 8394.4512 | M42: 8423.9824 | N42: 8440.4258 | O42: 8451.6865 | P42: 8465.3477 | Q42: 8480.6543 | R42: 8497.1035 | S42: 8516.1016 | T42: 8536.0273 | U42: 8559.6494 | V42: 8580.2031 | W42: 8599.4805 | X42: 8618.3643 | Y42: 8635.5254 | Z42: 8659.0557 | AA42: 8680.4678 | AB42: 8702.9229 | AC42: 8720.7891 | AD42: 8742.2803 | AE42: 8768.0771 | AF42: 0.004935
A43: TFL000:ga_TDIDieselICE | B43: TDI Diesel ICE | C43: 60.55452 | D43: 54.813412 | E43: 48.998947 | F43: 43.883667 | G43: 39.715416 | H43: 35.790714 | I43: 32.023296 | J43: 28.420086 | K43: 24.994423 | L43: 21.770369 | M43: 18.758324 | N43: 15.995414 | O43: 13.487585 | P43: 11.270679 | Q43: 9.33564 | R43: 7.682456 | S43: 6.313601 | T43: 5.195662 | U43: 4.315732 | V43: 3.636456 | W43: 3.103021 | X43: 2.68296 | Y43: 2.347914 | Z43: 2.093235 | AA43: 1.89311 | AB43: 1.714415 | AC43: 1.55453 | AD43: 1.411821 | AE43: 1.284441 | AF43: -0.128566
A44: TFL000:ga_TotalConventi | B44: Total Conventional Light Trucks | C44: 7699.6377 | D44: 7709.9097 | E44: 7809.313 | F44: 7939.2466 | G44: 8062.8296 | H44: 8163.4233 | I44: 8245.0049 | J44: 8319.0088 | K44: 8374.9678 | L44: 8416.2217 | M44: 8442.7412 | N44: 8456.4209 | O44: 8465.1738 | P44: 8476.6182 | Q44: 8489.9902 | R44: 8504.7861 | S44: 8522.415 | T44: 8541.2227 | U44: 8563.9648 | V44: 8583.8398 | W44: 8602.583 | X44: 8621.0469 | Y44: 8637.873 | Z44: 8661.1484 | AA44: 8682.3613 | AB44: 8704.6377 | AC44: 8722.3438 | AD44: 8743.6924 | AE44: 8769.3613 | AF44: 0.004657
